{"num_games": 100, "student_agent_wins": [0, 0, 0, 1, 1, 0, 0, 0, 1, 1, 1, 0, 0, 0, 0, 1, 0, 0, 1, 0, 0, 1, 0, 0, 0, 0, 1, 1, 0, 0, 0, 0, 0, 0, 0, 0, 0, 0, 0, 1, 1, 0, 0, 0, 0, 0, 0, 0, 0, 1, 1, 0, 0, 0, 0, 0, 1, 0, 0, 1, 0, 0, 0, 0, 0, 1, 1, 0, 0, 1, 0, 0, 0, 0, 0, 0, 0, 0, 0, 0, 1, 0, 0, 0, 0, 0, 0, 0, 0, 1, 0, 0, 0, 0, 0, 0, 0, 0, 1, 1], "random_agent_wins": [1, 1, 1, 0, 0, 1, 1, 1, 0, 0, 0, 1, 1, 1, 1, 0, 1, 1, 0, 1, 1, 0, 1, 1, 1, 1, 0, 0, 1, 1, 1, 1, 1, 1, 1, 1, 1, 1, 1, 0, 0, 1, 1, 1, 1, 1, 1, 1, 1, 0, 0, 1, 1, 1, 1, 1, 0, 1, 1, 0, 1, 1, 1, 1, 1, 0, 0, 1, 1, 0, 1, 1, 1, 1, 1, 1, 1, 1, 1, 1, 0, 1, 1, 1, 1, 1, 1, 1, 1, 0, 1, 1, 1, 1, 1, 1, 1, 1, 0, 0], "student_agent_win_count": 23, "random_agent_win_count": 77, "student_agent_win_percentage": 0.23, "random_agent_win_percentage": 0.77, "student_agent_time_taken": 0.003913335800170899, "random_agent_time_taken": 0.003342695236206055, "run_info": [{"student_agent_score": 1, "random_agent_score": 35, "student_agent_time": 0.002495288848876953, "random_agent_time": 0.002147674560546875, "board_size": 6, "swap_players": true, "run_out": "An exception raised. The traceback is as follows:\nTraceback (most recent call last):\n  File \"/home/ml/users/ksinha4/mlp/comp424_final_project/submissions/comp424mcgill/final-project-a_new_team/world.py\", line 310, in step\n    raise ValueError(\nValueError: [INVALID:STEP] Not a valid step from [3 3] to [3 3] and put barrier at 0, with max steps = 3\n\nExecute Random Walk!\nAn exception raised. The traceback is as follows:\nTraceback (most recent call last):\n  File \"/home/ml/users/ksinha4/mlp/comp424_final_project/submissions/comp424mcgill/final-project-a_new_team/world.py\", line 310, in step\n    raise ValueError(\nValueError: [INVALID:STEP] Not a valid step from [3 3] to [3 3] and put barrier at 0, with max steps = 3\n\nExecute Random Walk!\n"}, {"student_agent_score": 1, "random_agent_score": 63, "student_agent_time": 0.004410505294799805, "random_agent_time": 0.002346038818359375, "board_size": 8, "swap_players": false, "run_out": "An exception raised. The traceback is as follows:\nTraceback (most recent call last):\n  File \"/home/ml/users/ksinha4/mlp/comp424_final_project/submissions/comp424mcgill/final-project-a_new_team/world.py\", line 310, in step\n    raise ValueError(\nValueError: [INVALID:STEP] Not a valid step from [2 2] to [2 2] and put barrier at 0, with max steps = 4\n\nExecute Random Walk!\nAn exception raised. The traceback is as follows:\nTraceback (most recent call last):\n  File \"/home/ml/users/ksinha4/mlp/comp424_final_project/submissions/comp424mcgill/final-project-a_new_team/world.py\", line 310, in step\n    raise ValueError(\nValueError: [INVALID:STEP] Not a valid step from [3 1] to [3 1] and put barrier at 0, with max steps = 4\n\nExecute Random Walk!\nAn exception raised. The traceback is as follows:\nTraceback (most recent call last):\n  File \"/home/ml/users/ksinha4/mlp/comp424_final_project/submissions/comp424mcgill/final-project-a_new_team/world.py\", line 310, in step\n    raise ValueError(\nValueError: [INVALID:STEP] Not a valid step from [3 0] to [3 0] and put barrier at 0, with max steps = 4\n\nExecute Random Walk!\nAn exception raised. The traceback is as follows:\nTraceback (most recent call last):\n  File \"/home/ml/users/ksinha4/mlp/comp424_final_project/submissions/comp424mcgill/final-project-a_new_team/world.py\", line 310, in step\n    raise ValueError(\nValueError: [INVALID:STEP] Not a valid step from [6 1] to [6 1] and put barrier at 0, with max steps = 4\n\nExecute Random Walk!\n"}, {"student_agent_score": 1, "random_agent_score": 35, "student_agent_time": 0.0029573440551757812, "random_agent_time": 0.0023670196533203125, "board_size": 6, "swap_players": true, "run_out": "An exception raised. The traceback is as follows:\nTraceback (most recent call last):\n  File \"/home/ml/users/ksinha4/mlp/comp424_final_project/submissions/comp424mcgill/final-project-a_new_team/world.py\", line 310, in step\n    raise ValueError(\nValueError: [INVALID:STEP] Not a valid step from [3 3] to [3 3] and put barrier at 0, with max steps = 3\n\nExecute Random Walk!\nAn exception raised. The traceback is as follows:\nTraceback (most recent call last):\n  File \"/home/ml/users/ksinha4/mlp/comp424_final_project/submissions/comp424mcgill/final-project-a_new_team/world.py\", line 310, in step\n    raise ValueError(\nValueError: [INVALID:STEP] Not a valid step from [3 3] to [3 3] and put barrier at 0, with max steps = 3\n\nExecute Random Walk!\n"}, {"student_agent_score": 120, "random_agent_score": 1, "student_agent_time": 0.0019383430480957031, "random_agent_time": 0.002422332763671875, "board_size": 11, "swap_players": true, "run_out": "An exception raised. The traceback is as follows:\nTraceback (most recent call last):\n  File \"/home/ml/users/ksinha4/mlp/comp424_final_project/submissions/comp424mcgill/final-project-a_new_team/world.py\", line 310, in step\n    raise ValueError(\nValueError: [INVALID:STEP] Not a valid step from [9 3] to [9 3] and put barrier at 0, with max steps = 6\n\nExecute Random Walk!\nAn exception raised. The traceback is as follows:\nTraceback (most recent call last):\n  File \"/home/ml/users/ksinha4/mlp/comp424_final_project/submissions/comp424mcgill/final-project-a_new_team/world.py\", line 310, in step\n    raise ValueError(\nValueError: [INVALID:STEP] Not a valid step from [9 3] to [9 3] and put barrier at 0, with max steps = 6\n\nExecute Random Walk!\n"}, {"student_agent_score": 120, "random_agent_score": 1, "student_agent_time": 0.001636505126953125, "random_agent_time": 0.002001047134399414, "board_size": 11, "swap_players": true, "run_out": "An exception raised. The traceback is as follows:\nTraceback (most recent call last):\n  File \"/home/ml/users/ksinha4/mlp/comp424_final_project/submissions/comp424mcgill/final-project-a_new_team/world.py\", line 310, in step\n    raise ValueError(\nValueError: [INVALID:STEP] Not a valid step from [9 3] to [9 3] and put barrier at 0, with max steps = 6\n\nExecute Random Walk!\nAn exception raised. The traceback is as follows:\nTraceback (most recent call last):\n  File \"/home/ml/users/ksinha4/mlp/comp424_final_project/submissions/comp424mcgill/final-project-a_new_team/world.py\", line 310, in step\n    raise ValueError(\nValueError: [INVALID:STEP] Not a valid step from [9 3] to [9 3] and put barrier at 0, with max steps = 6\n\nExecute Random Walk!\n"}, {"student_agent_score": 2, "random_agent_score": 79, "student_agent_time": 0.0028951168060302734, "random_agent_time": 0.002772808074951172, "board_size": 9, "swap_players": false, "run_out": "An exception raised. The traceback is as follows:\nTraceback (most recent call last):\n  File \"/home/ml/users/ksinha4/mlp/comp424_final_project/submissions/comp424mcgill/final-project-a_new_team/world.py\", line 310, in step\n    raise ValueError(\nValueError: [INVALID:STEP] Not a valid step from [5 4] to [5 4] and put barrier at 0, with max steps = 5\n\nExecute Random Walk!\nAn exception raised. The traceback is as follows:\nTraceback (most recent call last):\n  File \"/home/ml/users/ksinha4/mlp/comp424_final_project/submissions/comp424mcgill/final-project-a_new_team/world.py\", line 310, in step\n    raise ValueError(\nValueError: [INVALID:STEP] Not a valid step from [5 3] to [5 3] and put barrier at 0, with max steps = 5\n\nExecute Random Walk!\n"}, {"student_agent_score": 2, "random_agent_score": 98, "student_agent_time": 0.007967948913574219, "random_agent_time": 0.0064237117767333984, "board_size": 10, "swap_players": false, "run_out": "An exception raised. The traceback is as follows:\nTraceback (most recent call last):\n  File \"/home/ml/users/ksinha4/mlp/comp424_final_project/submissions/comp424mcgill/final-project-a_new_team/world.py\", line 310, in step\n    raise ValueError(\nValueError: [INVALID:STEP] Not a valid step from [7 5] to [7 5] and put barrier at 0, with max steps = 5\n\nExecute Random Walk!\nAn exception raised. The traceback is as follows:\nTraceback (most recent call last):\n  File \"/home/ml/users/ksinha4/mlp/comp424_final_project/submissions/comp424mcgill/final-project-a_new_team/world.py\", line 310, in step\n    raise ValueError(\nValueError: [INVALID:STEP] Not a valid step from [6 6] to [6 6] and put barrier at 0, with max steps = 5\n\nExecute Random Walk!\nAn exception raised. The traceback is as follows:\nTraceback (most recent call last):\n  File \"/home/ml/users/ksinha4/mlp/comp424_final_project/submissions/comp424mcgill/final-project-a_new_team/world.py\", line 310, in step\n    raise ValueError(\nValueError: [INVALID:STEP] Not a valid step from [7 8] to [7 8] and put barrier at 0, with max steps = 5\n\nExecute Random Walk!\nAn exception raised. The traceback is as follows:\nTraceback (most recent call last):\n  File \"/home/ml/users/ksinha4/mlp/comp424_final_project/submissions/comp424mcgill/final-project-a_new_team/world.py\", line 310, in step\n    raise ValueError(\nValueError: [INVALID:STEP] Not a valid step from [7 8] to [7 8] and put barrier at 0, with max steps = 5\n\nExecute Random Walk!\n"}, {"student_agent_score": 2, "random_agent_score": 79, "student_agent_time": 0.004424571990966797, "random_agent_time": 0.0019221305847167969, "board_size": 9, "swap_players": false, "run_out": "An exception raised. The traceback is as follows:\nTraceback (most recent call last):\n  File \"/home/ml/users/ksinha4/mlp/comp424_final_project/submissions/comp424mcgill/final-project-a_new_team/world.py\", line 310, in step\n    raise ValueError(\nValueError: [INVALID:STEP] Not a valid step from [5 4] to [5 4] and put barrier at 0, with max steps = 5\n\nExecute Random Walk!\nAn exception raised. The traceback is as follows:\nTraceback (most recent call last):\n  File \"/home/ml/users/ksinha4/mlp/comp424_final_project/submissions/comp424mcgill/final-project-a_new_team/world.py\", line 310, in step\n    raise ValueError(\nValueError: [INVALID:STEP] Not a valid step from [5 3] to [5 3] and put barrier at 0, with max steps = 5\n\nExecute Random Walk!\n"}, {"student_agent_score": 63, "random_agent_score": 1, "student_agent_time": 0.002130270004272461, "random_agent_time": 0.0020275115966796875, "board_size": 8, "swap_players": true, "run_out": "An exception raised. The traceback is as follows:\nTraceback (most recent call last):\n  File \"/home/ml/users/ksinha4/mlp/comp424_final_project/submissions/comp424mcgill/final-project-a_new_team/world.py\", line 310, in step\n    raise ValueError(\nValueError: [INVALID:STEP] Not a valid step from [5 5] to [5 5] and put barrier at 0, with max steps = 4\n\nExecute Random Walk!\nAn exception raised. The traceback is as follows:\nTraceback (most recent call last):\n  File \"/home/ml/users/ksinha4/mlp/comp424_final_project/submissions/comp424mcgill/final-project-a_new_team/world.py\", line 310, in step\n    raise ValueError(\nValueError: [INVALID:STEP] Not a valid step from [5 4] to [5 4] and put barrier at 0, with max steps = 4\n\nExecute Random Walk!\nAn exception raised. The traceback is as follows:\nTraceback (most recent call last):\n  File \"/home/ml/users/ksinha4/mlp/comp424_final_project/submissions/comp424mcgill/final-project-a_new_team/world.py\", line 310, in step\n    raise ValueError(\nValueError: [INVALID:STEP] Not a valid step from [5 4] to [5 4] and put barrier at 0, with max steps = 4\n\nExecute Random Walk!\n"}, {"student_agent_score": 80, "random_agent_score": 1, "student_agent_time": 0.005379438400268555, "random_agent_time": 0.004593610763549805, "board_size": 9, "swap_players": true, "run_out": "An exception raised. The traceback is as follows:\nTraceback (most recent call last):\n  File \"/home/ml/users/ksinha4/mlp/comp424_final_project/submissions/comp424mcgill/final-project-a_new_team/world.py\", line 310, in step\n    raise ValueError(\nValueError: [INVALID:STEP] Not a valid step from [3 4] to [3 4] and put barrier at 0, with max steps = 5\n\nExecute Random Walk!\nAn exception raised. The traceback is as follows:\nTraceback (most recent call last):\n  File \"/home/ml/users/ksinha4/mlp/comp424_final_project/submissions/comp424mcgill/final-project-a_new_team/world.py\", line 310, in step\n    raise ValueError(\nValueError: [INVALID:STEP] Not a valid step from [3 5] to [3 5] and put barrier at 0, with max steps = 5\n\nExecute Random Walk!\nAn exception raised. The traceback is as follows:\nTraceback (most recent call last):\n  File \"/home/ml/users/ksinha4/mlp/comp424_final_project/submissions/comp424mcgill/final-project-a_new_team/world.py\", line 310, in step\n    raise ValueError(\nValueError: [INVALID:STEP] Not a valid step from [3 4] to [3 4] and put barrier at 0, with max steps = 5\n\nExecute Random Walk!\nAn exception raised. The traceback is as follows:\nTraceback (most recent call last):\n  File \"/home/ml/users/ksinha4/mlp/comp424_final_project/submissions/comp424mcgill/final-project-a_new_team/world.py\", line 310, in step\n    raise ValueError(\nValueError: [INVALID:STEP] Not a valid step from [5 4] to [5 4] and put barrier at 0, with max steps = 5\n\nExecute Random Walk!\nAn exception raised. The traceback is as follows:\nTraceback (most recent call last):\n  File \"/home/ml/users/ksinha4/mlp/comp424_final_project/submissions/comp424mcgill/final-project-a_new_team/world.py\", line 310, in step\n    raise ValueError(\nValueError: [INVALID:STEP] Not a valid step from [5 5] to [5 5] and put barrier at 0, with max steps = 5\n\nExecute Random Walk!\n"}, {"student_agent_score": 80, "random_agent_score": 1, "student_agent_time": 0.005722999572753906, "random_agent_time": 0.008364200592041016, "board_size": 9, "swap_players": true, "run_out": "An exception raised. The traceback is as follows:\nTraceback (most recent call last):\n  File \"/home/ml/users/ksinha4/mlp/comp424_final_project/submissions/comp424mcgill/final-project-a_new_team/world.py\", line 310, in step\n    raise ValueError(\nValueError: [INVALID:STEP] Not a valid step from [3 4] to [3 4] and put barrier at 0, with max steps = 5\n\nExecute Random Walk!\nAn exception raised. The traceback is as follows:\nTraceback (most recent call last):\n  File \"/home/ml/users/ksinha4/mlp/comp424_final_project/submissions/comp424mcgill/final-project-a_new_team/world.py\", line 310, in step\n    raise ValueError(\nValueError: [INVALID:STEP] Not a valid step from [3 5] to [3 5] and put barrier at 0, with max steps = 5\n\nExecute Random Walk!\nAn exception raised. The traceback is as follows:\nTraceback (most recent call last):\n  File \"/home/ml/users/ksinha4/mlp/comp424_final_project/submissions/comp424mcgill/final-project-a_new_team/world.py\", line 310, in step\n    raise ValueError(\nValueError: [INVALID:STEP] Not a valid step from [3 4] to [3 4] and put barrier at 0, with max steps = 5\n\nExecute Random Walk!\nAn exception raised. The traceback is as follows:\nTraceback (most recent call last):\n  File \"/home/ml/users/ksinha4/mlp/comp424_final_project/submissions/comp424mcgill/final-project-a_new_team/world.py\", line 310, in step\n    raise ValueError(\nValueError: [INVALID:STEP] Not a valid step from [5 4] to [5 4] and put barrier at 0, with max steps = 5\n\nExecute Random Walk!\nAn exception raised. The traceback is as follows:\nTraceback (most recent call last):\n  File \"/home/ml/users/ksinha4/mlp/comp424_final_project/submissions/comp424mcgill/final-project-a_new_team/world.py\", line 310, in step\n    raise ValueError(\nValueError: [INVALID:STEP] Not a valid step from [5 5] to [5 5] and put barrier at 0, with max steps = 5\n\nExecute Random Walk!\n"}, {"student_agent_score": 1, "random_agent_score": 48, "student_agent_time": 0.0020177364349365234, "random_agent_time": 0.0033528804779052734, "board_size": 7, "swap_players": true, "run_out": "An exception raised. The traceback is as follows:\nTraceback (most recent call last):\n  File \"/home/ml/users/ksinha4/mlp/comp424_final_project/submissions/comp424mcgill/final-project-a_new_team/world.py\", line 310, in step\n    raise ValueError(\nValueError: [INVALID:STEP] Not a valid step from [2 3] to [2 3] and put barrier at 0, with max steps = 4\n\nExecute Random Walk!\nAn exception raised. The traceback is as follows:\nTraceback (most recent call last):\n  File \"/home/ml/users/ksinha4/mlp/comp424_final_project/submissions/comp424mcgill/final-project-a_new_team/world.py\", line 310, in step\n    raise ValueError(\nValueError: [INVALID:STEP] Not a valid step from [5 4] to [5 4] and put barrier at 0, with max steps = 4\n\nExecute Random Walk!\nAn exception raised. The traceback is as follows:\nTraceback (most recent call last):\n  File \"/home/ml/users/ksinha4/mlp/comp424_final_project/submissions/comp424mcgill/final-project-a_new_team/world.py\", line 310, in step\n    raise ValueError(\nValueError: [INVALID:STEP] Not a valid step from [6 3] to [6 3] and put barrier at 0, with max steps = 4\n\nExecute Random Walk!\n"}, {"student_agent_score": 2, "random_agent_score": 98, "student_agent_time": 0.007608652114868164, "random_agent_time": 0.005166292190551758, "board_size": 10, "swap_players": false, "run_out": "An exception raised. The traceback is as follows:\nTraceback (most recent call last):\n  File \"/home/ml/users/ksinha4/mlp/comp424_final_project/submissions/comp424mcgill/final-project-a_new_team/world.py\", line 310, in step\n    raise ValueError(\nValueError: [INVALID:STEP] Not a valid step from [7 5] to [7 5] and put barrier at 0, with max steps = 5\n\nExecute Random Walk!\nAn exception raised. The traceback is as follows:\nTraceback (most recent call last):\n  File \"/home/ml/users/ksinha4/mlp/comp424_final_project/submissions/comp424mcgill/final-project-a_new_team/world.py\", line 310, in step\n    raise ValueError(\nValueError: [INVALID:STEP] Not a valid step from [6 6] to [6 6] and put barrier at 0, with max steps = 5\n\nExecute Random Walk!\nAn exception raised. The traceback is as follows:\nTraceback (most recent call last):\n  File \"/home/ml/users/ksinha4/mlp/comp424_final_project/submissions/comp424mcgill/final-project-a_new_team/world.py\", line 310, in step\n    raise ValueError(\nValueError: [INVALID:STEP] Not a valid step from [7 8] to [7 8] and put barrier at 0, with max steps = 5\n\nExecute Random Walk!\nAn exception raised. The traceback is as follows:\nTraceback (most recent call last):\n  File \"/home/ml/users/ksinha4/mlp/comp424_final_project/submissions/comp424mcgill/final-project-a_new_team/world.py\", line 310, in step\n    raise ValueError(\nValueError: [INVALID:STEP] Not a valid step from [7 8] to [7 8] and put barrier at 0, with max steps = 5\n\nExecute Random Walk!\n"}, {"student_agent_score": 2, "random_agent_score": 79, "student_agent_time": 0.0026688575744628906, "random_agent_time": 0.002208232879638672, "board_size": 9, "swap_players": false, "run_out": "An exception raised. The traceback is as follows:\nTraceback (most recent call last):\n  File \"/home/ml/users/ksinha4/mlp/comp424_final_project/submissions/comp424mcgill/final-project-a_new_team/world.py\", line 310, in step\n    raise ValueError(\nValueError: [INVALID:STEP] Not a valid step from [5 4] to [5 4] and put barrier at 0, with max steps = 5\n\nExecute Random Walk!\nAn exception raised. The traceback is as follows:\nTraceback (most recent call last):\n  File \"/home/ml/users/ksinha4/mlp/comp424_final_project/submissions/comp424mcgill/final-project-a_new_team/world.py\", line 310, in step\n    raise ValueError(\nValueError: [INVALID:STEP] Not a valid step from [5 3] to [5 3] and put barrier at 0, with max steps = 5\n\nExecute Random Walk!\n"}, {"student_agent_score": 1, "random_agent_score": 48, "student_agent_time": 0.003186464309692383, "random_agent_time": 0.004055976867675781, "board_size": 7, "swap_players": false, "run_out": "An exception raised. The traceback is as follows:\nTraceback (most recent call last):\n  File \"/home/ml/users/ksinha4/mlp/comp424_final_project/submissions/comp424mcgill/final-project-a_new_team/world.py\", line 310, in step\n    raise ValueError(\nValueError: [INVALID:STEP] Not a valid step from [4 3] to [4 3] and put barrier at 0, with max steps = 4\n\nExecute Random Walk!\nAn exception raised. The traceback is as follows:\nTraceback (most recent call last):\n  File \"/home/ml/users/ksinha4/mlp/comp424_final_project/submissions/comp424mcgill/final-project-a_new_team/world.py\", line 310, in step\n    raise ValueError(\nValueError: [INVALID:STEP] Not a valid step from [4 2] to [4 2] and put barrier at 0, with max steps = 4\n\nExecute Random Walk!\nAn exception raised. The traceback is as follows:\nTraceback (most recent call last):\n  File \"/home/ml/users/ksinha4/mlp/comp424_final_project/submissions/comp424mcgill/final-project-a_new_team/world.py\", line 310, in step\n    raise ValueError(\nValueError: [INVALID:STEP] Not a valid step from [4 3] to [4 3] and put barrier at 0, with max steps = 4\n\nExecute Random Walk!\nAn exception raised. The traceback is as follows:\nTraceback (most recent call last):\n  File \"/home/ml/users/ksinha4/mlp/comp424_final_project/submissions/comp424mcgill/final-project-a_new_team/world.py\", line 310, in step\n    raise ValueError(\nValueError: [INVALID:STEP] Not a valid step from [5 4] to [5 4] and put barrier at 0, with max steps = 4\n\nExecute Random Walk!\nAn exception raised. The traceback is as follows:\nTraceback (most recent call last):\n  File \"/home/ml/users/ksinha4/mlp/comp424_final_project/submissions/comp424mcgill/final-project-a_new_team/world.py\", line 310, in step\n    raise ValueError(\nValueError: [INVALID:STEP] Not a valid step from [6 3] to [6 3] and put barrier at 0, with max steps = 4\n\nExecute Random Walk!\n"}, {"student_agent_score": 63, "random_agent_score": 1, "student_agent_time": 0.0024971961975097656, "random_agent_time": 0.0025086402893066406, "board_size": 8, "swap_players": true, "run_out": "An exception raised. The traceback is as follows:\nTraceback (most recent call last):\n  File \"/home/ml/users/ksinha4/mlp/comp424_final_project/submissions/comp424mcgill/final-project-a_new_team/world.py\", line 310, in step\n    raise ValueError(\nValueError: [INVALID:STEP] Not a valid step from [5 5] to [5 5] and put barrier at 0, with max steps = 4\n\nExecute Random Walk!\nAn exception raised. The traceback is as follows:\nTraceback (most recent call last):\n  File \"/home/ml/users/ksinha4/mlp/comp424_final_project/submissions/comp424mcgill/final-project-a_new_team/world.py\", line 310, in step\n    raise ValueError(\nValueError: [INVALID:STEP] Not a valid step from [5 4] to [5 4] and put barrier at 0, with max steps = 4\n\nExecute Random Walk!\nAn exception raised. The traceback is as follows:\nTraceback (most recent call last):\n  File \"/home/ml/users/ksinha4/mlp/comp424_final_project/submissions/comp424mcgill/final-project-a_new_team/world.py\", line 310, in step\n    raise ValueError(\nValueError: [INVALID:STEP] Not a valid step from [5 4] to [5 4] and put barrier at 0, with max steps = 4\n\nExecute Random Walk!\n"}, {"student_agent_score": 2, "random_agent_score": 98, "student_agent_time": 0.005625247955322266, "random_agent_time": 0.006700992584228516, "board_size": 10, "swap_players": false, "run_out": "An exception raised. The traceback is as follows:\nTraceback (most recent call last):\n  File \"/home/ml/users/ksinha4/mlp/comp424_final_project/submissions/comp424mcgill/final-project-a_new_team/world.py\", line 310, in step\n    raise ValueError(\nValueError: [INVALID:STEP] Not a valid step from [7 5] to [7 5] and put barrier at 0, with max steps = 5\n\nExecute Random Walk!\nAn exception raised. The traceback is as follows:\nTraceback (most recent call last):\n  File \"/home/ml/users/ksinha4/mlp/comp424_final_project/submissions/comp424mcgill/final-project-a_new_team/world.py\", line 310, in step\n    raise ValueError(\nValueError: [INVALID:STEP] Not a valid step from [6 6] to [6 6] and put barrier at 0, with max steps = 5\n\nExecute Random Walk!\nAn exception raised. The traceback is as follows:\nTraceback (most recent call last):\n  File \"/home/ml/users/ksinha4/mlp/comp424_final_project/submissions/comp424mcgill/final-project-a_new_team/world.py\", line 310, in step\n    raise ValueError(\nValueError: [INVALID:STEP] Not a valid step from [7 8] to [7 8] and put barrier at 0, with max steps = 5\n\nExecute Random Walk!\nAn exception raised. The traceback is as follows:\nTraceback (most recent call last):\n  File \"/home/ml/users/ksinha4/mlp/comp424_final_project/submissions/comp424mcgill/final-project-a_new_team/world.py\", line 310, in step\n    raise ValueError(\nValueError: [INVALID:STEP] Not a valid step from [7 8] to [7 8] and put barrier at 0, with max steps = 5\n\nExecute Random Walk!\n"}, {"student_agent_score": 1, "random_agent_score": 48, "student_agent_time": 0.0022644996643066406, "random_agent_time": 0.002023458480834961, "board_size": 7, "swap_players": true, "run_out": "An exception raised. The traceback is as follows:\nTraceback (most recent call last):\n  File \"/home/ml/users/ksinha4/mlp/comp424_final_project/submissions/comp424mcgill/final-project-a_new_team/world.py\", line 310, in step\n    raise ValueError(\nValueError: [INVALID:STEP] Not a valid step from [2 3] to [2 3] and put barrier at 0, with max steps = 4\n\nExecute Random Walk!\nAn exception raised. The traceback is as follows:\nTraceback (most recent call last):\n  File \"/home/ml/users/ksinha4/mlp/comp424_final_project/submissions/comp424mcgill/final-project-a_new_team/world.py\", line 310, in step\n    raise ValueError(\nValueError: [INVALID:STEP] Not a valid step from [5 4] to [5 4] and put barrier at 0, with max steps = 4\n\nExecute Random Walk!\nAn exception raised. The traceback is as follows:\nTraceback (most recent call last):\n  File \"/home/ml/users/ksinha4/mlp/comp424_final_project/submissions/comp424mcgill/final-project-a_new_team/world.py\", line 310, in step\n    raise ValueError(\nValueError: [INVALID:STEP] Not a valid step from [6 3] to [6 3] and put barrier at 0, with max steps = 4\n\nExecute Random Walk!\n"}, {"student_agent_score": 80, "random_agent_score": 1, "student_agent_time": 0.004589080810546875, "random_agent_time": 0.006852388381958008, "board_size": 9, "swap_players": true, "run_out": "An exception raised. The traceback is as follows:\nTraceback (most recent call last):\n  File \"/home/ml/users/ksinha4/mlp/comp424_final_project/submissions/comp424mcgill/final-project-a_new_team/world.py\", line 310, in step\n    raise ValueError(\nValueError: [INVALID:STEP] Not a valid step from [3 4] to [3 4] and put barrier at 0, with max steps = 5\n\nExecute Random Walk!\nAn exception raised. The traceback is as follows:\nTraceback (most recent call last):\n  File \"/home/ml/users/ksinha4/mlp/comp424_final_project/submissions/comp424mcgill/final-project-a_new_team/world.py\", line 310, in step\n    raise ValueError(\nValueError: [INVALID:STEP] Not a valid step from [3 5] to [3 5] and put barrier at 0, with max steps = 5\n\nExecute Random Walk!\nAn exception raised. The traceback is as follows:\nTraceback (most recent call last):\n  File \"/home/ml/users/ksinha4/mlp/comp424_final_project/submissions/comp424mcgill/final-project-a_new_team/world.py\", line 310, in step\n    raise ValueError(\nValueError: [INVALID:STEP] Not a valid step from [3 4] to [3 4] and put barrier at 0, with max steps = 5\n\nExecute Random Walk!\nAn exception raised. The traceback is as follows:\nTraceback (most recent call last):\n  File \"/home/ml/users/ksinha4/mlp/comp424_final_project/submissions/comp424mcgill/final-project-a_new_team/world.py\", line 310, in step\n    raise ValueError(\nValueError: [INVALID:STEP] Not a valid step from [5 4] to [5 4] and put barrier at 0, with max steps = 5\n\nExecute Random Walk!\nAn exception raised. The traceback is as follows:\nTraceback (most recent call last):\n  File \"/home/ml/users/ksinha4/mlp/comp424_final_project/submissions/comp424mcgill/final-project-a_new_team/world.py\", line 310, in step\n    raise ValueError(\nValueError: [INVALID:STEP] Not a valid step from [5 5] to [5 5] and put barrier at 0, with max steps = 5\n\nExecute Random Walk!\n"}, {"student_agent_score": 1, "random_agent_score": 48, "student_agent_time": 0.0037260055541992188, "random_agent_time": 0.0025343894958496094, "board_size": 7, "swap_players": false, "run_out": "An exception raised. The traceback is as follows:\nTraceback (most recent call last):\n  File \"/home/ml/users/ksinha4/mlp/comp424_final_project/submissions/comp424mcgill/final-project-a_new_team/world.py\", line 310, in step\n    raise ValueError(\nValueError: [INVALID:STEP] Not a valid step from [4 3] to [4 3] and put barrier at 0, with max steps = 4\n\nExecute Random Walk!\nAn exception raised. The traceback is as follows:\nTraceback (most recent call last):\n  File \"/home/ml/users/ksinha4/mlp/comp424_final_project/submissions/comp424mcgill/final-project-a_new_team/world.py\", line 310, in step\n    raise ValueError(\nValueError: [INVALID:STEP] Not a valid step from [4 2] to [4 2] and put barrier at 0, with max steps = 4\n\nExecute Random Walk!\nAn exception raised. The traceback is as follows:\nTraceback (most recent call last):\n  File \"/home/ml/users/ksinha4/mlp/comp424_final_project/submissions/comp424mcgill/final-project-a_new_team/world.py\", line 310, in step\n    raise ValueError(\nValueError: [INVALID:STEP] Not a valid step from [4 3] to [4 3] and put barrier at 0, with max steps = 4\n\nExecute Random Walk!\nAn exception raised. The traceback is as follows:\nTraceback (most recent call last):\n  File \"/home/ml/users/ksinha4/mlp/comp424_final_project/submissions/comp424mcgill/final-project-a_new_team/world.py\", line 310, in step\n    raise ValueError(\nValueError: [INVALID:STEP] Not a valid step from [5 4] to [5 4] and put barrier at 0, with max steps = 4\n\nExecute Random Walk!\nAn exception raised. The traceback is as follows:\nTraceback (most recent call last):\n  File \"/home/ml/users/ksinha4/mlp/comp424_final_project/submissions/comp424mcgill/final-project-a_new_team/world.py\", line 310, in step\n    raise ValueError(\nValueError: [INVALID:STEP] Not a valid step from [6 3] to [6 3] and put barrier at 0, with max steps = 4\n\nExecute Random Walk!\n"}, {"student_agent_score": 1, "random_agent_score": 48, "student_agent_time": 0.004930734634399414, "random_agent_time": 0.002471923828125, "board_size": 7, "swap_players": false, "run_out": "An exception raised. The traceback is as follows:\nTraceback (most recent call last):\n  File \"/home/ml/users/ksinha4/mlp/comp424_final_project/submissions/comp424mcgill/final-project-a_new_team/world.py\", line 310, in step\n    raise ValueError(\nValueError: [INVALID:STEP] Not a valid step from [4 3] to [4 3] and put barrier at 0, with max steps = 4\n\nExecute Random Walk!\nAn exception raised. The traceback is as follows:\nTraceback (most recent call last):\n  File \"/home/ml/users/ksinha4/mlp/comp424_final_project/submissions/comp424mcgill/final-project-a_new_team/world.py\", line 310, in step\n    raise ValueError(\nValueError: [INVALID:STEP] Not a valid step from [4 2] to [4 2] and put barrier at 0, with max steps = 4\n\nExecute Random Walk!\nAn exception raised. The traceback is as follows:\nTraceback (most recent call last):\n  File \"/home/ml/users/ksinha4/mlp/comp424_final_project/submissions/comp424mcgill/final-project-a_new_team/world.py\", line 310, in step\n    raise ValueError(\nValueError: [INVALID:STEP] Not a valid step from [4 3] to [4 3] and put barrier at 0, with max steps = 4\n\nExecute Random Walk!\nAn exception raised. The traceback is as follows:\nTraceback (most recent call last):\n  File \"/home/ml/users/ksinha4/mlp/comp424_final_project/submissions/comp424mcgill/final-project-a_new_team/world.py\", line 310, in step\n    raise ValueError(\nValueError: [INVALID:STEP] Not a valid step from [5 4] to [5 4] and put barrier at 0, with max steps = 4\n\nExecute Random Walk!\nAn exception raised. The traceback is as follows:\nTraceback (most recent call last):\n  File \"/home/ml/users/ksinha4/mlp/comp424_final_project/submissions/comp424mcgill/final-project-a_new_team/world.py\", line 310, in step\n    raise ValueError(\nValueError: [INVALID:STEP] Not a valid step from [6 3] to [6 3] and put barrier at 0, with max steps = 4\n\nExecute Random Walk!\n"}, {"student_agent_score": 63, "random_agent_score": 1, "student_agent_time": 0.0037245750427246094, "random_agent_time": 0.0030901432037353516, "board_size": 8, "swap_players": true, "run_out": "An exception raised. The traceback is as follows:\nTraceback (most recent call last):\n  File \"/home/ml/users/ksinha4/mlp/comp424_final_project/submissions/comp424mcgill/final-project-a_new_team/world.py\", line 310, in step\n    raise ValueError(\nValueError: [INVALID:STEP] Not a valid step from [5 5] to [5 5] and put barrier at 0, with max steps = 4\n\nExecute Random Walk!\nAn exception raised. The traceback is as follows:\nTraceback (most recent call last):\n  File \"/home/ml/users/ksinha4/mlp/comp424_final_project/submissions/comp424mcgill/final-project-a_new_team/world.py\", line 310, in step\n    raise ValueError(\nValueError: [INVALID:STEP] Not a valid step from [5 4] to [5 4] and put barrier at 0, with max steps = 4\n\nExecute Random Walk!\nAn exception raised. The traceback is as follows:\nTraceback (most recent call last):\n  File \"/home/ml/users/ksinha4/mlp/comp424_final_project/submissions/comp424mcgill/final-project-a_new_team/world.py\", line 310, in step\n    raise ValueError(\nValueError: [INVALID:STEP] Not a valid step from [5 4] to [5 4] and put barrier at 0, with max steps = 4\n\nExecute Random Walk!\n"}, {"student_agent_score": 2, "random_agent_score": 98, "student_agent_time": 0.0046732425689697266, "random_agent_time": 0.006979465484619141, "board_size": 10, "swap_players": false, "run_out": "An exception raised. The traceback is as follows:\nTraceback (most recent call last):\n  File \"/home/ml/users/ksinha4/mlp/comp424_final_project/submissions/comp424mcgill/final-project-a_new_team/world.py\", line 310, in step\n    raise ValueError(\nValueError: [INVALID:STEP] Not a valid step from [7 5] to [7 5] and put barrier at 0, with max steps = 5\n\nExecute Random Walk!\nAn exception raised. The traceback is as follows:\nTraceback (most recent call last):\n  File \"/home/ml/users/ksinha4/mlp/comp424_final_project/submissions/comp424mcgill/final-project-a_new_team/world.py\", line 310, in step\n    raise ValueError(\nValueError: [INVALID:STEP] Not a valid step from [6 6] to [6 6] and put barrier at 0, with max steps = 5\n\nExecute Random Walk!\nAn exception raised. The traceback is as follows:\nTraceback (most recent call last):\n  File \"/home/ml/users/ksinha4/mlp/comp424_final_project/submissions/comp424mcgill/final-project-a_new_team/world.py\", line 310, in step\n    raise ValueError(\nValueError: [INVALID:STEP] Not a valid step from [7 8] to [7 8] and put barrier at 0, with max steps = 5\n\nExecute Random Walk!\nAn exception raised. The traceback is as follows:\nTraceback (most recent call last):\n  File \"/home/ml/users/ksinha4/mlp/comp424_final_project/submissions/comp424mcgill/final-project-a_new_team/world.py\", line 310, in step\n    raise ValueError(\nValueError: [INVALID:STEP] Not a valid step from [7 8] to [7 8] and put barrier at 0, with max steps = 5\n\nExecute Random Walk!\n"}, {"student_agent_score": 1, "random_agent_score": 63, "student_agent_time": 0.005940914154052734, "random_agent_time": 0.002888202667236328, "board_size": 8, "swap_players": false, "run_out": "An exception raised. The traceback is as follows:\nTraceback (most recent call last):\n  File \"/home/ml/users/ksinha4/mlp/comp424_final_project/submissions/comp424mcgill/final-project-a_new_team/world.py\", line 310, in step\n    raise ValueError(\nValueError: [INVALID:STEP] Not a valid step from [2 2] to [2 2] and put barrier at 0, with max steps = 4\n\nExecute Random Walk!\nAn exception raised. The traceback is as follows:\nTraceback (most recent call last):\n  File \"/home/ml/users/ksinha4/mlp/comp424_final_project/submissions/comp424mcgill/final-project-a_new_team/world.py\", line 310, in step\n    raise ValueError(\nValueError: [INVALID:STEP] Not a valid step from [3 1] to [3 1] and put barrier at 0, with max steps = 4\n\nExecute Random Walk!\nAn exception raised. The traceback is as follows:\nTraceback (most recent call last):\n  File \"/home/ml/users/ksinha4/mlp/comp424_final_project/submissions/comp424mcgill/final-project-a_new_team/world.py\", line 310, in step\n    raise ValueError(\nValueError: [INVALID:STEP] Not a valid step from [3 0] to [3 0] and put barrier at 0, with max steps = 4\n\nExecute Random Walk!\nAn exception raised. The traceback is as follows:\nTraceback (most recent call last):\n  File \"/home/ml/users/ksinha4/mlp/comp424_final_project/submissions/comp424mcgill/final-project-a_new_team/world.py\", line 310, in step\n    raise ValueError(\nValueError: [INVALID:STEP] Not a valid step from [6 1] to [6 1] and put barrier at 0, with max steps = 4\n\nExecute Random Walk!\n"}, {"student_agent_score": 1, "random_agent_score": 48, "student_agent_time": 0.0035381317138671875, "random_agent_time": 0.0044209957122802734, "board_size": 7, "swap_players": true, "run_out": "An exception raised. The traceback is as follows:\nTraceback (most recent call last):\n  File \"/home/ml/users/ksinha4/mlp/comp424_final_project/submissions/comp424mcgill/final-project-a_new_team/world.py\", line 310, in step\n    raise ValueError(\nValueError: [INVALID:STEP] Not a valid step from [2 3] to [2 3] and put barrier at 0, with max steps = 4\n\nExecute Random Walk!\nAn exception raised. The traceback is as follows:\nTraceback (most recent call last):\n  File \"/home/ml/users/ksinha4/mlp/comp424_final_project/submissions/comp424mcgill/final-project-a_new_team/world.py\", line 310, in step\n    raise ValueError(\nValueError: [INVALID:STEP] Not a valid step from [5 4] to [5 4] and put barrier at 0, with max steps = 4\n\nExecute Random Walk!\nAn exception raised. The traceback is as follows:\nTraceback (most recent call last):\n  File \"/home/ml/users/ksinha4/mlp/comp424_final_project/submissions/comp424mcgill/final-project-a_new_team/world.py\", line 310, in step\n    raise ValueError(\nValueError: [INVALID:STEP] Not a valid step from [6 3] to [6 3] and put barrier at 0, with max steps = 4\n\nExecute Random Walk!\n"}, {"student_agent_score": 1, "random_agent_score": 48, "student_agent_time": 0.00616765022277832, "random_agent_time": 0.002112150192260742, "board_size": 7, "swap_players": false, "run_out": "An exception raised. The traceback is as follows:\nTraceback (most recent call last):\n  File \"/home/ml/users/ksinha4/mlp/comp424_final_project/submissions/comp424mcgill/final-project-a_new_team/world.py\", line 310, in step\n    raise ValueError(\nValueError: [INVALID:STEP] Not a valid step from [4 3] to [4 3] and put barrier at 0, with max steps = 4\n\nExecute Random Walk!\nAn exception raised. The traceback is as follows:\nTraceback (most recent call last):\n  File \"/home/ml/users/ksinha4/mlp/comp424_final_project/submissions/comp424mcgill/final-project-a_new_team/world.py\", line 310, in step\n    raise ValueError(\nValueError: [INVALID:STEP] Not a valid step from [4 2] to [4 2] and put barrier at 0, with max steps = 4\n\nExecute Random Walk!\nAn exception raised. The traceback is as follows:\nTraceback (most recent call last):\n  File \"/home/ml/users/ksinha4/mlp/comp424_final_project/submissions/comp424mcgill/final-project-a_new_team/world.py\", line 310, in step\n    raise ValueError(\nValueError: [INVALID:STEP] Not a valid step from [4 3] to [4 3] and put barrier at 0, with max steps = 4\n\nExecute Random Walk!\nAn exception raised. The traceback is as follows:\nTraceback (most recent call last):\n  File \"/home/ml/users/ksinha4/mlp/comp424_final_project/submissions/comp424mcgill/final-project-a_new_team/world.py\", line 310, in step\n    raise ValueError(\nValueError: [INVALID:STEP] Not a valid step from [5 4] to [5 4] and put barrier at 0, with max steps = 4\n\nExecute Random Walk!\nAn exception raised. The traceback is as follows:\nTraceback (most recent call last):\n  File \"/home/ml/users/ksinha4/mlp/comp424_final_project/submissions/comp424mcgill/final-project-a_new_team/world.py\", line 310, in step\n    raise ValueError(\nValueError: [INVALID:STEP] Not a valid step from [6 3] to [6 3] and put barrier at 0, with max steps = 4\n\nExecute Random Walk!\n"}, {"student_agent_score": 80, "random_agent_score": 1, "student_agent_time": 0.005838632583618164, "random_agent_time": 0.007187843322753906, "board_size": 9, "swap_players": true, "run_out": "An exception raised. The traceback is as follows:\nTraceback (most recent call last):\n  File \"/home/ml/users/ksinha4/mlp/comp424_final_project/submissions/comp424mcgill/final-project-a_new_team/world.py\", line 310, in step\n    raise ValueError(\nValueError: [INVALID:STEP] Not a valid step from [3 4] to [3 4] and put barrier at 0, with max steps = 5\n\nExecute Random Walk!\nAn exception raised. The traceback is as follows:\nTraceback (most recent call last):\n  File \"/home/ml/users/ksinha4/mlp/comp424_final_project/submissions/comp424mcgill/final-project-a_new_team/world.py\", line 310, in step\n    raise ValueError(\nValueError: [INVALID:STEP] Not a valid step from [3 5] to [3 5] and put barrier at 0, with max steps = 5\n\nExecute Random Walk!\nAn exception raised. The traceback is as follows:\nTraceback (most recent call last):\n  File \"/home/ml/users/ksinha4/mlp/comp424_final_project/submissions/comp424mcgill/final-project-a_new_team/world.py\", line 310, in step\n    raise ValueError(\nValueError: [INVALID:STEP] Not a valid step from [3 4] to [3 4] and put barrier at 0, with max steps = 5\n\nExecute Random Walk!\nAn exception raised. The traceback is as follows:\nTraceback (most recent call last):\n  File \"/home/ml/users/ksinha4/mlp/comp424_final_project/submissions/comp424mcgill/final-project-a_new_team/world.py\", line 310, in step\n    raise ValueError(\nValueError: [INVALID:STEP] Not a valid step from [5 4] to [5 4] and put barrier at 0, with max steps = 5\n\nExecute Random Walk!\nAn exception raised. The traceback is as follows:\nTraceback (most recent call last):\n  File \"/home/ml/users/ksinha4/mlp/comp424_final_project/submissions/comp424mcgill/final-project-a_new_team/world.py\", line 310, in step\n    raise ValueError(\nValueError: [INVALID:STEP] Not a valid step from [5 5] to [5 5] and put barrier at 0, with max steps = 5\n\nExecute Random Walk!\n"}, {"student_agent_score": 63, "random_agent_score": 1, "student_agent_time": 0.002834320068359375, "random_agent_time": 0.003229856491088867, "board_size": 8, "swap_players": true, "run_out": "An exception raised. The traceback is as follows:\nTraceback (most recent call last):\n  File \"/home/ml/users/ksinha4/mlp/comp424_final_project/submissions/comp424mcgill/final-project-a_new_team/world.py\", line 310, in step\n    raise ValueError(\nValueError: [INVALID:STEP] Not a valid step from [5 5] to [5 5] and put barrier at 0, with max steps = 4\n\nExecute Random Walk!\nAn exception raised. The traceback is as follows:\nTraceback (most recent call last):\n  File \"/home/ml/users/ksinha4/mlp/comp424_final_project/submissions/comp424mcgill/final-project-a_new_team/world.py\", line 310, in step\n    raise ValueError(\nValueError: [INVALID:STEP] Not a valid step from [5 4] to [5 4] and put barrier at 0, with max steps = 4\n\nExecute Random Walk!\nAn exception raised. The traceback is as follows:\nTraceback (most recent call last):\n  File \"/home/ml/users/ksinha4/mlp/comp424_final_project/submissions/comp424mcgill/final-project-a_new_team/world.py\", line 310, in step\n    raise ValueError(\nValueError: [INVALID:STEP] Not a valid step from [5 4] to [5 4] and put barrier at 0, with max steps = 4\n\nExecute Random Walk!\n"}, {"student_agent_score": 1, "random_agent_score": 48, "student_agent_time": 0.006081342697143555, "random_agent_time": 0.005228519439697266, "board_size": 7, "swap_players": false, "run_out": "An exception raised. The traceback is as follows:\nTraceback (most recent call last):\n  File \"/home/ml/users/ksinha4/mlp/comp424_final_project/submissions/comp424mcgill/final-project-a_new_team/world.py\", line 310, in step\n    raise ValueError(\nValueError: [INVALID:STEP] Not a valid step from [4 3] to [4 3] and put barrier at 0, with max steps = 4\n\nExecute Random Walk!\nAn exception raised. The traceback is as follows:\nTraceback (most recent call last):\n  File \"/home/ml/users/ksinha4/mlp/comp424_final_project/submissions/comp424mcgill/final-project-a_new_team/world.py\", line 310, in step\n    raise ValueError(\nValueError: [INVALID:STEP] Not a valid step from [4 2] to [4 2] and put barrier at 0, with max steps = 4\n\nExecute Random Walk!\nAn exception raised. The traceback is as follows:\nTraceback (most recent call last):\n  File \"/home/ml/users/ksinha4/mlp/comp424_final_project/submissions/comp424mcgill/final-project-a_new_team/world.py\", line 310, in step\n    raise ValueError(\nValueError: [INVALID:STEP] Not a valid step from [4 3] to [4 3] and put barrier at 0, with max steps = 4\n\nExecute Random Walk!\nAn exception raised. The traceback is as follows:\nTraceback (most recent call last):\n  File \"/home/ml/users/ksinha4/mlp/comp424_final_project/submissions/comp424mcgill/final-project-a_new_team/world.py\", line 310, in step\n    raise ValueError(\nValueError: [INVALID:STEP] Not a valid step from [5 4] to [5 4] and put barrier at 0, with max steps = 4\n\nExecute Random Walk!\nAn exception raised. The traceback is as follows:\nTraceback (most recent call last):\n  File \"/home/ml/users/ksinha4/mlp/comp424_final_project/submissions/comp424mcgill/final-project-a_new_team/world.py\", line 310, in step\n    raise ValueError(\nValueError: [INVALID:STEP] Not a valid step from [6 3] to [6 3] and put barrier at 0, with max steps = 4\n\nExecute Random Walk!\n"}, {"student_agent_score": 1, "random_agent_score": 48, "student_agent_time": 0.0025665760040283203, "random_agent_time": 0.0023956298828125, "board_size": 7, "swap_players": true, "run_out": "An exception raised. The traceback is as follows:\nTraceback (most recent call last):\n  File \"/home/ml/users/ksinha4/mlp/comp424_final_project/submissions/comp424mcgill/final-project-a_new_team/world.py\", line 310, in step\n    raise ValueError(\nValueError: [INVALID:STEP] Not a valid step from [2 3] to [2 3] and put barrier at 0, with max steps = 4\n\nExecute Random Walk!\nAn exception raised. The traceback is as follows:\nTraceback (most recent call last):\n  File \"/home/ml/users/ksinha4/mlp/comp424_final_project/submissions/comp424mcgill/final-project-a_new_team/world.py\", line 310, in step\n    raise ValueError(\nValueError: [INVALID:STEP] Not a valid step from [5 4] to [5 4] and put barrier at 0, with max steps = 4\n\nExecute Random Walk!\nAn exception raised. The traceback is as follows:\nTraceback (most recent call last):\n  File \"/home/ml/users/ksinha4/mlp/comp424_final_project/submissions/comp424mcgill/final-project-a_new_team/world.py\", line 310, in step\n    raise ValueError(\nValueError: [INVALID:STEP] Not a valid step from [6 3] to [6 3] and put barrier at 0, with max steps = 4\n\nExecute Random Walk!\n"}, {"student_agent_score": 1, "random_agent_score": 35, "student_agent_time": 0.003679990768432617, "random_agent_time": 0.0009815692901611328, "board_size": 6, "swap_players": false, "run_out": "An exception raised. The traceback is as follows:\nTraceback (most recent call last):\n  File \"/home/ml/users/ksinha4/mlp/comp424_final_project/submissions/comp424mcgill/final-project-a_new_team/world.py\", line 310, in step\n    raise ValueError(\nValueError: [INVALID:STEP] Not a valid step from [2 2] to [2 2] and put barrier at 0, with max steps = 3\n\nExecute Random Walk!\nAn exception raised. The traceback is as follows:\nTraceback (most recent call last):\n  File \"/home/ml/users/ksinha4/mlp/comp424_final_project/submissions/comp424mcgill/final-project-a_new_team/world.py\", line 310, in step\n    raise ValueError(\nValueError: [INVALID:STEP] Not a valid step from [3 0] to [3 0] and put barrier at 0, with max steps = 3\n\nExecute Random Walk!\n"}, {"student_agent_score": 1, "random_agent_score": 48, "student_agent_time": 0.002591848373413086, "random_agent_time": 0.004502296447753906, "board_size": 7, "swap_players": true, "run_out": "An exception raised. The traceback is as follows:\nTraceback (most recent call last):\n  File \"/home/ml/users/ksinha4/mlp/comp424_final_project/submissions/comp424mcgill/final-project-a_new_team/world.py\", line 310, in step\n    raise ValueError(\nValueError: [INVALID:STEP] Not a valid step from [2 3] to [2 3] and put barrier at 0, with max steps = 4\n\nExecute Random Walk!\nAn exception raised. The traceback is as follows:\nTraceback (most recent call last):\n  File \"/home/ml/users/ksinha4/mlp/comp424_final_project/submissions/comp424mcgill/final-project-a_new_team/world.py\", line 310, in step\n    raise ValueError(\nValueError: [INVALID:STEP] Not a valid step from [5 4] to [5 4] and put barrier at 0, with max steps = 4\n\nExecute Random Walk!\nAn exception raised. The traceback is as follows:\nTraceback (most recent call last):\n  File \"/home/ml/users/ksinha4/mlp/comp424_final_project/submissions/comp424mcgill/final-project-a_new_team/world.py\", line 310, in step\n    raise ValueError(\nValueError: [INVALID:STEP] Not a valid step from [6 3] to [6 3] and put barrier at 0, with max steps = 4\n\nExecute Random Walk!\n"}, {"student_agent_score": 1, "random_agent_score": 48, "student_agent_time": 0.003928661346435547, "random_agent_time": 0.004687786102294922, "board_size": 7, "swap_players": false, "run_out": "An exception raised. The traceback is as follows:\nTraceback (most recent call last):\n  File \"/home/ml/users/ksinha4/mlp/comp424_final_project/submissions/comp424mcgill/final-project-a_new_team/world.py\", line 310, in step\n    raise ValueError(\nValueError: [INVALID:STEP] Not a valid step from [4 3] to [4 3] and put barrier at 0, with max steps = 4\n\nExecute Random Walk!\nAn exception raised. The traceback is as follows:\nTraceback (most recent call last):\n  File \"/home/ml/users/ksinha4/mlp/comp424_final_project/submissions/comp424mcgill/final-project-a_new_team/world.py\", line 310, in step\n    raise ValueError(\nValueError: [INVALID:STEP] Not a valid step from [4 2] to [4 2] and put barrier at 0, with max steps = 4\n\nExecute Random Walk!\nAn exception raised. The traceback is as follows:\nTraceback (most recent call last):\n  File \"/home/ml/users/ksinha4/mlp/comp424_final_project/submissions/comp424mcgill/final-project-a_new_team/world.py\", line 310, in step\n    raise ValueError(\nValueError: [INVALID:STEP] Not a valid step from [4 3] to [4 3] and put barrier at 0, with max steps = 4\n\nExecute Random Walk!\nAn exception raised. The traceback is as follows:\nTraceback (most recent call last):\n  File \"/home/ml/users/ksinha4/mlp/comp424_final_project/submissions/comp424mcgill/final-project-a_new_team/world.py\", line 310, in step\n    raise ValueError(\nValueError: [INVALID:STEP] Not a valid step from [5 4] to [5 4] and put barrier at 0, with max steps = 4\n\nExecute Random Walk!\nAn exception raised. The traceback is as follows:\nTraceback (most recent call last):\n  File \"/home/ml/users/ksinha4/mlp/comp424_final_project/submissions/comp424mcgill/final-project-a_new_team/world.py\", line 310, in step\n    raise ValueError(\nValueError: [INVALID:STEP] Not a valid step from [6 3] to [6 3] and put barrier at 0, with max steps = 4\n\nExecute Random Walk!\n"}, {"student_agent_score": 1, "random_agent_score": 48, "student_agent_time": 0.0044097900390625, "random_agent_time": 0.003927946090698242, "board_size": 7, "swap_players": false, "run_out": "An exception raised. The traceback is as follows:\nTraceback (most recent call last):\n  File \"/home/ml/users/ksinha4/mlp/comp424_final_project/submissions/comp424mcgill/final-project-a_new_team/world.py\", line 310, in step\n    raise ValueError(\nValueError: [INVALID:STEP] Not a valid step from [4 3] to [4 3] and put barrier at 0, with max steps = 4\n\nExecute Random Walk!\nAn exception raised. The traceback is as follows:\nTraceback (most recent call last):\n  File \"/home/ml/users/ksinha4/mlp/comp424_final_project/submissions/comp424mcgill/final-project-a_new_team/world.py\", line 310, in step\n    raise ValueError(\nValueError: [INVALID:STEP] Not a valid step from [4 2] to [4 2] and put barrier at 0, with max steps = 4\n\nExecute Random Walk!\nAn exception raised. The traceback is as follows:\nTraceback (most recent call last):\n  File \"/home/ml/users/ksinha4/mlp/comp424_final_project/submissions/comp424mcgill/final-project-a_new_team/world.py\", line 310, in step\n    raise ValueError(\nValueError: [INVALID:STEP] Not a valid step from [4 3] to [4 3] and put barrier at 0, with max steps = 4\n\nExecute Random Walk!\nAn exception raised. The traceback is as follows:\nTraceback (most recent call last):\n  File \"/home/ml/users/ksinha4/mlp/comp424_final_project/submissions/comp424mcgill/final-project-a_new_team/world.py\", line 310, in step\n    raise ValueError(\nValueError: [INVALID:STEP] Not a valid step from [5 4] to [5 4] and put barrier at 0, with max steps = 4\n\nExecute Random Walk!\nAn exception raised. The traceback is as follows:\nTraceback (most recent call last):\n  File \"/home/ml/users/ksinha4/mlp/comp424_final_project/submissions/comp424mcgill/final-project-a_new_team/world.py\", line 310, in step\n    raise ValueError(\nValueError: [INVALID:STEP] Not a valid step from [6 3] to [6 3] and put barrier at 0, with max steps = 4\n\nExecute Random Walk!\n"}, {"student_agent_score": 1, "random_agent_score": 48, "student_agent_time": 0.004360675811767578, "random_agent_time": 0.0029637813568115234, "board_size": 7, "swap_players": false, "run_out": "An exception raised. The traceback is as follows:\nTraceback (most recent call last):\n  File \"/home/ml/users/ksinha4/mlp/comp424_final_project/submissions/comp424mcgill/final-project-a_new_team/world.py\", line 310, in step\n    raise ValueError(\nValueError: [INVALID:STEP] Not a valid step from [4 3] to [4 3] and put barrier at 0, with max steps = 4\n\nExecute Random Walk!\nAn exception raised. The traceback is as follows:\nTraceback (most recent call last):\n  File \"/home/ml/users/ksinha4/mlp/comp424_final_project/submissions/comp424mcgill/final-project-a_new_team/world.py\", line 310, in step\n    raise ValueError(\nValueError: [INVALID:STEP] Not a valid step from [4 2] to [4 2] and put barrier at 0, with max steps = 4\n\nExecute Random Walk!\nAn exception raised. The traceback is as follows:\nTraceback (most recent call last):\n  File \"/home/ml/users/ksinha4/mlp/comp424_final_project/submissions/comp424mcgill/final-project-a_new_team/world.py\", line 310, in step\n    raise ValueError(\nValueError: [INVALID:STEP] Not a valid step from [4 3] to [4 3] and put barrier at 0, with max steps = 4\n\nExecute Random Walk!\nAn exception raised. The traceback is as follows:\nTraceback (most recent call last):\n  File \"/home/ml/users/ksinha4/mlp/comp424_final_project/submissions/comp424mcgill/final-project-a_new_team/world.py\", line 310, in step\n    raise ValueError(\nValueError: [INVALID:STEP] Not a valid step from [5 4] to [5 4] and put barrier at 0, with max steps = 4\n\nExecute Random Walk!\nAn exception raised. The traceback is as follows:\nTraceback (most recent call last):\n  File \"/home/ml/users/ksinha4/mlp/comp424_final_project/submissions/comp424mcgill/final-project-a_new_team/world.py\", line 310, in step\n    raise ValueError(\nValueError: [INVALID:STEP] Not a valid step from [6 3] to [6 3] and put barrier at 0, with max steps = 4\n\nExecute Random Walk!\n"}, {"student_agent_score": 1, "random_agent_score": 48, "student_agent_time": 0.002864837646484375, "random_agent_time": 0.002414226531982422, "board_size": 7, "swap_players": true, "run_out": "An exception raised. The traceback is as follows:\nTraceback (most recent call last):\n  File \"/home/ml/users/ksinha4/mlp/comp424_final_project/submissions/comp424mcgill/final-project-a_new_team/world.py\", line 310, in step\n    raise ValueError(\nValueError: [INVALID:STEP] Not a valid step from [2 3] to [2 3] and put barrier at 0, with max steps = 4\n\nExecute Random Walk!\nAn exception raised. The traceback is as follows:\nTraceback (most recent call last):\n  File \"/home/ml/users/ksinha4/mlp/comp424_final_project/submissions/comp424mcgill/final-project-a_new_team/world.py\", line 310, in step\n    raise ValueError(\nValueError: [INVALID:STEP] Not a valid step from [5 4] to [5 4] and put barrier at 0, with max steps = 4\n\nExecute Random Walk!\nAn exception raised. The traceback is as follows:\nTraceback (most recent call last):\n  File \"/home/ml/users/ksinha4/mlp/comp424_final_project/submissions/comp424mcgill/final-project-a_new_team/world.py\", line 310, in step\n    raise ValueError(\nValueError: [INVALID:STEP] Not a valid step from [6 3] to [6 3] and put barrier at 0, with max steps = 4\n\nExecute Random Walk!\n"}, {"student_agent_score": 1, "random_agent_score": 48, "student_agent_time": 0.0027108192443847656, "random_agent_time": 0.0031604766845703125, "board_size": 7, "swap_players": true, "run_out": "An exception raised. The traceback is as follows:\nTraceback (most recent call last):\n  File \"/home/ml/users/ksinha4/mlp/comp424_final_project/submissions/comp424mcgill/final-project-a_new_team/world.py\", line 310, in step\n    raise ValueError(\nValueError: [INVALID:STEP] Not a valid step from [2 3] to [2 3] and put barrier at 0, with max steps = 4\n\nExecute Random Walk!\nAn exception raised. The traceback is as follows:\nTraceback (most recent call last):\n  File \"/home/ml/users/ksinha4/mlp/comp424_final_project/submissions/comp424mcgill/final-project-a_new_team/world.py\", line 310, in step\n    raise ValueError(\nValueError: [INVALID:STEP] Not a valid step from [5 4] to [5 4] and put barrier at 0, with max steps = 4\n\nExecute Random Walk!\nAn exception raised. The traceback is as follows:\nTraceback (most recent call last):\n  File \"/home/ml/users/ksinha4/mlp/comp424_final_project/submissions/comp424mcgill/final-project-a_new_team/world.py\", line 310, in step\n    raise ValueError(\nValueError: [INVALID:STEP] Not a valid step from [6 3] to [6 3] and put barrier at 0, with max steps = 4\n\nExecute Random Walk!\n"}, {"student_agent_score": 2, "random_agent_score": 98, "student_agent_time": 0.006980419158935547, "random_agent_time": 0.00634312629699707, "board_size": 10, "swap_players": false, "run_out": "An exception raised. The traceback is as follows:\nTraceback (most recent call last):\n  File \"/home/ml/users/ksinha4/mlp/comp424_final_project/submissions/comp424mcgill/final-project-a_new_team/world.py\", line 310, in step\n    raise ValueError(\nValueError: [INVALID:STEP] Not a valid step from [7 5] to [7 5] and put barrier at 0, with max steps = 5\n\nExecute Random Walk!\nAn exception raised. The traceback is as follows:\nTraceback (most recent call last):\n  File \"/home/ml/users/ksinha4/mlp/comp424_final_project/submissions/comp424mcgill/final-project-a_new_team/world.py\", line 310, in step\n    raise ValueError(\nValueError: [INVALID:STEP] Not a valid step from [6 6] to [6 6] and put barrier at 0, with max steps = 5\n\nExecute Random Walk!\nAn exception raised. The traceback is as follows:\nTraceback (most recent call last):\n  File \"/home/ml/users/ksinha4/mlp/comp424_final_project/submissions/comp424mcgill/final-project-a_new_team/world.py\", line 310, in step\n    raise ValueError(\nValueError: [INVALID:STEP] Not a valid step from [7 8] to [7 8] and put barrier at 0, with max steps = 5\n\nExecute Random Walk!\nAn exception raised. The traceback is as follows:\nTraceback (most recent call last):\n  File \"/home/ml/users/ksinha4/mlp/comp424_final_project/submissions/comp424mcgill/final-project-a_new_team/world.py\", line 310, in step\n    raise ValueError(\nValueError: [INVALID:STEP] Not a valid step from [7 8] to [7 8] and put barrier at 0, with max steps = 5\n\nExecute Random Walk!\n"}, {"student_agent_score": 1, "random_agent_score": 63, "student_agent_time": 0.0031735897064208984, "random_agent_time": 0.002998828887939453, "board_size": 8, "swap_players": false, "run_out": "An exception raised. The traceback is as follows:\nTraceback (most recent call last):\n  File \"/home/ml/users/ksinha4/mlp/comp424_final_project/submissions/comp424mcgill/final-project-a_new_team/world.py\", line 310, in step\n    raise ValueError(\nValueError: [INVALID:STEP] Not a valid step from [2 2] to [2 2] and put barrier at 0, with max steps = 4\n\nExecute Random Walk!\nAn exception raised. The traceback is as follows:\nTraceback (most recent call last):\n  File \"/home/ml/users/ksinha4/mlp/comp424_final_project/submissions/comp424mcgill/final-project-a_new_team/world.py\", line 310, in step\n    raise ValueError(\nValueError: [INVALID:STEP] Not a valid step from [3 1] to [3 1] and put barrier at 0, with max steps = 4\n\nExecute Random Walk!\nAn exception raised. The traceback is as follows:\nTraceback (most recent call last):\n  File \"/home/ml/users/ksinha4/mlp/comp424_final_project/submissions/comp424mcgill/final-project-a_new_team/world.py\", line 310, in step\n    raise ValueError(\nValueError: [INVALID:STEP] Not a valid step from [3 0] to [3 0] and put barrier at 0, with max steps = 4\n\nExecute Random Walk!\nAn exception raised. The traceback is as follows:\nTraceback (most recent call last):\n  File \"/home/ml/users/ksinha4/mlp/comp424_final_project/submissions/comp424mcgill/final-project-a_new_team/world.py\", line 310, in step\n    raise ValueError(\nValueError: [INVALID:STEP] Not a valid step from [6 1] to [6 1] and put barrier at 0, with max steps = 4\n\nExecute Random Walk!\n"}, {"student_agent_score": 80, "random_agent_score": 1, "student_agent_time": 0.006147861480712891, "random_agent_time": 0.00594329833984375, "board_size": 9, "swap_players": true, "run_out": "An exception raised. The traceback is as follows:\nTraceback (most recent call last):\n  File \"/home/ml/users/ksinha4/mlp/comp424_final_project/submissions/comp424mcgill/final-project-a_new_team/world.py\", line 310, in step\n    raise ValueError(\nValueError: [INVALID:STEP] Not a valid step from [3 4] to [3 4] and put barrier at 0, with max steps = 5\n\nExecute Random Walk!\nAn exception raised. The traceback is as follows:\nTraceback (most recent call last):\n  File \"/home/ml/users/ksinha4/mlp/comp424_final_project/submissions/comp424mcgill/final-project-a_new_team/world.py\", line 310, in step\n    raise ValueError(\nValueError: [INVALID:STEP] Not a valid step from [3 5] to [3 5] and put barrier at 0, with max steps = 5\n\nExecute Random Walk!\nAn exception raised. The traceback is as follows:\nTraceback (most recent call last):\n  File \"/home/ml/users/ksinha4/mlp/comp424_final_project/submissions/comp424mcgill/final-project-a_new_team/world.py\", line 310, in step\n    raise ValueError(\nValueError: [INVALID:STEP] Not a valid step from [3 4] to [3 4] and put barrier at 0, with max steps = 5\n\nExecute Random Walk!\nAn exception raised. The traceback is as follows:\nTraceback (most recent call last):\n  File \"/home/ml/users/ksinha4/mlp/comp424_final_project/submissions/comp424mcgill/final-project-a_new_team/world.py\", line 310, in step\n    raise ValueError(\nValueError: [INVALID:STEP] Not a valid step from [5 4] to [5 4] and put barrier at 0, with max steps = 5\n\nExecute Random Walk!\nAn exception raised. The traceback is as follows:\nTraceback (most recent call last):\n  File \"/home/ml/users/ksinha4/mlp/comp424_final_project/submissions/comp424mcgill/final-project-a_new_team/world.py\", line 310, in step\n    raise ValueError(\nValueError: [INVALID:STEP] Not a valid step from [5 5] to [5 5] and put barrier at 0, with max steps = 5\n\nExecute Random Walk!\n"}, {"student_agent_score": 99, "random_agent_score": 1, "student_agent_time": 0.00035691261291503906, "random_agent_time": 0.000843048095703125, "board_size": 10, "swap_players": true, "run_out": ""}, {"student_agent_score": 1, "random_agent_score": 48, "student_agent_time": 0.005698442459106445, "random_agent_time": 0.004255771636962891, "board_size": 7, "swap_players": false, "run_out": "An exception raised. The traceback is as follows:\nTraceback (most recent call last):\n  File \"/home/ml/users/ksinha4/mlp/comp424_final_project/submissions/comp424mcgill/final-project-a_new_team/world.py\", line 310, in step\n    raise ValueError(\nValueError: [INVALID:STEP] Not a valid step from [4 3] to [4 3] and put barrier at 0, with max steps = 4\n\nExecute Random Walk!\nAn exception raised. The traceback is as follows:\nTraceback (most recent call last):\n  File \"/home/ml/users/ksinha4/mlp/comp424_final_project/submissions/comp424mcgill/final-project-a_new_team/world.py\", line 310, in step\n    raise ValueError(\nValueError: [INVALID:STEP] Not a valid step from [4 2] to [4 2] and put barrier at 0, with max steps = 4\n\nExecute Random Walk!\nAn exception raised. The traceback is as follows:\nTraceback (most recent call last):\n  File \"/home/ml/users/ksinha4/mlp/comp424_final_project/submissions/comp424mcgill/final-project-a_new_team/world.py\", line 310, in step\n    raise ValueError(\nValueError: [INVALID:STEP] Not a valid step from [4 3] to [4 3] and put barrier at 0, with max steps = 4\n\nExecute Random Walk!\nAn exception raised. The traceback is as follows:\nTraceback (most recent call last):\n  File \"/home/ml/users/ksinha4/mlp/comp424_final_project/submissions/comp424mcgill/final-project-a_new_team/world.py\", line 310, in step\n    raise ValueError(\nValueError: [INVALID:STEP] Not a valid step from [5 4] to [5 4] and put barrier at 0, with max steps = 4\n\nExecute Random Walk!\nAn exception raised. The traceback is as follows:\nTraceback (most recent call last):\n  File \"/home/ml/users/ksinha4/mlp/comp424_final_project/submissions/comp424mcgill/final-project-a_new_team/world.py\", line 310, in step\n    raise ValueError(\nValueError: [INVALID:STEP] Not a valid step from [6 3] to [6 3] and put barrier at 0, with max steps = 4\n\nExecute Random Walk!\n"}, {"student_agent_score": 1, "random_agent_score": 48, "student_agent_time": 0.002624988555908203, "random_agent_time": 0.0023899078369140625, "board_size": 7, "swap_players": true, "run_out": "An exception raised. The traceback is as follows:\nTraceback (most recent call last):\n  File \"/home/ml/users/ksinha4/mlp/comp424_final_project/submissions/comp424mcgill/final-project-a_new_team/world.py\", line 310, in step\n    raise ValueError(\nValueError: [INVALID:STEP] Not a valid step from [2 3] to [2 3] and put barrier at 0, with max steps = 4\n\nExecute Random Walk!\nAn exception raised. The traceback is as follows:\nTraceback (most recent call last):\n  File \"/home/ml/users/ksinha4/mlp/comp424_final_project/submissions/comp424mcgill/final-project-a_new_team/world.py\", line 310, in step\n    raise ValueError(\nValueError: [INVALID:STEP] Not a valid step from [5 4] to [5 4] and put barrier at 0, with max steps = 4\n\nExecute Random Walk!\nAn exception raised. The traceback is as follows:\nTraceback (most recent call last):\n  File \"/home/ml/users/ksinha4/mlp/comp424_final_project/submissions/comp424mcgill/final-project-a_new_team/world.py\", line 310, in step\n    raise ValueError(\nValueError: [INVALID:STEP] Not a valid step from [6 3] to [6 3] and put barrier at 0, with max steps = 4\n\nExecute Random Walk!\n"}, {"student_agent_score": 1, "random_agent_score": 48, "student_agent_time": 0.0034275054931640625, "random_agent_time": 0.002083301544189453, "board_size": 7, "swap_players": false, "run_out": "An exception raised. The traceback is as follows:\nTraceback (most recent call last):\n  File \"/home/ml/users/ksinha4/mlp/comp424_final_project/submissions/comp424mcgill/final-project-a_new_team/world.py\", line 310, in step\n    raise ValueError(\nValueError: [INVALID:STEP] Not a valid step from [4 3] to [4 3] and put barrier at 0, with max steps = 4\n\nExecute Random Walk!\nAn exception raised. The traceback is as follows:\nTraceback (most recent call last):\n  File \"/home/ml/users/ksinha4/mlp/comp424_final_project/submissions/comp424mcgill/final-project-a_new_team/world.py\", line 310, in step\n    raise ValueError(\nValueError: [INVALID:STEP] Not a valid step from [4 2] to [4 2] and put barrier at 0, with max steps = 4\n\nExecute Random Walk!\nAn exception raised. The traceback is as follows:\nTraceback (most recent call last):\n  File \"/home/ml/users/ksinha4/mlp/comp424_final_project/submissions/comp424mcgill/final-project-a_new_team/world.py\", line 310, in step\n    raise ValueError(\nValueError: [INVALID:STEP] Not a valid step from [4 3] to [4 3] and put barrier at 0, with max steps = 4\n\nExecute Random Walk!\nAn exception raised. The traceback is as follows:\nTraceback (most recent call last):\n  File \"/home/ml/users/ksinha4/mlp/comp424_final_project/submissions/comp424mcgill/final-project-a_new_team/world.py\", line 310, in step\n    raise ValueError(\nValueError: [INVALID:STEP] Not a valid step from [5 4] to [5 4] and put barrier at 0, with max steps = 4\n\nExecute Random Walk!\nAn exception raised. The traceback is as follows:\nTraceback (most recent call last):\n  File \"/home/ml/users/ksinha4/mlp/comp424_final_project/submissions/comp424mcgill/final-project-a_new_team/world.py\", line 310, in step\n    raise ValueError(\nValueError: [INVALID:STEP] Not a valid step from [6 3] to [6 3] and put barrier at 0, with max steps = 4\n\nExecute Random Walk!\n"}, {"student_agent_score": 1, "random_agent_score": 48, "student_agent_time": 0.0049512386322021484, "random_agent_time": 0.0034618377685546875, "board_size": 7, "swap_players": true, "run_out": "An exception raised. The traceback is as follows:\nTraceback (most recent call last):\n  File \"/home/ml/users/ksinha4/mlp/comp424_final_project/submissions/comp424mcgill/final-project-a_new_team/world.py\", line 310, in step\n    raise ValueError(\nValueError: [INVALID:STEP] Not a valid step from [2 3] to [2 3] and put barrier at 0, with max steps = 4\n\nExecute Random Walk!\nAn exception raised. The traceback is as follows:\nTraceback (most recent call last):\n  File \"/home/ml/users/ksinha4/mlp/comp424_final_project/submissions/comp424mcgill/final-project-a_new_team/world.py\", line 310, in step\n    raise ValueError(\nValueError: [INVALID:STEP] Not a valid step from [5 4] to [5 4] and put barrier at 0, with max steps = 4\n\nExecute Random Walk!\nAn exception raised. The traceback is as follows:\nTraceback (most recent call last):\n  File \"/home/ml/users/ksinha4/mlp/comp424_final_project/submissions/comp424mcgill/final-project-a_new_team/world.py\", line 310, in step\n    raise ValueError(\nValueError: [INVALID:STEP] Not a valid step from [6 3] to [6 3] and put barrier at 0, with max steps = 4\n\nExecute Random Walk!\n"}, {"student_agent_score": 1, "random_agent_score": 63, "student_agent_time": 0.0035543441772460938, "random_agent_time": 0.003094196319580078, "board_size": 8, "swap_players": false, "run_out": "An exception raised. The traceback is as follows:\nTraceback (most recent call last):\n  File \"/home/ml/users/ksinha4/mlp/comp424_final_project/submissions/comp424mcgill/final-project-a_new_team/world.py\", line 310, in step\n    raise ValueError(\nValueError: [INVALID:STEP] Not a valid step from [2 2] to [2 2] and put barrier at 0, with max steps = 4\n\nExecute Random Walk!\nAn exception raised. The traceback is as follows:\nTraceback (most recent call last):\n  File \"/home/ml/users/ksinha4/mlp/comp424_final_project/submissions/comp424mcgill/final-project-a_new_team/world.py\", line 310, in step\n    raise ValueError(\nValueError: [INVALID:STEP] Not a valid step from [3 1] to [3 1] and put barrier at 0, with max steps = 4\n\nExecute Random Walk!\nAn exception raised. The traceback is as follows:\nTraceback (most recent call last):\n  File \"/home/ml/users/ksinha4/mlp/comp424_final_project/submissions/comp424mcgill/final-project-a_new_team/world.py\", line 310, in step\n    raise ValueError(\nValueError: [INVALID:STEP] Not a valid step from [3 0] to [3 0] and put barrier at 0, with max steps = 4\n\nExecute Random Walk!\nAn exception raised. The traceback is as follows:\nTraceback (most recent call last):\n  File \"/home/ml/users/ksinha4/mlp/comp424_final_project/submissions/comp424mcgill/final-project-a_new_team/world.py\", line 310, in step\n    raise ValueError(\nValueError: [INVALID:STEP] Not a valid step from [6 1] to [6 1] and put barrier at 0, with max steps = 4\n\nExecute Random Walk!\n"}, {"student_agent_score": 2, "random_agent_score": 79, "student_agent_time": 0.002852916717529297, "random_agent_time": 0.0025572776794433594, "board_size": 9, "swap_players": false, "run_out": "An exception raised. The traceback is as follows:\nTraceback (most recent call last):\n  File \"/home/ml/users/ksinha4/mlp/comp424_final_project/submissions/comp424mcgill/final-project-a_new_team/world.py\", line 310, in step\n    raise ValueError(\nValueError: [INVALID:STEP] Not a valid step from [5 4] to [5 4] and put barrier at 0, with max steps = 5\n\nExecute Random Walk!\nAn exception raised. The traceback is as follows:\nTraceback (most recent call last):\n  File \"/home/ml/users/ksinha4/mlp/comp424_final_project/submissions/comp424mcgill/final-project-a_new_team/world.py\", line 310, in step\n    raise ValueError(\nValueError: [INVALID:STEP] Not a valid step from [5 3] to [5 3] and put barrier at 0, with max steps = 5\n\nExecute Random Walk!\n"}, {"student_agent_score": 1, "random_agent_score": 48, "student_agent_time": 0.0022552013397216797, "random_agent_time": 0.0022025108337402344, "board_size": 7, "swap_players": true, "run_out": "An exception raised. The traceback is as follows:\nTraceback (most recent call last):\n  File \"/home/ml/users/ksinha4/mlp/comp424_final_project/submissions/comp424mcgill/final-project-a_new_team/world.py\", line 310, in step\n    raise ValueError(\nValueError: [INVALID:STEP] Not a valid step from [2 3] to [2 3] and put barrier at 0, with max steps = 4\n\nExecute Random Walk!\nAn exception raised. The traceback is as follows:\nTraceback (most recent call last):\n  File \"/home/ml/users/ksinha4/mlp/comp424_final_project/submissions/comp424mcgill/final-project-a_new_team/world.py\", line 310, in step\n    raise ValueError(\nValueError: [INVALID:STEP] Not a valid step from [5 4] to [5 4] and put barrier at 0, with max steps = 4\n\nExecute Random Walk!\nAn exception raised. The traceback is as follows:\nTraceback (most recent call last):\n  File \"/home/ml/users/ksinha4/mlp/comp424_final_project/submissions/comp424mcgill/final-project-a_new_team/world.py\", line 310, in step\n    raise ValueError(\nValueError: [INVALID:STEP] Not a valid step from [6 3] to [6 3] and put barrier at 0, with max steps = 4\n\nExecute Random Walk!\n"}, {"student_agent_score": 1, "random_agent_score": 35, "student_agent_time": 0.0024857521057128906, "random_agent_time": 0.001766204833984375, "board_size": 6, "swap_players": true, "run_out": "An exception raised. The traceback is as follows:\nTraceback (most recent call last):\n  File \"/home/ml/users/ksinha4/mlp/comp424_final_project/submissions/comp424mcgill/final-project-a_new_team/world.py\", line 310, in step\n    raise ValueError(\nValueError: [INVALID:STEP] Not a valid step from [3 3] to [3 3] and put barrier at 0, with max steps = 3\n\nExecute Random Walk!\nAn exception raised. The traceback is as follows:\nTraceback (most recent call last):\n  File \"/home/ml/users/ksinha4/mlp/comp424_final_project/submissions/comp424mcgill/final-project-a_new_team/world.py\", line 310, in step\n    raise ValueError(\nValueError: [INVALID:STEP] Not a valid step from [3 3] to [3 3] and put barrier at 0, with max steps = 3\n\nExecute Random Walk!\n"}, {"student_agent_score": 99, "random_agent_score": 1, "student_agent_time": 0.0003039836883544922, "random_agent_time": 0.0011298656463623047, "board_size": 10, "swap_players": true, "run_out": ""}, {"student_agent_score": 120, "random_agent_score": 1, "student_agent_time": 0.0019443035125732422, "random_agent_time": 0.002758026123046875, "board_size": 11, "swap_players": true, "run_out": "An exception raised. The traceback is as follows:\nTraceback (most recent call last):\n  File \"/home/ml/users/ksinha4/mlp/comp424_final_project/submissions/comp424mcgill/final-project-a_new_team/world.py\", line 310, in step\n    raise ValueError(\nValueError: [INVALID:STEP] Not a valid step from [9 3] to [9 3] and put barrier at 0, with max steps = 6\n\nExecute Random Walk!\nAn exception raised. The traceback is as follows:\nTraceback (most recent call last):\n  File \"/home/ml/users/ksinha4/mlp/comp424_final_project/submissions/comp424mcgill/final-project-a_new_team/world.py\", line 310, in step\n    raise ValueError(\nValueError: [INVALID:STEP] Not a valid step from [9 3] to [9 3] and put barrier at 0, with max steps = 6\n\nExecute Random Walk!\n"}, {"student_agent_score": 1, "random_agent_score": 48, "student_agent_time": 0.0046117305755615234, "random_agent_time": 0.0021347999572753906, "board_size": 7, "swap_players": false, "run_out": "An exception raised. The traceback is as follows:\nTraceback (most recent call last):\n  File \"/home/ml/users/ksinha4/mlp/comp424_final_project/submissions/comp424mcgill/final-project-a_new_team/world.py\", line 310, in step\n    raise ValueError(\nValueError: [INVALID:STEP] Not a valid step from [4 3] to [4 3] and put barrier at 0, with max steps = 4\n\nExecute Random Walk!\nAn exception raised. The traceback is as follows:\nTraceback (most recent call last):\n  File \"/home/ml/users/ksinha4/mlp/comp424_final_project/submissions/comp424mcgill/final-project-a_new_team/world.py\", line 310, in step\n    raise ValueError(\nValueError: [INVALID:STEP] Not a valid step from [4 2] to [4 2] and put barrier at 0, with max steps = 4\n\nExecute Random Walk!\nAn exception raised. The traceback is as follows:\nTraceback (most recent call last):\n  File \"/home/ml/users/ksinha4/mlp/comp424_final_project/submissions/comp424mcgill/final-project-a_new_team/world.py\", line 310, in step\n    raise ValueError(\nValueError: [INVALID:STEP] Not a valid step from [4 3] to [4 3] and put barrier at 0, with max steps = 4\n\nExecute Random Walk!\nAn exception raised. The traceback is as follows:\nTraceback (most recent call last):\n  File \"/home/ml/users/ksinha4/mlp/comp424_final_project/submissions/comp424mcgill/final-project-a_new_team/world.py\", line 310, in step\n    raise ValueError(\nValueError: [INVALID:STEP] Not a valid step from [5 4] to [5 4] and put barrier at 0, with max steps = 4\n\nExecute Random Walk!\nAn exception raised. The traceback is as follows:\nTraceback (most recent call last):\n  File \"/home/ml/users/ksinha4/mlp/comp424_final_project/submissions/comp424mcgill/final-project-a_new_team/world.py\", line 310, in step\n    raise ValueError(\nValueError: [INVALID:STEP] Not a valid step from [6 3] to [6 3] and put barrier at 0, with max steps = 4\n\nExecute Random Walk!\n"}, {"student_agent_score": 1, "random_agent_score": 48, "student_agent_time": 0.0041010379791259766, "random_agent_time": 0.002767324447631836, "board_size": 7, "swap_players": false, "run_out": "An exception raised. The traceback is as follows:\nTraceback (most recent call last):\n  File \"/home/ml/users/ksinha4/mlp/comp424_final_project/submissions/comp424mcgill/final-project-a_new_team/world.py\", line 310, in step\n    raise ValueError(\nValueError: [INVALID:STEP] Not a valid step from [4 3] to [4 3] and put barrier at 0, with max steps = 4\n\nExecute Random Walk!\nAn exception raised. The traceback is as follows:\nTraceback (most recent call last):\n  File \"/home/ml/users/ksinha4/mlp/comp424_final_project/submissions/comp424mcgill/final-project-a_new_team/world.py\", line 310, in step\n    raise ValueError(\nValueError: [INVALID:STEP] Not a valid step from [4 2] to [4 2] and put barrier at 0, with max steps = 4\n\nExecute Random Walk!\nAn exception raised. The traceback is as follows:\nTraceback (most recent call last):\n  File \"/home/ml/users/ksinha4/mlp/comp424_final_project/submissions/comp424mcgill/final-project-a_new_team/world.py\", line 310, in step\n    raise ValueError(\nValueError: [INVALID:STEP] Not a valid step from [4 3] to [4 3] and put barrier at 0, with max steps = 4\n\nExecute Random Walk!\nAn exception raised. The traceback is as follows:\nTraceback (most recent call last):\n  File \"/home/ml/users/ksinha4/mlp/comp424_final_project/submissions/comp424mcgill/final-project-a_new_team/world.py\", line 310, in step\n    raise ValueError(\nValueError: [INVALID:STEP] Not a valid step from [5 4] to [5 4] and put barrier at 0, with max steps = 4\n\nExecute Random Walk!\nAn exception raised. The traceback is as follows:\nTraceback (most recent call last):\n  File \"/home/ml/users/ksinha4/mlp/comp424_final_project/submissions/comp424mcgill/final-project-a_new_team/world.py\", line 310, in step\n    raise ValueError(\nValueError: [INVALID:STEP] Not a valid step from [6 3] to [6 3] and put barrier at 0, with max steps = 4\n\nExecute Random Walk!\n"}, {"student_agent_score": 1, "random_agent_score": 48, "student_agent_time": 0.005183696746826172, "random_agent_time": 0.002554178237915039, "board_size": 7, "swap_players": true, "run_out": "An exception raised. The traceback is as follows:\nTraceback (most recent call last):\n  File \"/home/ml/users/ksinha4/mlp/comp424_final_project/submissions/comp424mcgill/final-project-a_new_team/world.py\", line 310, in step\n    raise ValueError(\nValueError: [INVALID:STEP] Not a valid step from [2 3] to [2 3] and put barrier at 0, with max steps = 4\n\nExecute Random Walk!\nAn exception raised. The traceback is as follows:\nTraceback (most recent call last):\n  File \"/home/ml/users/ksinha4/mlp/comp424_final_project/submissions/comp424mcgill/final-project-a_new_team/world.py\", line 310, in step\n    raise ValueError(\nValueError: [INVALID:STEP] Not a valid step from [5 4] to [5 4] and put barrier at 0, with max steps = 4\n\nExecute Random Walk!\nAn exception raised. The traceback is as follows:\nTraceback (most recent call last):\n  File \"/home/ml/users/ksinha4/mlp/comp424_final_project/submissions/comp424mcgill/final-project-a_new_team/world.py\", line 310, in step\n    raise ValueError(\nValueError: [INVALID:STEP] Not a valid step from [6 3] to [6 3] and put barrier at 0, with max steps = 4\n\nExecute Random Walk!\n"}, {"student_agent_score": 1, "random_agent_score": 48, "student_agent_time": 0.005144357681274414, "random_agent_time": 0.0022029876708984375, "board_size": 7, "swap_players": false, "run_out": "An exception raised. The traceback is as follows:\nTraceback (most recent call last):\n  File \"/home/ml/users/ksinha4/mlp/comp424_final_project/submissions/comp424mcgill/final-project-a_new_team/world.py\", line 310, in step\n    raise ValueError(\nValueError: [INVALID:STEP] Not a valid step from [4 3] to [4 3] and put barrier at 0, with max steps = 4\n\nExecute Random Walk!\nAn exception raised. The traceback is as follows:\nTraceback (most recent call last):\n  File \"/home/ml/users/ksinha4/mlp/comp424_final_project/submissions/comp424mcgill/final-project-a_new_team/world.py\", line 310, in step\n    raise ValueError(\nValueError: [INVALID:STEP] Not a valid step from [4 2] to [4 2] and put barrier at 0, with max steps = 4\n\nExecute Random Walk!\nAn exception raised. The traceback is as follows:\nTraceback (most recent call last):\n  File \"/home/ml/users/ksinha4/mlp/comp424_final_project/submissions/comp424mcgill/final-project-a_new_team/world.py\", line 310, in step\n    raise ValueError(\nValueError: [INVALID:STEP] Not a valid step from [4 3] to [4 3] and put barrier at 0, with max steps = 4\n\nExecute Random Walk!\nAn exception raised. The traceback is as follows:\nTraceback (most recent call last):\n  File \"/home/ml/users/ksinha4/mlp/comp424_final_project/submissions/comp424mcgill/final-project-a_new_team/world.py\", line 310, in step\n    raise ValueError(\nValueError: [INVALID:STEP] Not a valid step from [5 4] to [5 4] and put barrier at 0, with max steps = 4\n\nExecute Random Walk!\nAn exception raised. The traceback is as follows:\nTraceback (most recent call last):\n  File \"/home/ml/users/ksinha4/mlp/comp424_final_project/submissions/comp424mcgill/final-project-a_new_team/world.py\", line 310, in step\n    raise ValueError(\nValueError: [INVALID:STEP] Not a valid step from [6 3] to [6 3] and put barrier at 0, with max steps = 4\n\nExecute Random Walk!\n"}, {"student_agent_score": 1, "random_agent_score": 48, "student_agent_time": 0.002902507781982422, "random_agent_time": 0.0024538040161132812, "board_size": 7, "swap_players": true, "run_out": "An exception raised. The traceback is as follows:\nTraceback (most recent call last):\n  File \"/home/ml/users/ksinha4/mlp/comp424_final_project/submissions/comp424mcgill/final-project-a_new_team/world.py\", line 310, in step\n    raise ValueError(\nValueError: [INVALID:STEP] Not a valid step from [2 3] to [2 3] and put barrier at 0, with max steps = 4\n\nExecute Random Walk!\nAn exception raised. The traceback is as follows:\nTraceback (most recent call last):\n  File \"/home/ml/users/ksinha4/mlp/comp424_final_project/submissions/comp424mcgill/final-project-a_new_team/world.py\", line 310, in step\n    raise ValueError(\nValueError: [INVALID:STEP] Not a valid step from [5 4] to [5 4] and put barrier at 0, with max steps = 4\n\nExecute Random Walk!\nAn exception raised. The traceback is as follows:\nTraceback (most recent call last):\n  File \"/home/ml/users/ksinha4/mlp/comp424_final_project/submissions/comp424mcgill/final-project-a_new_team/world.py\", line 310, in step\n    raise ValueError(\nValueError: [INVALID:STEP] Not a valid step from [6 3] to [6 3] and put barrier at 0, with max steps = 4\n\nExecute Random Walk!\n"}, {"student_agent_score": 120, "random_agent_score": 1, "student_agent_time": 0.0020418167114257812, "random_agent_time": 0.0023794174194335938, "board_size": 11, "swap_players": true, "run_out": "An exception raised. The traceback is as follows:\nTraceback (most recent call last):\n  File \"/home/ml/users/ksinha4/mlp/comp424_final_project/submissions/comp424mcgill/final-project-a_new_team/world.py\", line 310, in step\n    raise ValueError(\nValueError: [INVALID:STEP] Not a valid step from [9 3] to [9 3] and put barrier at 0, with max steps = 6\n\nExecute Random Walk!\nAn exception raised. The traceback is as follows:\nTraceback (most recent call last):\n  File \"/home/ml/users/ksinha4/mlp/comp424_final_project/submissions/comp424mcgill/final-project-a_new_team/world.py\", line 310, in step\n    raise ValueError(\nValueError: [INVALID:STEP] Not a valid step from [9 3] to [9 3] and put barrier at 0, with max steps = 6\n\nExecute Random Walk!\n"}, {"student_agent_score": 1, "random_agent_score": 48, "student_agent_time": 0.005019664764404297, "random_agent_time": 0.0021293163299560547, "board_size": 7, "swap_players": false, "run_out": "An exception raised. The traceback is as follows:\nTraceback (most recent call last):\n  File \"/home/ml/users/ksinha4/mlp/comp424_final_project/submissions/comp424mcgill/final-project-a_new_team/world.py\", line 310, in step\n    raise ValueError(\nValueError: [INVALID:STEP] Not a valid step from [4 3] to [4 3] and put barrier at 0, with max steps = 4\n\nExecute Random Walk!\nAn exception raised. The traceback is as follows:\nTraceback (most recent call last):\n  File \"/home/ml/users/ksinha4/mlp/comp424_final_project/submissions/comp424mcgill/final-project-a_new_team/world.py\", line 310, in step\n    raise ValueError(\nValueError: [INVALID:STEP] Not a valid step from [4 2] to [4 2] and put barrier at 0, with max steps = 4\n\nExecute Random Walk!\nAn exception raised. The traceback is as follows:\nTraceback (most recent call last):\n  File \"/home/ml/users/ksinha4/mlp/comp424_final_project/submissions/comp424mcgill/final-project-a_new_team/world.py\", line 310, in step\n    raise ValueError(\nValueError: [INVALID:STEP] Not a valid step from [4 3] to [4 3] and put barrier at 0, with max steps = 4\n\nExecute Random Walk!\nAn exception raised. The traceback is as follows:\nTraceback (most recent call last):\n  File \"/home/ml/users/ksinha4/mlp/comp424_final_project/submissions/comp424mcgill/final-project-a_new_team/world.py\", line 310, in step\n    raise ValueError(\nValueError: [INVALID:STEP] Not a valid step from [5 4] to [5 4] and put barrier at 0, with max steps = 4\n\nExecute Random Walk!\nAn exception raised. The traceback is as follows:\nTraceback (most recent call last):\n  File \"/home/ml/users/ksinha4/mlp/comp424_final_project/submissions/comp424mcgill/final-project-a_new_team/world.py\", line 310, in step\n    raise ValueError(\nValueError: [INVALID:STEP] Not a valid step from [6 3] to [6 3] and put barrier at 0, with max steps = 4\n\nExecute Random Walk!\n"}, {"student_agent_score": 1, "random_agent_score": 48, "student_agent_time": 0.0056002140045166016, "random_agent_time": 0.001871347427368164, "board_size": 7, "swap_players": false, "run_out": "An exception raised. The traceback is as follows:\nTraceback (most recent call last):\n  File \"/home/ml/users/ksinha4/mlp/comp424_final_project/submissions/comp424mcgill/final-project-a_new_team/world.py\", line 310, in step\n    raise ValueError(\nValueError: [INVALID:STEP] Not a valid step from [4 3] to [4 3] and put barrier at 0, with max steps = 4\n\nExecute Random Walk!\nAn exception raised. The traceback is as follows:\nTraceback (most recent call last):\n  File \"/home/ml/users/ksinha4/mlp/comp424_final_project/submissions/comp424mcgill/final-project-a_new_team/world.py\", line 310, in step\n    raise ValueError(\nValueError: [INVALID:STEP] Not a valid step from [4 2] to [4 2] and put barrier at 0, with max steps = 4\n\nExecute Random Walk!\nAn exception raised. The traceback is as follows:\nTraceback (most recent call last):\n  File \"/home/ml/users/ksinha4/mlp/comp424_final_project/submissions/comp424mcgill/final-project-a_new_team/world.py\", line 310, in step\n    raise ValueError(\nValueError: [INVALID:STEP] Not a valid step from [4 3] to [4 3] and put barrier at 0, with max steps = 4\n\nExecute Random Walk!\nAn exception raised. The traceback is as follows:\nTraceback (most recent call last):\n  File \"/home/ml/users/ksinha4/mlp/comp424_final_project/submissions/comp424mcgill/final-project-a_new_team/world.py\", line 310, in step\n    raise ValueError(\nValueError: [INVALID:STEP] Not a valid step from [5 4] to [5 4] and put barrier at 0, with max steps = 4\n\nExecute Random Walk!\nAn exception raised. The traceback is as follows:\nTraceback (most recent call last):\n  File \"/home/ml/users/ksinha4/mlp/comp424_final_project/submissions/comp424mcgill/final-project-a_new_team/world.py\", line 310, in step\n    raise ValueError(\nValueError: [INVALID:STEP] Not a valid step from [6 3] to [6 3] and put barrier at 0, with max steps = 4\n\nExecute Random Walk!\n"}, {"student_agent_score": 80, "random_agent_score": 1, "student_agent_time": 0.004158496856689453, "random_agent_time": 0.0052411556243896484, "board_size": 9, "swap_players": true, "run_out": "An exception raised. The traceback is as follows:\nTraceback (most recent call last):\n  File \"/home/ml/users/ksinha4/mlp/comp424_final_project/submissions/comp424mcgill/final-project-a_new_team/world.py\", line 310, in step\n    raise ValueError(\nValueError: [INVALID:STEP] Not a valid step from [3 4] to [3 4] and put barrier at 0, with max steps = 5\n\nExecute Random Walk!\nAn exception raised. The traceback is as follows:\nTraceback (most recent call last):\n  File \"/home/ml/users/ksinha4/mlp/comp424_final_project/submissions/comp424mcgill/final-project-a_new_team/world.py\", line 310, in step\n    raise ValueError(\nValueError: [INVALID:STEP] Not a valid step from [3 5] to [3 5] and put barrier at 0, with max steps = 5\n\nExecute Random Walk!\nAn exception raised. The traceback is as follows:\nTraceback (most recent call last):\n  File \"/home/ml/users/ksinha4/mlp/comp424_final_project/submissions/comp424mcgill/final-project-a_new_team/world.py\", line 310, in step\n    raise ValueError(\nValueError: [INVALID:STEP] Not a valid step from [3 4] to [3 4] and put barrier at 0, with max steps = 5\n\nExecute Random Walk!\nAn exception raised. The traceback is as follows:\nTraceback (most recent call last):\n  File \"/home/ml/users/ksinha4/mlp/comp424_final_project/submissions/comp424mcgill/final-project-a_new_team/world.py\", line 310, in step\n    raise ValueError(\nValueError: [INVALID:STEP] Not a valid step from [5 4] to [5 4] and put barrier at 0, with max steps = 5\n\nExecute Random Walk!\nAn exception raised. The traceback is as follows:\nTraceback (most recent call last):\n  File \"/home/ml/users/ksinha4/mlp/comp424_final_project/submissions/comp424mcgill/final-project-a_new_team/world.py\", line 310, in step\n    raise ValueError(\nValueError: [INVALID:STEP] Not a valid step from [5 5] to [5 5] and put barrier at 0, with max steps = 5\n\nExecute Random Walk!\n"}, {"student_agent_score": 2, "random_agent_score": 98, "student_agent_time": 0.004470348358154297, "random_agent_time": 0.009586811065673828, "board_size": 10, "swap_players": false, "run_out": "An exception raised. The traceback is as follows:\nTraceback (most recent call last):\n  File \"/home/ml/users/ksinha4/mlp/comp424_final_project/submissions/comp424mcgill/final-project-a_new_team/world.py\", line 310, in step\n    raise ValueError(\nValueError: [INVALID:STEP] Not a valid step from [7 5] to [7 5] and put barrier at 0, with max steps = 5\n\nExecute Random Walk!\nAn exception raised. The traceback is as follows:\nTraceback (most recent call last):\n  File \"/home/ml/users/ksinha4/mlp/comp424_final_project/submissions/comp424mcgill/final-project-a_new_team/world.py\", line 310, in step\n    raise ValueError(\nValueError: [INVALID:STEP] Not a valid step from [6 6] to [6 6] and put barrier at 0, with max steps = 5\n\nExecute Random Walk!\nAn exception raised. The traceback is as follows:\nTraceback (most recent call last):\n  File \"/home/ml/users/ksinha4/mlp/comp424_final_project/submissions/comp424mcgill/final-project-a_new_team/world.py\", line 310, in step\n    raise ValueError(\nValueError: [INVALID:STEP] Not a valid step from [7 8] to [7 8] and put barrier at 0, with max steps = 5\n\nExecute Random Walk!\nAn exception raised. The traceback is as follows:\nTraceback (most recent call last):\n  File \"/home/ml/users/ksinha4/mlp/comp424_final_project/submissions/comp424mcgill/final-project-a_new_team/world.py\", line 310, in step\n    raise ValueError(\nValueError: [INVALID:STEP] Not a valid step from [7 8] to [7 8] and put barrier at 0, with max steps = 5\n\nExecute Random Walk!\n"}, {"student_agent_score": 1, "random_agent_score": 48, "student_agent_time": 0.006365060806274414, "random_agent_time": 0.0022475719451904297, "board_size": 7, "swap_players": true, "run_out": "An exception raised. The traceback is as follows:\nTraceback (most recent call last):\n  File \"/home/ml/users/ksinha4/mlp/comp424_final_project/submissions/comp424mcgill/final-project-a_new_team/world.py\", line 310, in step\n    raise ValueError(\nValueError: [INVALID:STEP] Not a valid step from [2 3] to [2 3] and put barrier at 0, with max steps = 4\n\nExecute Random Walk!\nAn exception raised. The traceback is as follows:\nTraceback (most recent call last):\n  File \"/home/ml/users/ksinha4/mlp/comp424_final_project/submissions/comp424mcgill/final-project-a_new_team/world.py\", line 310, in step\n    raise ValueError(\nValueError: [INVALID:STEP] Not a valid step from [5 4] to [5 4] and put barrier at 0, with max steps = 4\n\nExecute Random Walk!\nAn exception raised. The traceback is as follows:\nTraceback (most recent call last):\n  File \"/home/ml/users/ksinha4/mlp/comp424_final_project/submissions/comp424mcgill/final-project-a_new_team/world.py\", line 310, in step\n    raise ValueError(\nValueError: [INVALID:STEP] Not a valid step from [6 3] to [6 3] and put barrier at 0, with max steps = 4\n\nExecute Random Walk!\n"}, {"student_agent_score": 1, "random_agent_score": 48, "student_agent_time": 0.0035691261291503906, "random_agent_time": 0.0019500255584716797, "board_size": 7, "swap_players": true, "run_out": "An exception raised. The traceback is as follows:\nTraceback (most recent call last):\n  File \"/home/ml/users/ksinha4/mlp/comp424_final_project/submissions/comp424mcgill/final-project-a_new_team/world.py\", line 310, in step\n    raise ValueError(\nValueError: [INVALID:STEP] Not a valid step from [2 3] to [2 3] and put barrier at 0, with max steps = 4\n\nExecute Random Walk!\nAn exception raised. The traceback is as follows:\nTraceback (most recent call last):\n  File \"/home/ml/users/ksinha4/mlp/comp424_final_project/submissions/comp424mcgill/final-project-a_new_team/world.py\", line 310, in step\n    raise ValueError(\nValueError: [INVALID:STEP] Not a valid step from [5 4] to [5 4] and put barrier at 0, with max steps = 4\n\nExecute Random Walk!\nAn exception raised. The traceback is as follows:\nTraceback (most recent call last):\n  File \"/home/ml/users/ksinha4/mlp/comp424_final_project/submissions/comp424mcgill/final-project-a_new_team/world.py\", line 310, in step\n    raise ValueError(\nValueError: [INVALID:STEP] Not a valid step from [6 3] to [6 3] and put barrier at 0, with max steps = 4\n\nExecute Random Walk!\n"}, {"student_agent_score": 1, "random_agent_score": 48, "student_agent_time": 0.005768299102783203, "random_agent_time": 0.0035228729248046875, "board_size": 7, "swap_players": false, "run_out": "An exception raised. The traceback is as follows:\nTraceback (most recent call last):\n  File \"/home/ml/users/ksinha4/mlp/comp424_final_project/submissions/comp424mcgill/final-project-a_new_team/world.py\", line 310, in step\n    raise ValueError(\nValueError: [INVALID:STEP] Not a valid step from [4 3] to [4 3] and put barrier at 0, with max steps = 4\n\nExecute Random Walk!\nAn exception raised. The traceback is as follows:\nTraceback (most recent call last):\n  File \"/home/ml/users/ksinha4/mlp/comp424_final_project/submissions/comp424mcgill/final-project-a_new_team/world.py\", line 310, in step\n    raise ValueError(\nValueError: [INVALID:STEP] Not a valid step from [4 2] to [4 2] and put barrier at 0, with max steps = 4\n\nExecute Random Walk!\nAn exception raised. The traceback is as follows:\nTraceback (most recent call last):\n  File \"/home/ml/users/ksinha4/mlp/comp424_final_project/submissions/comp424mcgill/final-project-a_new_team/world.py\", line 310, in step\n    raise ValueError(\nValueError: [INVALID:STEP] Not a valid step from [4 3] to [4 3] and put barrier at 0, with max steps = 4\n\nExecute Random Walk!\nAn exception raised. The traceback is as follows:\nTraceback (most recent call last):\n  File \"/home/ml/users/ksinha4/mlp/comp424_final_project/submissions/comp424mcgill/final-project-a_new_team/world.py\", line 310, in step\n    raise ValueError(\nValueError: [INVALID:STEP] Not a valid step from [5 4] to [5 4] and put barrier at 0, with max steps = 4\n\nExecute Random Walk!\nAn exception raised. The traceback is as follows:\nTraceback (most recent call last):\n  File \"/home/ml/users/ksinha4/mlp/comp424_final_project/submissions/comp424mcgill/final-project-a_new_team/world.py\", line 310, in step\n    raise ValueError(\nValueError: [INVALID:STEP] Not a valid step from [6 3] to [6 3] and put barrier at 0, with max steps = 4\n\nExecute Random Walk!\n"}, {"student_agent_score": 1, "random_agent_score": 48, "student_agent_time": 0.0041081905364990234, "random_agent_time": 0.0026476383209228516, "board_size": 7, "swap_players": false, "run_out": "An exception raised. The traceback is as follows:\nTraceback (most recent call last):\n  File \"/home/ml/users/ksinha4/mlp/comp424_final_project/submissions/comp424mcgill/final-project-a_new_team/world.py\", line 310, in step\n    raise ValueError(\nValueError: [INVALID:STEP] Not a valid step from [4 3] to [4 3] and put barrier at 0, with max steps = 4\n\nExecute Random Walk!\nAn exception raised. The traceback is as follows:\nTraceback (most recent call last):\n  File \"/home/ml/users/ksinha4/mlp/comp424_final_project/submissions/comp424mcgill/final-project-a_new_team/world.py\", line 310, in step\n    raise ValueError(\nValueError: [INVALID:STEP] Not a valid step from [4 2] to [4 2] and put barrier at 0, with max steps = 4\n\nExecute Random Walk!\nAn exception raised. The traceback is as follows:\nTraceback (most recent call last):\n  File \"/home/ml/users/ksinha4/mlp/comp424_final_project/submissions/comp424mcgill/final-project-a_new_team/world.py\", line 310, in step\n    raise ValueError(\nValueError: [INVALID:STEP] Not a valid step from [4 3] to [4 3] and put barrier at 0, with max steps = 4\n\nExecute Random Walk!\nAn exception raised. The traceback is as follows:\nTraceback (most recent call last):\n  File \"/home/ml/users/ksinha4/mlp/comp424_final_project/submissions/comp424mcgill/final-project-a_new_team/world.py\", line 310, in step\n    raise ValueError(\nValueError: [INVALID:STEP] Not a valid step from [5 4] to [5 4] and put barrier at 0, with max steps = 4\n\nExecute Random Walk!\nAn exception raised. The traceback is as follows:\nTraceback (most recent call last):\n  File \"/home/ml/users/ksinha4/mlp/comp424_final_project/submissions/comp424mcgill/final-project-a_new_team/world.py\", line 310, in step\n    raise ValueError(\nValueError: [INVALID:STEP] Not a valid step from [6 3] to [6 3] and put barrier at 0, with max steps = 4\n\nExecute Random Walk!\n"}, {"student_agent_score": 80, "random_agent_score": 1, "student_agent_time": 0.003762960433959961, "random_agent_time": 0.0055539608001708984, "board_size": 9, "swap_players": true, "run_out": "An exception raised. The traceback is as follows:\nTraceback (most recent call last):\n  File \"/home/ml/users/ksinha4/mlp/comp424_final_project/submissions/comp424mcgill/final-project-a_new_team/world.py\", line 310, in step\n    raise ValueError(\nValueError: [INVALID:STEP] Not a valid step from [3 4] to [3 4] and put barrier at 0, with max steps = 5\n\nExecute Random Walk!\nAn exception raised. The traceback is as follows:\nTraceback (most recent call last):\n  File \"/home/ml/users/ksinha4/mlp/comp424_final_project/submissions/comp424mcgill/final-project-a_new_team/world.py\", line 310, in step\n    raise ValueError(\nValueError: [INVALID:STEP] Not a valid step from [3 5] to [3 5] and put barrier at 0, with max steps = 5\n\nExecute Random Walk!\nAn exception raised. The traceback is as follows:\nTraceback (most recent call last):\n  File \"/home/ml/users/ksinha4/mlp/comp424_final_project/submissions/comp424mcgill/final-project-a_new_team/world.py\", line 310, in step\n    raise ValueError(\nValueError: [INVALID:STEP] Not a valid step from [3 4] to [3 4] and put barrier at 0, with max steps = 5\n\nExecute Random Walk!\nAn exception raised. The traceback is as follows:\nTraceback (most recent call last):\n  File \"/home/ml/users/ksinha4/mlp/comp424_final_project/submissions/comp424mcgill/final-project-a_new_team/world.py\", line 310, in step\n    raise ValueError(\nValueError: [INVALID:STEP] Not a valid step from [5 4] to [5 4] and put barrier at 0, with max steps = 5\n\nExecute Random Walk!\nAn exception raised. The traceback is as follows:\nTraceback (most recent call last):\n  File \"/home/ml/users/ksinha4/mlp/comp424_final_project/submissions/comp424mcgill/final-project-a_new_team/world.py\", line 310, in step\n    raise ValueError(\nValueError: [INVALID:STEP] Not a valid step from [5 5] to [5 5] and put barrier at 0, with max steps = 5\n\nExecute Random Walk!\n"}, {"student_agent_score": 63, "random_agent_score": 1, "student_agent_time": 0.0030019283294677734, "random_agent_time": 0.0026705265045166016, "board_size": 8, "swap_players": true, "run_out": "An exception raised. The traceback is as follows:\nTraceback (most recent call last):\n  File \"/home/ml/users/ksinha4/mlp/comp424_final_project/submissions/comp424mcgill/final-project-a_new_team/world.py\", line 310, in step\n    raise ValueError(\nValueError: [INVALID:STEP] Not a valid step from [5 5] to [5 5] and put barrier at 0, with max steps = 4\n\nExecute Random Walk!\nAn exception raised. The traceback is as follows:\nTraceback (most recent call last):\n  File \"/home/ml/users/ksinha4/mlp/comp424_final_project/submissions/comp424mcgill/final-project-a_new_team/world.py\", line 310, in step\n    raise ValueError(\nValueError: [INVALID:STEP] Not a valid step from [5 4] to [5 4] and put barrier at 0, with max steps = 4\n\nExecute Random Walk!\nAn exception raised. The traceback is as follows:\nTraceback (most recent call last):\n  File \"/home/ml/users/ksinha4/mlp/comp424_final_project/submissions/comp424mcgill/final-project-a_new_team/world.py\", line 310, in step\n    raise ValueError(\nValueError: [INVALID:STEP] Not a valid step from [5 4] to [5 4] and put barrier at 0, with max steps = 4\n\nExecute Random Walk!\n"}, {"student_agent_score": 2, "random_agent_score": 79, "student_agent_time": 0.003036022186279297, "random_agent_time": 0.002124309539794922, "board_size": 9, "swap_players": false, "run_out": "An exception raised. The traceback is as follows:\nTraceback (most recent call last):\n  File \"/home/ml/users/ksinha4/mlp/comp424_final_project/submissions/comp424mcgill/final-project-a_new_team/world.py\", line 310, in step\n    raise ValueError(\nValueError: [INVALID:STEP] Not a valid step from [5 4] to [5 4] and put barrier at 0, with max steps = 5\n\nExecute Random Walk!\nAn exception raised. The traceback is as follows:\nTraceback (most recent call last):\n  File \"/home/ml/users/ksinha4/mlp/comp424_final_project/submissions/comp424mcgill/final-project-a_new_team/world.py\", line 310, in step\n    raise ValueError(\nValueError: [INVALID:STEP] Not a valid step from [5 3] to [5 3] and put barrier at 0, with max steps = 5\n\nExecute Random Walk!\n"}, {"student_agent_score": 1, "random_agent_score": 48, "student_agent_time": 0.004909515380859375, "random_agent_time": 0.0024352073669433594, "board_size": 7, "swap_players": false, "run_out": "An exception raised. The traceback is as follows:\nTraceback (most recent call last):\n  File \"/home/ml/users/ksinha4/mlp/comp424_final_project/submissions/comp424mcgill/final-project-a_new_team/world.py\", line 310, in step\n    raise ValueError(\nValueError: [INVALID:STEP] Not a valid step from [4 3] to [4 3] and put barrier at 0, with max steps = 4\n\nExecute Random Walk!\nAn exception raised. The traceback is as follows:\nTraceback (most recent call last):\n  File \"/home/ml/users/ksinha4/mlp/comp424_final_project/submissions/comp424mcgill/final-project-a_new_team/world.py\", line 310, in step\n    raise ValueError(\nValueError: [INVALID:STEP] Not a valid step from [4 2] to [4 2] and put barrier at 0, with max steps = 4\n\nExecute Random Walk!\nAn exception raised. The traceback is as follows:\nTraceback (most recent call last):\n  File \"/home/ml/users/ksinha4/mlp/comp424_final_project/submissions/comp424mcgill/final-project-a_new_team/world.py\", line 310, in step\n    raise ValueError(\nValueError: [INVALID:STEP] Not a valid step from [4 3] to [4 3] and put barrier at 0, with max steps = 4\n\nExecute Random Walk!\nAn exception raised. The traceback is as follows:\nTraceback (most recent call last):\n  File \"/home/ml/users/ksinha4/mlp/comp424_final_project/submissions/comp424mcgill/final-project-a_new_team/world.py\", line 310, in step\n    raise ValueError(\nValueError: [INVALID:STEP] Not a valid step from [5 4] to [5 4] and put barrier at 0, with max steps = 4\n\nExecute Random Walk!\nAn exception raised. The traceback is as follows:\nTraceback (most recent call last):\n  File \"/home/ml/users/ksinha4/mlp/comp424_final_project/submissions/comp424mcgill/final-project-a_new_team/world.py\", line 310, in step\n    raise ValueError(\nValueError: [INVALID:STEP] Not a valid step from [6 3] to [6 3] and put barrier at 0, with max steps = 4\n\nExecute Random Walk!\n"}, {"student_agent_score": 117, "random_agent_score": 1, "student_agent_time": 0.007832765579223633, "random_agent_time": 0.008124113082885742, "board_size": 11, "swap_players": false, "run_out": "An exception raised. The traceback is as follows:\nTraceback (most recent call last):\n  File \"/home/ml/users/ksinha4/mlp/comp424_final_project/submissions/comp424mcgill/final-project-a_new_team/world.py\", line 310, in step\n    raise ValueError(\nValueError: [INVALID:STEP] Not a valid step from [1 7] to [1 7] and put barrier at 0, with max steps = 6\n\nExecute Random Walk!\nAn exception raised. The traceback is as follows:\nTraceback (most recent call last):\n  File \"/home/ml/users/ksinha4/mlp/comp424_final_project/submissions/comp424mcgill/final-project-a_new_team/world.py\", line 310, in step\n    raise ValueError(\nValueError: [INVALID:STEP] Not a valid step from [1 8] to [1 8] and put barrier at 0, with max steps = 6\n\nExecute Random Walk!\nAn exception raised. The traceback is as follows:\nTraceback (most recent call last):\n  File \"/home/ml/users/ksinha4/mlp/comp424_final_project/submissions/comp424mcgill/final-project-a_new_team/world.py\", line 310, in step\n    raise ValueError(\nValueError: [INVALID:STEP] Not a valid step from [1 6] to [1 6] and put barrier at 0, with max steps = 6\n\nExecute Random Walk!\nAn exception raised. The traceback is as follows:\nTraceback (most recent call last):\n  File \"/home/ml/users/ksinha4/mlp/comp424_final_project/submissions/comp424mcgill/final-project-a_new_team/world.py\", line 310, in step\n    raise ValueError(\nValueError: [INVALID:STEP] Not a valid step from [3 3] to [3 3] and put barrier at 0, with max steps = 6\n\nExecute Random Walk!\nAn exception raised. The traceback is as follows:\nTraceback (most recent call last):\n  File \"/home/ml/users/ksinha4/mlp/comp424_final_project/submissions/comp424mcgill/final-project-a_new_team/world.py\", line 310, in step\n    raise ValueError(\nValueError: [INVALID:STEP] Not a valid step from [3 4] to [3 4] and put barrier at 0, with max steps = 6\n\nExecute Random Walk!\nAn exception raised. The traceback is as follows:\nTraceback (most recent call last):\n  File \"/home/ml/users/ksinha4/mlp/comp424_final_project/submissions/comp424mcgill/final-project-a_new_team/world.py\", line 310, in step\n    raise ValueError(\nValueError: [INVALID:STEP] Not a valid step from [3 4] to [3 4] and put barrier at 0, with max steps = 6\n\nExecute Random Walk!\nAn exception raised. The traceback is as follows:\nTraceback (most recent call last):\n  File \"/home/ml/users/ksinha4/mlp/comp424_final_project/submissions/comp424mcgill/final-project-a_new_team/world.py\", line 310, in step\n    raise ValueError(\nValueError: [INVALID:STEP] Not a valid step from [4 4] to [4 4] and put barrier at 0, with max steps = 6\n\nExecute Random Walk!\nAn exception raised. The traceback is as follows:\nTraceback (most recent call last):\n  File \"/home/ml/users/ksinha4/mlp/comp424_final_project/submissions/comp424mcgill/final-project-a_new_team/world.py\", line 310, in step\n    raise ValueError(\nValueError: [INVALID:STEP] Not a valid step from [4 4] to [4 4] and put barrier at 0, with max steps = 6\n\nExecute Random Walk!\n"}, {"student_agent_score": 1, "random_agent_score": 48, "student_agent_time": 0.0026197433471679688, "random_agent_time": 0.0029838085174560547, "board_size": 7, "swap_players": true, "run_out": "An exception raised. The traceback is as follows:\nTraceback (most recent call last):\n  File \"/home/ml/users/ksinha4/mlp/comp424_final_project/submissions/comp424mcgill/final-project-a_new_team/world.py\", line 310, in step\n    raise ValueError(\nValueError: [INVALID:STEP] Not a valid step from [2 3] to [2 3] and put barrier at 0, with max steps = 4\n\nExecute Random Walk!\nAn exception raised. The traceback is as follows:\nTraceback (most recent call last):\n  File \"/home/ml/users/ksinha4/mlp/comp424_final_project/submissions/comp424mcgill/final-project-a_new_team/world.py\", line 310, in step\n    raise ValueError(\nValueError: [INVALID:STEP] Not a valid step from [5 4] to [5 4] and put barrier at 0, with max steps = 4\n\nExecute Random Walk!\nAn exception raised. The traceback is as follows:\nTraceback (most recent call last):\n  File \"/home/ml/users/ksinha4/mlp/comp424_final_project/submissions/comp424mcgill/final-project-a_new_team/world.py\", line 310, in step\n    raise ValueError(\nValueError: [INVALID:STEP] Not a valid step from [6 3] to [6 3] and put barrier at 0, with max steps = 4\n\nExecute Random Walk!\n"}, {"student_agent_score": 1, "random_agent_score": 48, "student_agent_time": 0.002633333206176758, "random_agent_time": 0.0023555755615234375, "board_size": 7, "swap_players": true, "run_out": "An exception raised. The traceback is as follows:\nTraceback (most recent call last):\n  File \"/home/ml/users/ksinha4/mlp/comp424_final_project/submissions/comp424mcgill/final-project-a_new_team/world.py\", line 310, in step\n    raise ValueError(\nValueError: [INVALID:STEP] Not a valid step from [2 3] to [2 3] and put barrier at 0, with max steps = 4\n\nExecute Random Walk!\nAn exception raised. The traceback is as follows:\nTraceback (most recent call last):\n  File \"/home/ml/users/ksinha4/mlp/comp424_final_project/submissions/comp424mcgill/final-project-a_new_team/world.py\", line 310, in step\n    raise ValueError(\nValueError: [INVALID:STEP] Not a valid step from [5 4] to [5 4] and put barrier at 0, with max steps = 4\n\nExecute Random Walk!\nAn exception raised. The traceback is as follows:\nTraceback (most recent call last):\n  File \"/home/ml/users/ksinha4/mlp/comp424_final_project/submissions/comp424mcgill/final-project-a_new_team/world.py\", line 310, in step\n    raise ValueError(\nValueError: [INVALID:STEP] Not a valid step from [6 3] to [6 3] and put barrier at 0, with max steps = 4\n\nExecute Random Walk!\n"}, {"student_agent_score": 1, "random_agent_score": 48, "student_agent_time": 0.0023605823516845703, "random_agent_time": 0.0028557777404785156, "board_size": 7, "swap_players": true, "run_out": "An exception raised. The traceback is as follows:\nTraceback (most recent call last):\n  File \"/home/ml/users/ksinha4/mlp/comp424_final_project/submissions/comp424mcgill/final-project-a_new_team/world.py\", line 310, in step\n    raise ValueError(\nValueError: [INVALID:STEP] Not a valid step from [2 3] to [2 3] and put barrier at 0, with max steps = 4\n\nExecute Random Walk!\nAn exception raised. The traceback is as follows:\nTraceback (most recent call last):\n  File \"/home/ml/users/ksinha4/mlp/comp424_final_project/submissions/comp424mcgill/final-project-a_new_team/world.py\", line 310, in step\n    raise ValueError(\nValueError: [INVALID:STEP] Not a valid step from [5 4] to [5 4] and put barrier at 0, with max steps = 4\n\nExecute Random Walk!\nAn exception raised. The traceback is as follows:\nTraceback (most recent call last):\n  File \"/home/ml/users/ksinha4/mlp/comp424_final_project/submissions/comp424mcgill/final-project-a_new_team/world.py\", line 310, in step\n    raise ValueError(\nValueError: [INVALID:STEP] Not a valid step from [6 3] to [6 3] and put barrier at 0, with max steps = 4\n\nExecute Random Walk!\n"}, {"student_agent_score": 2, "random_agent_score": 79, "student_agent_time": 0.002509593963623047, "random_agent_time": 0.0025243759155273438, "board_size": 9, "swap_players": false, "run_out": "An exception raised. The traceback is as follows:\nTraceback (most recent call last):\n  File \"/home/ml/users/ksinha4/mlp/comp424_final_project/submissions/comp424mcgill/final-project-a_new_team/world.py\", line 310, in step\n    raise ValueError(\nValueError: [INVALID:STEP] Not a valid step from [5 4] to [5 4] and put barrier at 0, with max steps = 5\n\nExecute Random Walk!\nAn exception raised. The traceback is as follows:\nTraceback (most recent call last):\n  File \"/home/ml/users/ksinha4/mlp/comp424_final_project/submissions/comp424mcgill/final-project-a_new_team/world.py\", line 310, in step\n    raise ValueError(\nValueError: [INVALID:STEP] Not a valid step from [5 3] to [5 3] and put barrier at 0, with max steps = 5\n\nExecute Random Walk!\n"}, {"student_agent_score": 1, "random_agent_score": 48, "student_agent_time": 0.0061643123626708984, "random_agent_time": 0.0026590824127197266, "board_size": 7, "swap_players": false, "run_out": "An exception raised. The traceback is as follows:\nTraceback (most recent call last):\n  File \"/home/ml/users/ksinha4/mlp/comp424_final_project/submissions/comp424mcgill/final-project-a_new_team/world.py\", line 310, in step\n    raise ValueError(\nValueError: [INVALID:STEP] Not a valid step from [4 3] to [4 3] and put barrier at 0, with max steps = 4\n\nExecute Random Walk!\nAn exception raised. The traceback is as follows:\nTraceback (most recent call last):\n  File \"/home/ml/users/ksinha4/mlp/comp424_final_project/submissions/comp424mcgill/final-project-a_new_team/world.py\", line 310, in step\n    raise ValueError(\nValueError: [INVALID:STEP] Not a valid step from [4 2] to [4 2] and put barrier at 0, with max steps = 4\n\nExecute Random Walk!\nAn exception raised. The traceback is as follows:\nTraceback (most recent call last):\n  File \"/home/ml/users/ksinha4/mlp/comp424_final_project/submissions/comp424mcgill/final-project-a_new_team/world.py\", line 310, in step\n    raise ValueError(\nValueError: [INVALID:STEP] Not a valid step from [4 3] to [4 3] and put barrier at 0, with max steps = 4\n\nExecute Random Walk!\nAn exception raised. The traceback is as follows:\nTraceback (most recent call last):\n  File \"/home/ml/users/ksinha4/mlp/comp424_final_project/submissions/comp424mcgill/final-project-a_new_team/world.py\", line 310, in step\n    raise ValueError(\nValueError: [INVALID:STEP] Not a valid step from [5 4] to [5 4] and put barrier at 0, with max steps = 4\n\nExecute Random Walk!\nAn exception raised. The traceback is as follows:\nTraceback (most recent call last):\n  File \"/home/ml/users/ksinha4/mlp/comp424_final_project/submissions/comp424mcgill/final-project-a_new_team/world.py\", line 310, in step\n    raise ValueError(\nValueError: [INVALID:STEP] Not a valid step from [6 3] to [6 3] and put barrier at 0, with max steps = 4\n\nExecute Random Walk!\n"}, {"student_agent_score": 1, "random_agent_score": 35, "student_agent_time": 0.003191709518432617, "random_agent_time": 0.0010673999786376953, "board_size": 6, "swap_players": false, "run_out": "An exception raised. The traceback is as follows:\nTraceback (most recent call last):\n  File \"/home/ml/users/ksinha4/mlp/comp424_final_project/submissions/comp424mcgill/final-project-a_new_team/world.py\", line 310, in step\n    raise ValueError(\nValueError: [INVALID:STEP] Not a valid step from [2 2] to [2 2] and put barrier at 0, with max steps = 3\n\nExecute Random Walk!\nAn exception raised. The traceback is as follows:\nTraceback (most recent call last):\n  File \"/home/ml/users/ksinha4/mlp/comp424_final_project/submissions/comp424mcgill/final-project-a_new_team/world.py\", line 310, in step\n    raise ValueError(\nValueError: [INVALID:STEP] Not a valid step from [3 0] to [3 0] and put barrier at 0, with max steps = 3\n\nExecute Random Walk!\n"}, {"student_agent_score": 1, "random_agent_score": 48, "student_agent_time": 0.002325296401977539, "random_agent_time": 0.002145051956176758, "board_size": 7, "swap_players": true, "run_out": "An exception raised. The traceback is as follows:\nTraceback (most recent call last):\n  File \"/home/ml/users/ksinha4/mlp/comp424_final_project/submissions/comp424mcgill/final-project-a_new_team/world.py\", line 310, in step\n    raise ValueError(\nValueError: [INVALID:STEP] Not a valid step from [2 3] to [2 3] and put barrier at 0, with max steps = 4\n\nExecute Random Walk!\nAn exception raised. The traceback is as follows:\nTraceback (most recent call last):\n  File \"/home/ml/users/ksinha4/mlp/comp424_final_project/submissions/comp424mcgill/final-project-a_new_team/world.py\", line 310, in step\n    raise ValueError(\nValueError: [INVALID:STEP] Not a valid step from [5 4] to [5 4] and put barrier at 0, with max steps = 4\n\nExecute Random Walk!\nAn exception raised. The traceback is as follows:\nTraceback (most recent call last):\n  File \"/home/ml/users/ksinha4/mlp/comp424_final_project/submissions/comp424mcgill/final-project-a_new_team/world.py\", line 310, in step\n    raise ValueError(\nValueError: [INVALID:STEP] Not a valid step from [6 3] to [6 3] and put barrier at 0, with max steps = 4\n\nExecute Random Walk!\n"}, {"student_agent_score": 1, "random_agent_score": 35, "student_agent_time": 0.0028443336486816406, "random_agent_time": 0.002186298370361328, "board_size": 6, "swap_players": true, "run_out": "An exception raised. The traceback is as follows:\nTraceback (most recent call last):\n  File \"/home/ml/users/ksinha4/mlp/comp424_final_project/submissions/comp424mcgill/final-project-a_new_team/world.py\", line 310, in step\n    raise ValueError(\nValueError: [INVALID:STEP] Not a valid step from [3 3] to [3 3] and put barrier at 0, with max steps = 3\n\nExecute Random Walk!\nAn exception raised. The traceback is as follows:\nTraceback (most recent call last):\n  File \"/home/ml/users/ksinha4/mlp/comp424_final_project/submissions/comp424mcgill/final-project-a_new_team/world.py\", line 310, in step\n    raise ValueError(\nValueError: [INVALID:STEP] Not a valid step from [3 3] to [3 3] and put barrier at 0, with max steps = 3\n\nExecute Random Walk!\n"}, {"student_agent_score": 1, "random_agent_score": 48, "student_agent_time": 0.003987789154052734, "random_agent_time": 0.003206968307495117, "board_size": 7, "swap_players": false, "run_out": "An exception raised. The traceback is as follows:\nTraceback (most recent call last):\n  File \"/home/ml/users/ksinha4/mlp/comp424_final_project/submissions/comp424mcgill/final-project-a_new_team/world.py\", line 310, in step\n    raise ValueError(\nValueError: [INVALID:STEP] Not a valid step from [4 3] to [4 3] and put barrier at 0, with max steps = 4\n\nExecute Random Walk!\nAn exception raised. The traceback is as follows:\nTraceback (most recent call last):\n  File \"/home/ml/users/ksinha4/mlp/comp424_final_project/submissions/comp424mcgill/final-project-a_new_team/world.py\", line 310, in step\n    raise ValueError(\nValueError: [INVALID:STEP] Not a valid step from [4 2] to [4 2] and put barrier at 0, with max steps = 4\n\nExecute Random Walk!\nAn exception raised. The traceback is as follows:\nTraceback (most recent call last):\n  File \"/home/ml/users/ksinha4/mlp/comp424_final_project/submissions/comp424mcgill/final-project-a_new_team/world.py\", line 310, in step\n    raise ValueError(\nValueError: [INVALID:STEP] Not a valid step from [4 3] to [4 3] and put barrier at 0, with max steps = 4\n\nExecute Random Walk!\nAn exception raised. The traceback is as follows:\nTraceback (most recent call last):\n  File \"/home/ml/users/ksinha4/mlp/comp424_final_project/submissions/comp424mcgill/final-project-a_new_team/world.py\", line 310, in step\n    raise ValueError(\nValueError: [INVALID:STEP] Not a valid step from [5 4] to [5 4] and put barrier at 0, with max steps = 4\n\nExecute Random Walk!\nAn exception raised. The traceback is as follows:\nTraceback (most recent call last):\n  File \"/home/ml/users/ksinha4/mlp/comp424_final_project/submissions/comp424mcgill/final-project-a_new_team/world.py\", line 310, in step\n    raise ValueError(\nValueError: [INVALID:STEP] Not a valid step from [6 3] to [6 3] and put barrier at 0, with max steps = 4\n\nExecute Random Walk!\n"}, {"student_agent_score": 1, "random_agent_score": 48, "student_agent_time": 0.0024633407592773438, "random_agent_time": 0.004035472869873047, "board_size": 7, "swap_players": true, "run_out": "An exception raised. The traceback is as follows:\nTraceback (most recent call last):\n  File \"/home/ml/users/ksinha4/mlp/comp424_final_project/submissions/comp424mcgill/final-project-a_new_team/world.py\", line 310, in step\n    raise ValueError(\nValueError: [INVALID:STEP] Not a valid step from [2 3] to [2 3] and put barrier at 0, with max steps = 4\n\nExecute Random Walk!\nAn exception raised. The traceback is as follows:\nTraceback (most recent call last):\n  File \"/home/ml/users/ksinha4/mlp/comp424_final_project/submissions/comp424mcgill/final-project-a_new_team/world.py\", line 310, in step\n    raise ValueError(\nValueError: [INVALID:STEP] Not a valid step from [5 4] to [5 4] and put barrier at 0, with max steps = 4\n\nExecute Random Walk!\nAn exception raised. The traceback is as follows:\nTraceback (most recent call last):\n  File \"/home/ml/users/ksinha4/mlp/comp424_final_project/submissions/comp424mcgill/final-project-a_new_team/world.py\", line 310, in step\n    raise ValueError(\nValueError: [INVALID:STEP] Not a valid step from [6 3] to [6 3] and put barrier at 0, with max steps = 4\n\nExecute Random Walk!\n"}, {"student_agent_score": 63, "random_agent_score": 1, "student_agent_time": 0.0048067569732666016, "random_agent_time": 0.0035004615783691406, "board_size": 8, "swap_players": true, "run_out": "An exception raised. The traceback is as follows:\nTraceback (most recent call last):\n  File \"/home/ml/users/ksinha4/mlp/comp424_final_project/submissions/comp424mcgill/final-project-a_new_team/world.py\", line 310, in step\n    raise ValueError(\nValueError: [INVALID:STEP] Not a valid step from [5 5] to [5 5] and put barrier at 0, with max steps = 4\n\nExecute Random Walk!\nAn exception raised. The traceback is as follows:\nTraceback (most recent call last):\n  File \"/home/ml/users/ksinha4/mlp/comp424_final_project/submissions/comp424mcgill/final-project-a_new_team/world.py\", line 310, in step\n    raise ValueError(\nValueError: [INVALID:STEP] Not a valid step from [5 4] to [5 4] and put barrier at 0, with max steps = 4\n\nExecute Random Walk!\nAn exception raised. The traceback is as follows:\nTraceback (most recent call last):\n  File \"/home/ml/users/ksinha4/mlp/comp424_final_project/submissions/comp424mcgill/final-project-a_new_team/world.py\", line 310, in step\n    raise ValueError(\nValueError: [INVALID:STEP] Not a valid step from [5 4] to [5 4] and put barrier at 0, with max steps = 4\n\nExecute Random Walk!\n"}, {"student_agent_score": 2, "random_agent_score": 98, "student_agent_time": 0.004378318786621094, "random_agent_time": 0.004827976226806641, "board_size": 10, "swap_players": false, "run_out": "An exception raised. The traceback is as follows:\nTraceback (most recent call last):\n  File \"/home/ml/users/ksinha4/mlp/comp424_final_project/submissions/comp424mcgill/final-project-a_new_team/world.py\", line 310, in step\n    raise ValueError(\nValueError: [INVALID:STEP] Not a valid step from [7 5] to [7 5] and put barrier at 0, with max steps = 5\n\nExecute Random Walk!\nAn exception raised. The traceback is as follows:\nTraceback (most recent call last):\n  File \"/home/ml/users/ksinha4/mlp/comp424_final_project/submissions/comp424mcgill/final-project-a_new_team/world.py\", line 310, in step\n    raise ValueError(\nValueError: [INVALID:STEP] Not a valid step from [6 6] to [6 6] and put barrier at 0, with max steps = 5\n\nExecute Random Walk!\nAn exception raised. The traceback is as follows:\nTraceback (most recent call last):\n  File \"/home/ml/users/ksinha4/mlp/comp424_final_project/submissions/comp424mcgill/final-project-a_new_team/world.py\", line 310, in step\n    raise ValueError(\nValueError: [INVALID:STEP] Not a valid step from [7 8] to [7 8] and put barrier at 0, with max steps = 5\n\nExecute Random Walk!\nAn exception raised. The traceback is as follows:\nTraceback (most recent call last):\n  File \"/home/ml/users/ksinha4/mlp/comp424_final_project/submissions/comp424mcgill/final-project-a_new_team/world.py\", line 310, in step\n    raise ValueError(\nValueError: [INVALID:STEP] Not a valid step from [7 8] to [7 8] and put barrier at 0, with max steps = 5\n\nExecute Random Walk!\n"}, {"student_agent_score": 1, "random_agent_score": 48, "student_agent_time": 0.00217437744140625, "random_agent_time": 0.0018002986907958984, "board_size": 7, "swap_players": true, "run_out": "An exception raised. The traceback is as follows:\nTraceback (most recent call last):\n  File \"/home/ml/users/ksinha4/mlp/comp424_final_project/submissions/comp424mcgill/final-project-a_new_team/world.py\", line 310, in step\n    raise ValueError(\nValueError: [INVALID:STEP] Not a valid step from [2 3] to [2 3] and put barrier at 0, with max steps = 4\n\nExecute Random Walk!\nAn exception raised. The traceback is as follows:\nTraceback (most recent call last):\n  File \"/home/ml/users/ksinha4/mlp/comp424_final_project/submissions/comp424mcgill/final-project-a_new_team/world.py\", line 310, in step\n    raise ValueError(\nValueError: [INVALID:STEP] Not a valid step from [5 4] to [5 4] and put barrier at 0, with max steps = 4\n\nExecute Random Walk!\nAn exception raised. The traceback is as follows:\nTraceback (most recent call last):\n  File \"/home/ml/users/ksinha4/mlp/comp424_final_project/submissions/comp424mcgill/final-project-a_new_team/world.py\", line 310, in step\n    raise ValueError(\nValueError: [INVALID:STEP] Not a valid step from [6 3] to [6 3] and put barrier at 0, with max steps = 4\n\nExecute Random Walk!\n"}, {"student_agent_score": 1, "random_agent_score": 48, "student_agent_time": 0.0050351619720458984, "random_agent_time": 0.0024538040161132812, "board_size": 7, "swap_players": false, "run_out": "An exception raised. The traceback is as follows:\nTraceback (most recent call last):\n  File \"/home/ml/users/ksinha4/mlp/comp424_final_project/submissions/comp424mcgill/final-project-a_new_team/world.py\", line 310, in step\n    raise ValueError(\nValueError: [INVALID:STEP] Not a valid step from [4 3] to [4 3] and put barrier at 0, with max steps = 4\n\nExecute Random Walk!\nAn exception raised. The traceback is as follows:\nTraceback (most recent call last):\n  File \"/home/ml/users/ksinha4/mlp/comp424_final_project/submissions/comp424mcgill/final-project-a_new_team/world.py\", line 310, in step\n    raise ValueError(\nValueError: [INVALID:STEP] Not a valid step from [4 2] to [4 2] and put barrier at 0, with max steps = 4\n\nExecute Random Walk!\nAn exception raised. The traceback is as follows:\nTraceback (most recent call last):\n  File \"/home/ml/users/ksinha4/mlp/comp424_final_project/submissions/comp424mcgill/final-project-a_new_team/world.py\", line 310, in step\n    raise ValueError(\nValueError: [INVALID:STEP] Not a valid step from [4 3] to [4 3] and put barrier at 0, with max steps = 4\n\nExecute Random Walk!\nAn exception raised. The traceback is as follows:\nTraceback (most recent call last):\n  File \"/home/ml/users/ksinha4/mlp/comp424_final_project/submissions/comp424mcgill/final-project-a_new_team/world.py\", line 310, in step\n    raise ValueError(\nValueError: [INVALID:STEP] Not a valid step from [5 4] to [5 4] and put barrier at 0, with max steps = 4\n\nExecute Random Walk!\nAn exception raised. The traceback is as follows:\nTraceback (most recent call last):\n  File \"/home/ml/users/ksinha4/mlp/comp424_final_project/submissions/comp424mcgill/final-project-a_new_team/world.py\", line 310, in step\n    raise ValueError(\nValueError: [INVALID:STEP] Not a valid step from [6 3] to [6 3] and put barrier at 0, with max steps = 4\n\nExecute Random Walk!\n"}, {"student_agent_score": 1, "random_agent_score": 48, "student_agent_time": 0.002982616424560547, "random_agent_time": 0.003000020980834961, "board_size": 7, "swap_players": true, "run_out": "An exception raised. The traceback is as follows:\nTraceback (most recent call last):\n  File \"/home/ml/users/ksinha4/mlp/comp424_final_project/submissions/comp424mcgill/final-project-a_new_team/world.py\", line 310, in step\n    raise ValueError(\nValueError: [INVALID:STEP] Not a valid step from [2 3] to [2 3] and put barrier at 0, with max steps = 4\n\nExecute Random Walk!\nAn exception raised. The traceback is as follows:\nTraceback (most recent call last):\n  File \"/home/ml/users/ksinha4/mlp/comp424_final_project/submissions/comp424mcgill/final-project-a_new_team/world.py\", line 310, in step\n    raise ValueError(\nValueError: [INVALID:STEP] Not a valid step from [5 4] to [5 4] and put barrier at 0, with max steps = 4\n\nExecute Random Walk!\nAn exception raised. The traceback is as follows:\nTraceback (most recent call last):\n  File \"/home/ml/users/ksinha4/mlp/comp424_final_project/submissions/comp424mcgill/final-project-a_new_team/world.py\", line 310, in step\n    raise ValueError(\nValueError: [INVALID:STEP] Not a valid step from [6 3] to [6 3] and put barrier at 0, with max steps = 4\n\nExecute Random Walk!\n"}, {"student_agent_score": 1, "random_agent_score": 48, "student_agent_time": 0.002499103546142578, "random_agent_time": 0.0028886795043945312, "board_size": 7, "swap_players": true, "run_out": "An exception raised. The traceback is as follows:\nTraceback (most recent call last):\n  File \"/home/ml/users/ksinha4/mlp/comp424_final_project/submissions/comp424mcgill/final-project-a_new_team/world.py\", line 310, in step\n    raise ValueError(\nValueError: [INVALID:STEP] Not a valid step from [2 3] to [2 3] and put barrier at 0, with max steps = 4\n\nExecute Random Walk!\nAn exception raised. The traceback is as follows:\nTraceback (most recent call last):\n  File \"/home/ml/users/ksinha4/mlp/comp424_final_project/submissions/comp424mcgill/final-project-a_new_team/world.py\", line 310, in step\n    raise ValueError(\nValueError: [INVALID:STEP] Not a valid step from [5 4] to [5 4] and put barrier at 0, with max steps = 4\n\nExecute Random Walk!\nAn exception raised. The traceback is as follows:\nTraceback (most recent call last):\n  File \"/home/ml/users/ksinha4/mlp/comp424_final_project/submissions/comp424mcgill/final-project-a_new_team/world.py\", line 310, in step\n    raise ValueError(\nValueError: [INVALID:STEP] Not a valid step from [6 3] to [6 3] and put barrier at 0, with max steps = 4\n\nExecute Random Walk!\n"}, {"student_agent_score": 1, "random_agent_score": 63, "student_agent_time": 0.00459742546081543, "random_agent_time": 0.002666950225830078, "board_size": 8, "swap_players": false, "run_out": "An exception raised. The traceback is as follows:\nTraceback (most recent call last):\n  File \"/home/ml/users/ksinha4/mlp/comp424_final_project/submissions/comp424mcgill/final-project-a_new_team/world.py\", line 310, in step\n    raise ValueError(\nValueError: [INVALID:STEP] Not a valid step from [2 2] to [2 2] and put barrier at 0, with max steps = 4\n\nExecute Random Walk!\nAn exception raised. The traceback is as follows:\nTraceback (most recent call last):\n  File \"/home/ml/users/ksinha4/mlp/comp424_final_project/submissions/comp424mcgill/final-project-a_new_team/world.py\", line 310, in step\n    raise ValueError(\nValueError: [INVALID:STEP] Not a valid step from [3 1] to [3 1] and put barrier at 0, with max steps = 4\n\nExecute Random Walk!\nAn exception raised. The traceback is as follows:\nTraceback (most recent call last):\n  File \"/home/ml/users/ksinha4/mlp/comp424_final_project/submissions/comp424mcgill/final-project-a_new_team/world.py\", line 310, in step\n    raise ValueError(\nValueError: [INVALID:STEP] Not a valid step from [3 0] to [3 0] and put barrier at 0, with max steps = 4\n\nExecute Random Walk!\nAn exception raised. The traceback is as follows:\nTraceback (most recent call last):\n  File \"/home/ml/users/ksinha4/mlp/comp424_final_project/submissions/comp424mcgill/final-project-a_new_team/world.py\", line 310, in step\n    raise ValueError(\nValueError: [INVALID:STEP] Not a valid step from [6 1] to [6 1] and put barrier at 0, with max steps = 4\n\nExecute Random Walk!\n"}, {"student_agent_score": 1, "random_agent_score": 48, "student_agent_time": 0.004101276397705078, "random_agent_time": 0.0024192333221435547, "board_size": 7, "swap_players": false, "run_out": "An exception raised. The traceback is as follows:\nTraceback (most recent call last):\n  File \"/home/ml/users/ksinha4/mlp/comp424_final_project/submissions/comp424mcgill/final-project-a_new_team/world.py\", line 310, in step\n    raise ValueError(\nValueError: [INVALID:STEP] Not a valid step from [4 3] to [4 3] and put barrier at 0, with max steps = 4\n\nExecute Random Walk!\nAn exception raised. The traceback is as follows:\nTraceback (most recent call last):\n  File \"/home/ml/users/ksinha4/mlp/comp424_final_project/submissions/comp424mcgill/final-project-a_new_team/world.py\", line 310, in step\n    raise ValueError(\nValueError: [INVALID:STEP] Not a valid step from [4 2] to [4 2] and put barrier at 0, with max steps = 4\n\nExecute Random Walk!\nAn exception raised. The traceback is as follows:\nTraceback (most recent call last):\n  File \"/home/ml/users/ksinha4/mlp/comp424_final_project/submissions/comp424mcgill/final-project-a_new_team/world.py\", line 310, in step\n    raise ValueError(\nValueError: [INVALID:STEP] Not a valid step from [4 3] to [4 3] and put barrier at 0, with max steps = 4\n\nExecute Random Walk!\nAn exception raised. The traceback is as follows:\nTraceback (most recent call last):\n  File \"/home/ml/users/ksinha4/mlp/comp424_final_project/submissions/comp424mcgill/final-project-a_new_team/world.py\", line 310, in step\n    raise ValueError(\nValueError: [INVALID:STEP] Not a valid step from [5 4] to [5 4] and put barrier at 0, with max steps = 4\n\nExecute Random Walk!\nAn exception raised. The traceback is as follows:\nTraceback (most recent call last):\n  File \"/home/ml/users/ksinha4/mlp/comp424_final_project/submissions/comp424mcgill/final-project-a_new_team/world.py\", line 310, in step\n    raise ValueError(\nValueError: [INVALID:STEP] Not a valid step from [6 3] to [6 3] and put barrier at 0, with max steps = 4\n\nExecute Random Walk!\n"}, {"student_agent_score": 1, "random_agent_score": 48, "student_agent_time": 0.003262042999267578, "random_agent_time": 0.0044329166412353516, "board_size": 7, "swap_players": true, "run_out": "An exception raised. The traceback is as follows:\nTraceback (most recent call last):\n  File \"/home/ml/users/ksinha4/mlp/comp424_final_project/submissions/comp424mcgill/final-project-a_new_team/world.py\", line 310, in step\n    raise ValueError(\nValueError: [INVALID:STEP] Not a valid step from [2 3] to [2 3] and put barrier at 0, with max steps = 4\n\nExecute Random Walk!\nAn exception raised. The traceback is as follows:\nTraceback (most recent call last):\n  File \"/home/ml/users/ksinha4/mlp/comp424_final_project/submissions/comp424mcgill/final-project-a_new_team/world.py\", line 310, in step\n    raise ValueError(\nValueError: [INVALID:STEP] Not a valid step from [5 4] to [5 4] and put barrier at 0, with max steps = 4\n\nExecute Random Walk!\nAn exception raised. The traceback is as follows:\nTraceback (most recent call last):\n  File \"/home/ml/users/ksinha4/mlp/comp424_final_project/submissions/comp424mcgill/final-project-a_new_team/world.py\", line 310, in step\n    raise ValueError(\nValueError: [INVALID:STEP] Not a valid step from [6 3] to [6 3] and put barrier at 0, with max steps = 4\n\nExecute Random Walk!\n"}, {"student_agent_score": 99, "random_agent_score": 1, "student_agent_time": 0.00030803680419921875, "random_agent_time": 0.0008165836334228516, "board_size": 10, "swap_players": true, "run_out": ""}, {"student_agent_score": 1, "random_agent_score": 48, "student_agent_time": 0.004578113555908203, "random_agent_time": 0.0026388168334960938, "board_size": 7, "swap_players": true, "run_out": "An exception raised. The traceback is as follows:\nTraceback (most recent call last):\n  File \"/home/ml/users/ksinha4/mlp/comp424_final_project/submissions/comp424mcgill/final-project-a_new_team/world.py\", line 310, in step\n    raise ValueError(\nValueError: [INVALID:STEP] Not a valid step from [2 3] to [2 3] and put barrier at 0, with max steps = 4\n\nExecute Random Walk!\nAn exception raised. The traceback is as follows:\nTraceback (most recent call last):\n  File \"/home/ml/users/ksinha4/mlp/comp424_final_project/submissions/comp424mcgill/final-project-a_new_team/world.py\", line 310, in step\n    raise ValueError(\nValueError: [INVALID:STEP] Not a valid step from [5 4] to [5 4] and put barrier at 0, with max steps = 4\n\nExecute Random Walk!\nAn exception raised. The traceback is as follows:\nTraceback (most recent call last):\n  File \"/home/ml/users/ksinha4/mlp/comp424_final_project/submissions/comp424mcgill/final-project-a_new_team/world.py\", line 310, in step\n    raise ValueError(\nValueError: [INVALID:STEP] Not a valid step from [6 3] to [6 3] and put barrier at 0, with max steps = 4\n\nExecute Random Walk!\n"}, {"student_agent_score": 1, "random_agent_score": 48, "student_agent_time": 0.002935171127319336, "random_agent_time": 0.0025413036346435547, "board_size": 7, "swap_players": true, "run_out": "An exception raised. The traceback is as follows:\nTraceback (most recent call last):\n  File \"/home/ml/users/ksinha4/mlp/comp424_final_project/submissions/comp424mcgill/final-project-a_new_team/world.py\", line 310, in step\n    raise ValueError(\nValueError: [INVALID:STEP] Not a valid step from [2 3] to [2 3] and put barrier at 0, with max steps = 4\n\nExecute Random Walk!\nAn exception raised. The traceback is as follows:\nTraceback (most recent call last):\n  File \"/home/ml/users/ksinha4/mlp/comp424_final_project/submissions/comp424mcgill/final-project-a_new_team/world.py\", line 310, in step\n    raise ValueError(\nValueError: [INVALID:STEP] Not a valid step from [5 4] to [5 4] and put barrier at 0, with max steps = 4\n\nExecute Random Walk!\nAn exception raised. The traceback is as follows:\nTraceback (most recent call last):\n  File \"/home/ml/users/ksinha4/mlp/comp424_final_project/submissions/comp424mcgill/final-project-a_new_team/world.py\", line 310, in step\n    raise ValueError(\nValueError: [INVALID:STEP] Not a valid step from [6 3] to [6 3] and put barrier at 0, with max steps = 4\n\nExecute Random Walk!\n"}, {"student_agent_score": 1, "random_agent_score": 63, "student_agent_time": 0.0033576488494873047, "random_agent_time": 0.0020618438720703125, "board_size": 8, "swap_players": false, "run_out": "An exception raised. The traceback is as follows:\nTraceback (most recent call last):\n  File \"/home/ml/users/ksinha4/mlp/comp424_final_project/submissions/comp424mcgill/final-project-a_new_team/world.py\", line 310, in step\n    raise ValueError(\nValueError: [INVALID:STEP] Not a valid step from [2 2] to [2 2] and put barrier at 0, with max steps = 4\n\nExecute Random Walk!\nAn exception raised. The traceback is as follows:\nTraceback (most recent call last):\n  File \"/home/ml/users/ksinha4/mlp/comp424_final_project/submissions/comp424mcgill/final-project-a_new_team/world.py\", line 310, in step\n    raise ValueError(\nValueError: [INVALID:STEP] Not a valid step from [3 1] to [3 1] and put barrier at 0, with max steps = 4\n\nExecute Random Walk!\nAn exception raised. The traceback is as follows:\nTraceback (most recent call last):\n  File \"/home/ml/users/ksinha4/mlp/comp424_final_project/submissions/comp424mcgill/final-project-a_new_team/world.py\", line 310, in step\n    raise ValueError(\nValueError: [INVALID:STEP] Not a valid step from [3 0] to [3 0] and put barrier at 0, with max steps = 4\n\nExecute Random Walk!\nAn exception raised. The traceback is as follows:\nTraceback (most recent call last):\n  File \"/home/ml/users/ksinha4/mlp/comp424_final_project/submissions/comp424mcgill/final-project-a_new_team/world.py\", line 310, in step\n    raise ValueError(\nValueError: [INVALID:STEP] Not a valid step from [6 1] to [6 1] and put barrier at 0, with max steps = 4\n\nExecute Random Walk!\n"}, {"student_agent_score": 1, "random_agent_score": 48, "student_agent_time": 0.004148244857788086, "random_agent_time": 0.003067493438720703, "board_size": 7, "swap_players": false, "run_out": "An exception raised. The traceback is as follows:\nTraceback (most recent call last):\n  File \"/home/ml/users/ksinha4/mlp/comp424_final_project/submissions/comp424mcgill/final-project-a_new_team/world.py\", line 310, in step\n    raise ValueError(\nValueError: [INVALID:STEP] Not a valid step from [4 3] to [4 3] and put barrier at 0, with max steps = 4\n\nExecute Random Walk!\nAn exception raised. The traceback is as follows:\nTraceback (most recent call last):\n  File \"/home/ml/users/ksinha4/mlp/comp424_final_project/submissions/comp424mcgill/final-project-a_new_team/world.py\", line 310, in step\n    raise ValueError(\nValueError: [INVALID:STEP] Not a valid step from [4 2] to [4 2] and put barrier at 0, with max steps = 4\n\nExecute Random Walk!\nAn exception raised. The traceback is as follows:\nTraceback (most recent call last):\n  File \"/home/ml/users/ksinha4/mlp/comp424_final_project/submissions/comp424mcgill/final-project-a_new_team/world.py\", line 310, in step\n    raise ValueError(\nValueError: [INVALID:STEP] Not a valid step from [4 3] to [4 3] and put barrier at 0, with max steps = 4\n\nExecute Random Walk!\nAn exception raised. The traceback is as follows:\nTraceback (most recent call last):\n  File \"/home/ml/users/ksinha4/mlp/comp424_final_project/submissions/comp424mcgill/final-project-a_new_team/world.py\", line 310, in step\n    raise ValueError(\nValueError: [INVALID:STEP] Not a valid step from [5 4] to [5 4] and put barrier at 0, with max steps = 4\n\nExecute Random Walk!\nAn exception raised. The traceback is as follows:\nTraceback (most recent call last):\n  File \"/home/ml/users/ksinha4/mlp/comp424_final_project/submissions/comp424mcgill/final-project-a_new_team/world.py\", line 310, in step\n    raise ValueError(\nValueError: [INVALID:STEP] Not a valid step from [6 3] to [6 3] and put barrier at 0, with max steps = 4\n\nExecute Random Walk!\n"}, {"student_agent_score": 2, "random_agent_score": 98, "student_agent_time": 0.006587982177734375, "random_agent_time": 0.007380247116088867, "board_size": 10, "swap_players": false, "run_out": "An exception raised. The traceback is as follows:\nTraceback (most recent call last):\n  File \"/home/ml/users/ksinha4/mlp/comp424_final_project/submissions/comp424mcgill/final-project-a_new_team/world.py\", line 310, in step\n    raise ValueError(\nValueError: [INVALID:STEP] Not a valid step from [7 5] to [7 5] and put barrier at 0, with max steps = 5\n\nExecute Random Walk!\nAn exception raised. The traceback is as follows:\nTraceback (most recent call last):\n  File \"/home/ml/users/ksinha4/mlp/comp424_final_project/submissions/comp424mcgill/final-project-a_new_team/world.py\", line 310, in step\n    raise ValueError(\nValueError: [INVALID:STEP] Not a valid step from [6 6] to [6 6] and put barrier at 0, with max steps = 5\n\nExecute Random Walk!\nAn exception raised. The traceback is as follows:\nTraceback (most recent call last):\n  File \"/home/ml/users/ksinha4/mlp/comp424_final_project/submissions/comp424mcgill/final-project-a_new_team/world.py\", line 310, in step\n    raise ValueError(\nValueError: [INVALID:STEP] Not a valid step from [7 8] to [7 8] and put barrier at 0, with max steps = 5\n\nExecute Random Walk!\nAn exception raised. The traceback is as follows:\nTraceback (most recent call last):\n  File \"/home/ml/users/ksinha4/mlp/comp424_final_project/submissions/comp424mcgill/final-project-a_new_team/world.py\", line 310, in step\n    raise ValueError(\nValueError: [INVALID:STEP] Not a valid step from [7 8] to [7 8] and put barrier at 0, with max steps = 5\n\nExecute Random Walk!\n"}, {"student_agent_score": 1, "random_agent_score": 48, "student_agent_time": 0.005008697509765625, "random_agent_time": 0.002610921859741211, "board_size": 7, "swap_players": false, "run_out": "An exception raised. The traceback is as follows:\nTraceback (most recent call last):\n  File \"/home/ml/users/ksinha4/mlp/comp424_final_project/submissions/comp424mcgill/final-project-a_new_team/world.py\", line 310, in step\n    raise ValueError(\nValueError: [INVALID:STEP] Not a valid step from [4 3] to [4 3] and put barrier at 0, with max steps = 4\n\nExecute Random Walk!\nAn exception raised. The traceback is as follows:\nTraceback (most recent call last):\n  File \"/home/ml/users/ksinha4/mlp/comp424_final_project/submissions/comp424mcgill/final-project-a_new_team/world.py\", line 310, in step\n    raise ValueError(\nValueError: [INVALID:STEP] Not a valid step from [4 2] to [4 2] and put barrier at 0, with max steps = 4\n\nExecute Random Walk!\nAn exception raised. The traceback is as follows:\nTraceback (most recent call last):\n  File \"/home/ml/users/ksinha4/mlp/comp424_final_project/submissions/comp424mcgill/final-project-a_new_team/world.py\", line 310, in step\n    raise ValueError(\nValueError: [INVALID:STEP] Not a valid step from [4 3] to [4 3] and put barrier at 0, with max steps = 4\n\nExecute Random Walk!\nAn exception raised. The traceback is as follows:\nTraceback (most recent call last):\n  File \"/home/ml/users/ksinha4/mlp/comp424_final_project/submissions/comp424mcgill/final-project-a_new_team/world.py\", line 310, in step\n    raise ValueError(\nValueError: [INVALID:STEP] Not a valid step from [5 4] to [5 4] and put barrier at 0, with max steps = 4\n\nExecute Random Walk!\nAn exception raised. The traceback is as follows:\nTraceback (most recent call last):\n  File \"/home/ml/users/ksinha4/mlp/comp424_final_project/submissions/comp424mcgill/final-project-a_new_team/world.py\", line 310, in step\n    raise ValueError(\nValueError: [INVALID:STEP] Not a valid step from [6 3] to [6 3] and put barrier at 0, with max steps = 4\n\nExecute Random Walk!\n"}, {"student_agent_score": 1, "random_agent_score": 48, "student_agent_time": 0.002354860305786133, "random_agent_time": 0.002198457717895508, "board_size": 7, "swap_players": true, "run_out": "An exception raised. The traceback is as follows:\nTraceback (most recent call last):\n  File \"/home/ml/users/ksinha4/mlp/comp424_final_project/submissions/comp424mcgill/final-project-a_new_team/world.py\", line 310, in step\n    raise ValueError(\nValueError: [INVALID:STEP] Not a valid step from [2 3] to [2 3] and put barrier at 0, with max steps = 4\n\nExecute Random Walk!\nAn exception raised. The traceback is as follows:\nTraceback (most recent call last):\n  File \"/home/ml/users/ksinha4/mlp/comp424_final_project/submissions/comp424mcgill/final-project-a_new_team/world.py\", line 310, in step\n    raise ValueError(\nValueError: [INVALID:STEP] Not a valid step from [5 4] to [5 4] and put barrier at 0, with max steps = 4\n\nExecute Random Walk!\nAn exception raised. The traceback is as follows:\nTraceback (most recent call last):\n  File \"/home/ml/users/ksinha4/mlp/comp424_final_project/submissions/comp424mcgill/final-project-a_new_team/world.py\", line 310, in step\n    raise ValueError(\nValueError: [INVALID:STEP] Not a valid step from [6 3] to [6 3] and put barrier at 0, with max steps = 4\n\nExecute Random Walk!\n"}, {"student_agent_score": 1, "random_agent_score": 48, "student_agent_time": 0.003498554229736328, "random_agent_time": 0.0018243789672851562, "board_size": 7, "swap_players": false, "run_out": "An exception raised. The traceback is as follows:\nTraceback (most recent call last):\n  File \"/home/ml/users/ksinha4/mlp/comp424_final_project/submissions/comp424mcgill/final-project-a_new_team/world.py\", line 310, in step\n    raise ValueError(\nValueError: [INVALID:STEP] Not a valid step from [4 3] to [4 3] and put barrier at 0, with max steps = 4\n\nExecute Random Walk!\nAn exception raised. The traceback is as follows:\nTraceback (most recent call last):\n  File \"/home/ml/users/ksinha4/mlp/comp424_final_project/submissions/comp424mcgill/final-project-a_new_team/world.py\", line 310, in step\n    raise ValueError(\nValueError: [INVALID:STEP] Not a valid step from [4 2] to [4 2] and put barrier at 0, with max steps = 4\n\nExecute Random Walk!\nAn exception raised. The traceback is as follows:\nTraceback (most recent call last):\n  File \"/home/ml/users/ksinha4/mlp/comp424_final_project/submissions/comp424mcgill/final-project-a_new_team/world.py\", line 310, in step\n    raise ValueError(\nValueError: [INVALID:STEP] Not a valid step from [4 3] to [4 3] and put barrier at 0, with max steps = 4\n\nExecute Random Walk!\nAn exception raised. The traceback is as follows:\nTraceback (most recent call last):\n  File \"/home/ml/users/ksinha4/mlp/comp424_final_project/submissions/comp424mcgill/final-project-a_new_team/world.py\", line 310, in step\n    raise ValueError(\nValueError: [INVALID:STEP] Not a valid step from [5 4] to [5 4] and put barrier at 0, with max steps = 4\n\nExecute Random Walk!\nAn exception raised. The traceback is as follows:\nTraceback (most recent call last):\n  File \"/home/ml/users/ksinha4/mlp/comp424_final_project/submissions/comp424mcgill/final-project-a_new_team/world.py\", line 310, in step\n    raise ValueError(\nValueError: [INVALID:STEP] Not a valid step from [6 3] to [6 3] and put barrier at 0, with max steps = 4\n\nExecute Random Walk!\n"}, {"student_agent_score": 117, "random_agent_score": 1, "student_agent_time": 0.008089303970336914, "random_agent_time": 0.007405281066894531, "board_size": 11, "swap_players": false, "run_out": "An exception raised. The traceback is as follows:\nTraceback (most recent call last):\n  File \"/home/ml/users/ksinha4/mlp/comp424_final_project/submissions/comp424mcgill/final-project-a_new_team/world.py\", line 310, in step\n    raise ValueError(\nValueError: [INVALID:STEP] Not a valid step from [1 7] to [1 7] and put barrier at 0, with max steps = 6\n\nExecute Random Walk!\nAn exception raised. The traceback is as follows:\nTraceback (most recent call last):\n  File \"/home/ml/users/ksinha4/mlp/comp424_final_project/submissions/comp424mcgill/final-project-a_new_team/world.py\", line 310, in step\n    raise ValueError(\nValueError: [INVALID:STEP] Not a valid step from [1 8] to [1 8] and put barrier at 0, with max steps = 6\n\nExecute Random Walk!\nAn exception raised. The traceback is as follows:\nTraceback (most recent call last):\n  File \"/home/ml/users/ksinha4/mlp/comp424_final_project/submissions/comp424mcgill/final-project-a_new_team/world.py\", line 310, in step\n    raise ValueError(\nValueError: [INVALID:STEP] Not a valid step from [1 6] to [1 6] and put barrier at 0, with max steps = 6\n\nExecute Random Walk!\nAn exception raised. The traceback is as follows:\nTraceback (most recent call last):\n  File \"/home/ml/users/ksinha4/mlp/comp424_final_project/submissions/comp424mcgill/final-project-a_new_team/world.py\", line 310, in step\n    raise ValueError(\nValueError: [INVALID:STEP] Not a valid step from [3 3] to [3 3] and put barrier at 0, with max steps = 6\n\nExecute Random Walk!\nAn exception raised. The traceback is as follows:\nTraceback (most recent call last):\n  File \"/home/ml/users/ksinha4/mlp/comp424_final_project/submissions/comp424mcgill/final-project-a_new_team/world.py\", line 310, in step\n    raise ValueError(\nValueError: [INVALID:STEP] Not a valid step from [3 4] to [3 4] and put barrier at 0, with max steps = 6\n\nExecute Random Walk!\nAn exception raised. The traceback is as follows:\nTraceback (most recent call last):\n  File \"/home/ml/users/ksinha4/mlp/comp424_final_project/submissions/comp424mcgill/final-project-a_new_team/world.py\", line 310, in step\n    raise ValueError(\nValueError: [INVALID:STEP] Not a valid step from [3 4] to [3 4] and put barrier at 0, with max steps = 6\n\nExecute Random Walk!\nAn exception raised. The traceback is as follows:\nTraceback (most recent call last):\n  File \"/home/ml/users/ksinha4/mlp/comp424_final_project/submissions/comp424mcgill/final-project-a_new_team/world.py\", line 310, in step\n    raise ValueError(\nValueError: [INVALID:STEP] Not a valid step from [4 4] to [4 4] and put barrier at 0, with max steps = 6\n\nExecute Random Walk!\nAn exception raised. The traceback is as follows:\nTraceback (most recent call last):\n  File \"/home/ml/users/ksinha4/mlp/comp424_final_project/submissions/comp424mcgill/final-project-a_new_team/world.py\", line 310, in step\n    raise ValueError(\nValueError: [INVALID:STEP] Not a valid step from [4 4] to [4 4] and put barrier at 0, with max steps = 6\n\nExecute Random Walk!\n"}, {"student_agent_score": 117, "random_agent_score": 1, "student_agent_time": 0.006199836730957031, "random_agent_time": 0.0058553218841552734, "board_size": 11, "swap_players": false, "run_out": "An exception raised. The traceback is as follows:\nTraceback (most recent call last):\n  File \"/home/ml/users/ksinha4/mlp/comp424_final_project/submissions/comp424mcgill/final-project-a_new_team/world.py\", line 310, in step\n    raise ValueError(\nValueError: [INVALID:STEP] Not a valid step from [1 7] to [1 7] and put barrier at 0, with max steps = 6\n\nExecute Random Walk!\nAn exception raised. The traceback is as follows:\nTraceback (most recent call last):\n  File \"/home/ml/users/ksinha4/mlp/comp424_final_project/submissions/comp424mcgill/final-project-a_new_team/world.py\", line 310, in step\n    raise ValueError(\nValueError: [INVALID:STEP] Not a valid step from [1 8] to [1 8] and put barrier at 0, with max steps = 6\n\nExecute Random Walk!\nAn exception raised. The traceback is as follows:\nTraceback (most recent call last):\n  File \"/home/ml/users/ksinha4/mlp/comp424_final_project/submissions/comp424mcgill/final-project-a_new_team/world.py\", line 310, in step\n    raise ValueError(\nValueError: [INVALID:STEP] Not a valid step from [1 6] to [1 6] and put barrier at 0, with max steps = 6\n\nExecute Random Walk!\nAn exception raised. The traceback is as follows:\nTraceback (most recent call last):\n  File \"/home/ml/users/ksinha4/mlp/comp424_final_project/submissions/comp424mcgill/final-project-a_new_team/world.py\", line 310, in step\n    raise ValueError(\nValueError: [INVALID:STEP] Not a valid step from [3 3] to [3 3] and put barrier at 0, with max steps = 6\n\nExecute Random Walk!\nAn exception raised. The traceback is as follows:\nTraceback (most recent call last):\n  File \"/home/ml/users/ksinha4/mlp/comp424_final_project/submissions/comp424mcgill/final-project-a_new_team/world.py\", line 310, in step\n    raise ValueError(\nValueError: [INVALID:STEP] Not a valid step from [3 4] to [3 4] and put barrier at 0, with max steps = 6\n\nExecute Random Walk!\nAn exception raised. The traceback is as follows:\nTraceback (most recent call last):\n  File \"/home/ml/users/ksinha4/mlp/comp424_final_project/submissions/comp424mcgill/final-project-a_new_team/world.py\", line 310, in step\n    raise ValueError(\nValueError: [INVALID:STEP] Not a valid step from [3 4] to [3 4] and put barrier at 0, with max steps = 6\n\nExecute Random Walk!\nAn exception raised. The traceback is as follows:\nTraceback (most recent call last):\n  File \"/home/ml/users/ksinha4/mlp/comp424_final_project/submissions/comp424mcgill/final-project-a_new_team/world.py\", line 310, in step\n    raise ValueError(\nValueError: [INVALID:STEP] Not a valid step from [4 4] to [4 4] and put barrier at 0, with max steps = 6\n\nExecute Random Walk!\nAn exception raised. The traceback is as follows:\nTraceback (most recent call last):\n  File \"/home/ml/users/ksinha4/mlp/comp424_final_project/submissions/comp424mcgill/final-project-a_new_team/world.py\", line 310, in step\n    raise ValueError(\nValueError: [INVALID:STEP] Not a valid step from [4 4] to [4 4] and put barrier at 0, with max steps = 6\n\nExecute Random Walk!\n"}]}