{"num_games": 100, "student_agent_wins": [0, 1, 1, 0, 1, 0, 0, 0, 1, 0, 0, 0, 0, 0, 0, 1, 1, 1, 0, 0, 0, 0, 0, 0, 0, 0, 1, 1, 1, 1, 0, 0, 0, 1, 0, 0, 1, 1, 0, 0, 0, 0, 0, 0, 1, 0, 0, 1, 0, 1, 1, 0, 0, 0, 0, 0, 1, 0, 0, 0, 0, 0, 1, 1, 1, 0, 0, 0, 0, 0, 1, 0, 0, 1, 1, 0, 0, 0, 1, 0, 1, 0, 0, 1, 1, 0, 0, 0, 1, 1, 0, 1, 0, 1, 0, 0, 1, 1, 1, 1], "random_agent_wins": [1, 0, 0, 1, 0, 1, 1, 1, 0, 1, 1, 1, 1, 1, 1, 0, 0, 0, 1, 1, 1, 1, 1, 1, 1, 1, 0, 0, 0, 0, 1, 1, 1, 0, 1, 1, 0, 0, 1, 1, 1, 1, 1, 1, 0, 1, 1, 0, 1, 0, 0, 1, 1, 1, 1, 1, 0, 1, 1, 1, 1, 1, 0, 0, 0, 1, 1, 1, 1, 1, 0, 1, 1, 0, 0, 1, 1, 1, 0, 1, 0, 1, 1, 0, 0, 1, 1, 1, 0, 0, 1, 0, 1, 0, 1, 1, 0, 0, 0, 0], "student_agent_win_count": 37, "random_agent_win_count": 63, "student_agent_win_percentage": 0.37, "random_agent_win_percentage": 0.63, "student_agent_time_taken": 0.004040009975433349, "random_agent_time_taken": 0.0034050202369689943, "run_info": [{"student_agent_score": 1, "random_agent_score": 35, "student_agent_time": 0.0029702186584472656, "random_agent_time": 0.0009002685546875, "board_size": 6, "swap_players": false, "run_out": "An exception raised. The traceback is as follows:\nTraceback (most recent call last):\n  File \"/home/ml/users/ksinha4/mlp/comp424_final_project/submissions/comp424mcgill/final-project-a_new_team/world.py\", line 310, in step\n    raise ValueError(\nValueError: [INVALID:STEP] Not a valid step from [2 2] to [2 2] and put barrier at 0, with max steps = 3\n\nExecute Random Walk!\nAn exception raised. The traceback is as follows:\nTraceback (most recent call last):\n  File \"/home/ml/users/ksinha4/mlp/comp424_final_project/submissions/comp424mcgill/final-project-a_new_team/world.py\", line 310, in step\n    raise ValueError(\nValueError: [INVALID:STEP] Not a valid step from [3 0] to [3 0] and put barrier at 0, with max steps = 3\n\nExecute Random Walk!\n"}, {"student_agent_score": 99, "random_agent_score": 1, "student_agent_time": 0.00030040740966796875, "random_agent_time": 0.0007669925689697266, "board_size": 10, "swap_players": true, "run_out": ""}, {"student_agent_score": 63, "random_agent_score": 1, "student_agent_time": 0.0021762847900390625, "random_agent_time": 0.002478361129760742, "board_size": 8, "swap_players": true, "run_out": "An exception raised. The traceback is as follows:\nTraceback (most recent call last):\n  File \"/home/ml/users/ksinha4/mlp/comp424_final_project/submissions/comp424mcgill/final-project-a_new_team/world.py\", line 310, in step\n    raise ValueError(\nValueError: [INVALID:STEP] Not a valid step from [5 5] to [5 5] and put barrier at 0, with max steps = 4\n\nExecute Random Walk!\nAn exception raised. The traceback is as follows:\nTraceback (most recent call last):\n  File \"/home/ml/users/ksinha4/mlp/comp424_final_project/submissions/comp424mcgill/final-project-a_new_team/world.py\", line 310, in step\n    raise ValueError(\nValueError: [INVALID:STEP] Not a valid step from [5 4] to [5 4] and put barrier at 0, with max steps = 4\n\nExecute Random Walk!\nAn exception raised. The traceback is as follows:\nTraceback (most recent call last):\n  File \"/home/ml/users/ksinha4/mlp/comp424_final_project/submissions/comp424mcgill/final-project-a_new_team/world.py\", line 310, in step\n    raise ValueError(\nValueError: [INVALID:STEP] Not a valid step from [5 4] to [5 4] and put barrier at 0, with max steps = 4\n\nExecute Random Walk!\n"}, {"student_agent_score": 1, "random_agent_score": 48, "student_agent_time": 0.0034079551696777344, "random_agent_time": 0.0023412704467773438, "board_size": 7, "swap_players": false, "run_out": "An exception raised. The traceback is as follows:\nTraceback (most recent call last):\n  File \"/home/ml/users/ksinha4/mlp/comp424_final_project/submissions/comp424mcgill/final-project-a_new_team/world.py\", line 310, in step\n    raise ValueError(\nValueError: [INVALID:STEP] Not a valid step from [4 3] to [4 3] and put barrier at 0, with max steps = 4\n\nExecute Random Walk!\nAn exception raised. The traceback is as follows:\nTraceback (most recent call last):\n  File \"/home/ml/users/ksinha4/mlp/comp424_final_project/submissions/comp424mcgill/final-project-a_new_team/world.py\", line 310, in step\n    raise ValueError(\nValueError: [INVALID:STEP] Not a valid step from [4 2] to [4 2] and put barrier at 0, with max steps = 4\n\nExecute Random Walk!\nAn exception raised. The traceback is as follows:\nTraceback (most recent call last):\n  File \"/home/ml/users/ksinha4/mlp/comp424_final_project/submissions/comp424mcgill/final-project-a_new_team/world.py\", line 310, in step\n    raise ValueError(\nValueError: [INVALID:STEP] Not a valid step from [4 3] to [4 3] and put barrier at 0, with max steps = 4\n\nExecute Random Walk!\nAn exception raised. The traceback is as follows:\nTraceback (most recent call last):\n  File \"/home/ml/users/ksinha4/mlp/comp424_final_project/submissions/comp424mcgill/final-project-a_new_team/world.py\", line 310, in step\n    raise ValueError(\nValueError: [INVALID:STEP] Not a valid step from [5 4] to [5 4] and put barrier at 0, with max steps = 4\n\nExecute Random Walk!\nAn exception raised. The traceback is as follows:\nTraceback (most recent call last):\n  File \"/home/ml/users/ksinha4/mlp/comp424_final_project/submissions/comp424mcgill/final-project-a_new_team/world.py\", line 310, in step\n    raise ValueError(\nValueError: [INVALID:STEP] Not a valid step from [6 3] to [6 3] and put barrier at 0, with max steps = 4\n\nExecute Random Walk!\n"}, {"student_agent_score": 120, "random_agent_score": 1, "student_agent_time": 0.002414703369140625, "random_agent_time": 0.0023040771484375, "board_size": 11, "swap_players": true, "run_out": "An exception raised. The traceback is as follows:\nTraceback (most recent call last):\n  File \"/home/ml/users/ksinha4/mlp/comp424_final_project/submissions/comp424mcgill/final-project-a_new_team/world.py\", line 310, in step\n    raise ValueError(\nValueError: [INVALID:STEP] Not a valid step from [9 3] to [9 3] and put barrier at 0, with max steps = 6\n\nExecute Random Walk!\nAn exception raised. The traceback is as follows:\nTraceback (most recent call last):\n  File \"/home/ml/users/ksinha4/mlp/comp424_final_project/submissions/comp424mcgill/final-project-a_new_team/world.py\", line 310, in step\n    raise ValueError(\nValueError: [INVALID:STEP] Not a valid step from [9 3] to [9 3] and put barrier at 0, with max steps = 6\n\nExecute Random Walk!\n"}, {"student_agent_score": 1, "random_agent_score": 48, "student_agent_time": 0.0040094852447509766, "random_agent_time": 0.0026154518127441406, "board_size": 7, "swap_players": false, "run_out": "An exception raised. The traceback is as follows:\nTraceback (most recent call last):\n  File \"/home/ml/users/ksinha4/mlp/comp424_final_project/submissions/comp424mcgill/final-project-a_new_team/world.py\", line 310, in step\n    raise ValueError(\nValueError: [INVALID:STEP] Not a valid step from [4 3] to [4 3] and put barrier at 0, with max steps = 4\n\nExecute Random Walk!\nAn exception raised. The traceback is as follows:\nTraceback (most recent call last):\n  File \"/home/ml/users/ksinha4/mlp/comp424_final_project/submissions/comp424mcgill/final-project-a_new_team/world.py\", line 310, in step\n    raise ValueError(\nValueError: [INVALID:STEP] Not a valid step from [4 2] to [4 2] and put barrier at 0, with max steps = 4\n\nExecute Random Walk!\nAn exception raised. The traceback is as follows:\nTraceback (most recent call last):\n  File \"/home/ml/users/ksinha4/mlp/comp424_final_project/submissions/comp424mcgill/final-project-a_new_team/world.py\", line 310, in step\n    raise ValueError(\nValueError: [INVALID:STEP] Not a valid step from [4 3] to [4 3] and put barrier at 0, with max steps = 4\n\nExecute Random Walk!\nAn exception raised. The traceback is as follows:\nTraceback (most recent call last):\n  File \"/home/ml/users/ksinha4/mlp/comp424_final_project/submissions/comp424mcgill/final-project-a_new_team/world.py\", line 310, in step\n    raise ValueError(\nValueError: [INVALID:STEP] Not a valid step from [5 4] to [5 4] and put barrier at 0, with max steps = 4\n\nExecute Random Walk!\nAn exception raised. The traceback is as follows:\nTraceback (most recent call last):\n  File \"/home/ml/users/ksinha4/mlp/comp424_final_project/submissions/comp424mcgill/final-project-a_new_team/world.py\", line 310, in step\n    raise ValueError(\nValueError: [INVALID:STEP] Not a valid step from [6 3] to [6 3] and put barrier at 0, with max steps = 4\n\nExecute Random Walk!\n"}, {"student_agent_score": 1, "random_agent_score": 48, "student_agent_time": 0.004691600799560547, "random_agent_time": 0.003469705581665039, "board_size": 7, "swap_players": false, "run_out": "An exception raised. The traceback is as follows:\nTraceback (most recent call last):\n  File \"/home/ml/users/ksinha4/mlp/comp424_final_project/submissions/comp424mcgill/final-project-a_new_team/world.py\", line 310, in step\n    raise ValueError(\nValueError: [INVALID:STEP] Not a valid step from [4 3] to [4 3] and put barrier at 0, with max steps = 4\n\nExecute Random Walk!\nAn exception raised. The traceback is as follows:\nTraceback (most recent call last):\n  File \"/home/ml/users/ksinha4/mlp/comp424_final_project/submissions/comp424mcgill/final-project-a_new_team/world.py\", line 310, in step\n    raise ValueError(\nValueError: [INVALID:STEP] Not a valid step from [4 2] to [4 2] and put barrier at 0, with max steps = 4\n\nExecute Random Walk!\nAn exception raised. The traceback is as follows:\nTraceback (most recent call last):\n  File \"/home/ml/users/ksinha4/mlp/comp424_final_project/submissions/comp424mcgill/final-project-a_new_team/world.py\", line 310, in step\n    raise ValueError(\nValueError: [INVALID:STEP] Not a valid step from [4 3] to [4 3] and put barrier at 0, with max steps = 4\n\nExecute Random Walk!\nAn exception raised. The traceback is as follows:\nTraceback (most recent call last):\n  File \"/home/ml/users/ksinha4/mlp/comp424_final_project/submissions/comp424mcgill/final-project-a_new_team/world.py\", line 310, in step\n    raise ValueError(\nValueError: [INVALID:STEP] Not a valid step from [5 4] to [5 4] and put barrier at 0, with max steps = 4\n\nExecute Random Walk!\nAn exception raised. The traceback is as follows:\nTraceback (most recent call last):\n  File \"/home/ml/users/ksinha4/mlp/comp424_final_project/submissions/comp424mcgill/final-project-a_new_team/world.py\", line 310, in step\n    raise ValueError(\nValueError: [INVALID:STEP] Not a valid step from [6 3] to [6 3] and put barrier at 0, with max steps = 4\n\nExecute Random Walk!\n"}, {"student_agent_score": 1, "random_agent_score": 48, "student_agent_time": 0.003442525863647461, "random_agent_time": 0.0025415420532226562, "board_size": 7, "swap_players": false, "run_out": "An exception raised. The traceback is as follows:\nTraceback (most recent call last):\n  File \"/home/ml/users/ksinha4/mlp/comp424_final_project/submissions/comp424mcgill/final-project-a_new_team/world.py\", line 310, in step\n    raise ValueError(\nValueError: [INVALID:STEP] Not a valid step from [4 3] to [4 3] and put barrier at 0, with max steps = 4\n\nExecute Random Walk!\nAn exception raised. The traceback is as follows:\nTraceback (most recent call last):\n  File \"/home/ml/users/ksinha4/mlp/comp424_final_project/submissions/comp424mcgill/final-project-a_new_team/world.py\", line 310, in step\n    raise ValueError(\nValueError: [INVALID:STEP] Not a valid step from [4 2] to [4 2] and put barrier at 0, with max steps = 4\n\nExecute Random Walk!\nAn exception raised. The traceback is as follows:\nTraceback (most recent call last):\n  File \"/home/ml/users/ksinha4/mlp/comp424_final_project/submissions/comp424mcgill/final-project-a_new_team/world.py\", line 310, in step\n    raise ValueError(\nValueError: [INVALID:STEP] Not a valid step from [4 3] to [4 3] and put barrier at 0, with max steps = 4\n\nExecute Random Walk!\nAn exception raised. The traceback is as follows:\nTraceback (most recent call last):\n  File \"/home/ml/users/ksinha4/mlp/comp424_final_project/submissions/comp424mcgill/final-project-a_new_team/world.py\", line 310, in step\n    raise ValueError(\nValueError: [INVALID:STEP] Not a valid step from [5 4] to [5 4] and put barrier at 0, with max steps = 4\n\nExecute Random Walk!\nAn exception raised. The traceback is as follows:\nTraceback (most recent call last):\n  File \"/home/ml/users/ksinha4/mlp/comp424_final_project/submissions/comp424mcgill/final-project-a_new_team/world.py\", line 310, in step\n    raise ValueError(\nValueError: [INVALID:STEP] Not a valid step from [6 3] to [6 3] and put barrier at 0, with max steps = 4\n\nExecute Random Walk!\n"}, {"student_agent_score": 80, "random_agent_score": 1, "student_agent_time": 0.004815340042114258, "random_agent_time": 0.004851341247558594, "board_size": 9, "swap_players": true, "run_out": "An exception raised. The traceback is as follows:\nTraceback (most recent call last):\n  File \"/home/ml/users/ksinha4/mlp/comp424_final_project/submissions/comp424mcgill/final-project-a_new_team/world.py\", line 310, in step\n    raise ValueError(\nValueError: [INVALID:STEP] Not a valid step from [3 4] to [3 4] and put barrier at 0, with max steps = 5\n\nExecute Random Walk!\nAn exception raised. The traceback is as follows:\nTraceback (most recent call last):\n  File \"/home/ml/users/ksinha4/mlp/comp424_final_project/submissions/comp424mcgill/final-project-a_new_team/world.py\", line 310, in step\n    raise ValueError(\nValueError: [INVALID:STEP] Not a valid step from [3 5] to [3 5] and put barrier at 0, with max steps = 5\n\nExecute Random Walk!\nAn exception raised. The traceback is as follows:\nTraceback (most recent call last):\n  File \"/home/ml/users/ksinha4/mlp/comp424_final_project/submissions/comp424mcgill/final-project-a_new_team/world.py\", line 310, in step\n    raise ValueError(\nValueError: [INVALID:STEP] Not a valid step from [3 4] to [3 4] and put barrier at 0, with max steps = 5\n\nExecute Random Walk!\nAn exception raised. The traceback is as follows:\nTraceback (most recent call last):\n  File \"/home/ml/users/ksinha4/mlp/comp424_final_project/submissions/comp424mcgill/final-project-a_new_team/world.py\", line 310, in step\n    raise ValueError(\nValueError: [INVALID:STEP] Not a valid step from [5 4] to [5 4] and put barrier at 0, with max steps = 5\n\nExecute Random Walk!\nAn exception raised. The traceback is as follows:\nTraceback (most recent call last):\n  File \"/home/ml/users/ksinha4/mlp/comp424_final_project/submissions/comp424mcgill/final-project-a_new_team/world.py\", line 310, in step\n    raise ValueError(\nValueError: [INVALID:STEP] Not a valid step from [5 5] to [5 5] and put barrier at 0, with max steps = 5\n\nExecute Random Walk!\n"}, {"student_agent_score": 2, "random_agent_score": 98, "student_agent_time": 0.005764961242675781, "random_agent_time": 0.006346464157104492, "board_size": 10, "swap_players": false, "run_out": "An exception raised. The traceback is as follows:\nTraceback (most recent call last):\n  File \"/home/ml/users/ksinha4/mlp/comp424_final_project/submissions/comp424mcgill/final-project-a_new_team/world.py\", line 310, in step\n    raise ValueError(\nValueError: [INVALID:STEP] Not a valid step from [7 5] to [7 5] and put barrier at 0, with max steps = 5\n\nExecute Random Walk!\nAn exception raised. The traceback is as follows:\nTraceback (most recent call last):\n  File \"/home/ml/users/ksinha4/mlp/comp424_final_project/submissions/comp424mcgill/final-project-a_new_team/world.py\", line 310, in step\n    raise ValueError(\nValueError: [INVALID:STEP] Not a valid step from [6 6] to [6 6] and put barrier at 0, with max steps = 5\n\nExecute Random Walk!\nAn exception raised. The traceback is as follows:\nTraceback (most recent call last):\n  File \"/home/ml/users/ksinha4/mlp/comp424_final_project/submissions/comp424mcgill/final-project-a_new_team/world.py\", line 310, in step\n    raise ValueError(\nValueError: [INVALID:STEP] Not a valid step from [7 8] to [7 8] and put barrier at 0, with max steps = 5\n\nExecute Random Walk!\nAn exception raised. The traceback is as follows:\nTraceback (most recent call last):\n  File \"/home/ml/users/ksinha4/mlp/comp424_final_project/submissions/comp424mcgill/final-project-a_new_team/world.py\", line 310, in step\n    raise ValueError(\nValueError: [INVALID:STEP] Not a valid step from [7 8] to [7 8] and put barrier at 0, with max steps = 5\n\nExecute Random Walk!\n"}, {"student_agent_score": 1, "random_agent_score": 48, "student_agent_time": 0.0038666725158691406, "random_agent_time": 0.0027723312377929688, "board_size": 7, "swap_players": true, "run_out": "An exception raised. The traceback is as follows:\nTraceback (most recent call last):\n  File \"/home/ml/users/ksinha4/mlp/comp424_final_project/submissions/comp424mcgill/final-project-a_new_team/world.py\", line 310, in step\n    raise ValueError(\nValueError: [INVALID:STEP] Not a valid step from [2 3] to [2 3] and put barrier at 0, with max steps = 4\n\nExecute Random Walk!\nAn exception raised. The traceback is as follows:\nTraceback (most recent call last):\n  File \"/home/ml/users/ksinha4/mlp/comp424_final_project/submissions/comp424mcgill/final-project-a_new_team/world.py\", line 310, in step\n    raise ValueError(\nValueError: [INVALID:STEP] Not a valid step from [5 4] to [5 4] and put barrier at 0, with max steps = 4\n\nExecute Random Walk!\nAn exception raised. The traceback is as follows:\nTraceback (most recent call last):\n  File \"/home/ml/users/ksinha4/mlp/comp424_final_project/submissions/comp424mcgill/final-project-a_new_team/world.py\", line 310, in step\n    raise ValueError(\nValueError: [INVALID:STEP] Not a valid step from [6 3] to [6 3] and put barrier at 0, with max steps = 4\n\nExecute Random Walk!\n"}, {"student_agent_score": 1, "random_agent_score": 48, "student_agent_time": 0.004561424255371094, "random_agent_time": 0.003281116485595703, "board_size": 7, "swap_players": false, "run_out": "An exception raised. The traceback is as follows:\nTraceback (most recent call last):\n  File \"/home/ml/users/ksinha4/mlp/comp424_final_project/submissions/comp424mcgill/final-project-a_new_team/world.py\", line 310, in step\n    raise ValueError(\nValueError: [INVALID:STEP] Not a valid step from [4 3] to [4 3] and put barrier at 0, with max steps = 4\n\nExecute Random Walk!\nAn exception raised. The traceback is as follows:\nTraceback (most recent call last):\n  File \"/home/ml/users/ksinha4/mlp/comp424_final_project/submissions/comp424mcgill/final-project-a_new_team/world.py\", line 310, in step\n    raise ValueError(\nValueError: [INVALID:STEP] Not a valid step from [4 2] to [4 2] and put barrier at 0, with max steps = 4\n\nExecute Random Walk!\nAn exception raised. The traceback is as follows:\nTraceback (most recent call last):\n  File \"/home/ml/users/ksinha4/mlp/comp424_final_project/submissions/comp424mcgill/final-project-a_new_team/world.py\", line 310, in step\n    raise ValueError(\nValueError: [INVALID:STEP] Not a valid step from [4 3] to [4 3] and put barrier at 0, with max steps = 4\n\nExecute Random Walk!\nAn exception raised. The traceback is as follows:\nTraceback (most recent call last):\n  File \"/home/ml/users/ksinha4/mlp/comp424_final_project/submissions/comp424mcgill/final-project-a_new_team/world.py\", line 310, in step\n    raise ValueError(\nValueError: [INVALID:STEP] Not a valid step from [5 4] to [5 4] and put barrier at 0, with max steps = 4\n\nExecute Random Walk!\nAn exception raised. The traceback is as follows:\nTraceback (most recent call last):\n  File \"/home/ml/users/ksinha4/mlp/comp424_final_project/submissions/comp424mcgill/final-project-a_new_team/world.py\", line 310, in step\n    raise ValueError(\nValueError: [INVALID:STEP] Not a valid step from [6 3] to [6 3] and put barrier at 0, with max steps = 4\n\nExecute Random Walk!\n"}, {"student_agent_score": 1, "random_agent_score": 63, "student_agent_time": 0.005311489105224609, "random_agent_time": 0.0022194385528564453, "board_size": 8, "swap_players": false, "run_out": "An exception raised. The traceback is as follows:\nTraceback (most recent call last):\n  File \"/home/ml/users/ksinha4/mlp/comp424_final_project/submissions/comp424mcgill/final-project-a_new_team/world.py\", line 310, in step\n    raise ValueError(\nValueError: [INVALID:STEP] Not a valid step from [2 2] to [2 2] and put barrier at 0, with max steps = 4\n\nExecute Random Walk!\nAn exception raised. The traceback is as follows:\nTraceback (most recent call last):\n  File \"/home/ml/users/ksinha4/mlp/comp424_final_project/submissions/comp424mcgill/final-project-a_new_team/world.py\", line 310, in step\n    raise ValueError(\nValueError: [INVALID:STEP] Not a valid step from [3 1] to [3 1] and put barrier at 0, with max steps = 4\n\nExecute Random Walk!\nAn exception raised. The traceback is as follows:\nTraceback (most recent call last):\n  File \"/home/ml/users/ksinha4/mlp/comp424_final_project/submissions/comp424mcgill/final-project-a_new_team/world.py\", line 310, in step\n    raise ValueError(\nValueError: [INVALID:STEP] Not a valid step from [3 0] to [3 0] and put barrier at 0, with max steps = 4\n\nExecute Random Walk!\nAn exception raised. The traceback is as follows:\nTraceback (most recent call last):\n  File \"/home/ml/users/ksinha4/mlp/comp424_final_project/submissions/comp424mcgill/final-project-a_new_team/world.py\", line 310, in step\n    raise ValueError(\nValueError: [INVALID:STEP] Not a valid step from [6 1] to [6 1] and put barrier at 0, with max steps = 4\n\nExecute Random Walk!\n"}, {"student_agent_score": 1, "random_agent_score": 48, "student_agent_time": 0.002269744873046875, "random_agent_time": 0.002799510955810547, "board_size": 7, "swap_players": true, "run_out": "An exception raised. The traceback is as follows:\nTraceback (most recent call last):\n  File \"/home/ml/users/ksinha4/mlp/comp424_final_project/submissions/comp424mcgill/final-project-a_new_team/world.py\", line 310, in step\n    raise ValueError(\nValueError: [INVALID:STEP] Not a valid step from [2 3] to [2 3] and put barrier at 0, with max steps = 4\n\nExecute Random Walk!\nAn exception raised. The traceback is as follows:\nTraceback (most recent call last):\n  File \"/home/ml/users/ksinha4/mlp/comp424_final_project/submissions/comp424mcgill/final-project-a_new_team/world.py\", line 310, in step\n    raise ValueError(\nValueError: [INVALID:STEP] Not a valid step from [5 4] to [5 4] and put barrier at 0, with max steps = 4\n\nExecute Random Walk!\nAn exception raised. The traceback is as follows:\nTraceback (most recent call last):\n  File \"/home/ml/users/ksinha4/mlp/comp424_final_project/submissions/comp424mcgill/final-project-a_new_team/world.py\", line 310, in step\n    raise ValueError(\nValueError: [INVALID:STEP] Not a valid step from [6 3] to [6 3] and put barrier at 0, with max steps = 4\n\nExecute Random Walk!\n"}, {"student_agent_score": 1, "random_agent_score": 48, "student_agent_time": 0.003445148468017578, "random_agent_time": 0.002942800521850586, "board_size": 7, "swap_players": true, "run_out": "An exception raised. The traceback is as follows:\nTraceback (most recent call last):\n  File \"/home/ml/users/ksinha4/mlp/comp424_final_project/submissions/comp424mcgill/final-project-a_new_team/world.py\", line 310, in step\n    raise ValueError(\nValueError: [INVALID:STEP] Not a valid step from [2 3] to [2 3] and put barrier at 0, with max steps = 4\n\nExecute Random Walk!\nAn exception raised. The traceback is as follows:\nTraceback (most recent call last):\n  File \"/home/ml/users/ksinha4/mlp/comp424_final_project/submissions/comp424mcgill/final-project-a_new_team/world.py\", line 310, in step\n    raise ValueError(\nValueError: [INVALID:STEP] Not a valid step from [5 4] to [5 4] and put barrier at 0, with max steps = 4\n\nExecute Random Walk!\nAn exception raised. The traceback is as follows:\nTraceback (most recent call last):\n  File \"/home/ml/users/ksinha4/mlp/comp424_final_project/submissions/comp424mcgill/final-project-a_new_team/world.py\", line 310, in step\n    raise ValueError(\nValueError: [INVALID:STEP] Not a valid step from [6 3] to [6 3] and put barrier at 0, with max steps = 4\n\nExecute Random Walk!\n"}, {"student_agent_score": 99, "random_agent_score": 1, "student_agent_time": 0.0003104209899902344, "random_agent_time": 0.0008943080902099609, "board_size": 10, "swap_players": true, "run_out": ""}, {"student_agent_score": 80, "random_agent_score": 1, "student_agent_time": 0.005341291427612305, "random_agent_time": 0.007403850555419922, "board_size": 9, "swap_players": true, "run_out": "An exception raised. The traceback is as follows:\nTraceback (most recent call last):\n  File \"/home/ml/users/ksinha4/mlp/comp424_final_project/submissions/comp424mcgill/final-project-a_new_team/world.py\", line 310, in step\n    raise ValueError(\nValueError: [INVALID:STEP] Not a valid step from [3 4] to [3 4] and put barrier at 0, with max steps = 5\n\nExecute Random Walk!\nAn exception raised. The traceback is as follows:\nTraceback (most recent call last):\n  File \"/home/ml/users/ksinha4/mlp/comp424_final_project/submissions/comp424mcgill/final-project-a_new_team/world.py\", line 310, in step\n    raise ValueError(\nValueError: [INVALID:STEP] Not a valid step from [3 5] to [3 5] and put barrier at 0, with max steps = 5\n\nExecute Random Walk!\nAn exception raised. The traceback is as follows:\nTraceback (most recent call last):\n  File \"/home/ml/users/ksinha4/mlp/comp424_final_project/submissions/comp424mcgill/final-project-a_new_team/world.py\", line 310, in step\n    raise ValueError(\nValueError: [INVALID:STEP] Not a valid step from [3 4] to [3 4] and put barrier at 0, with max steps = 5\n\nExecute Random Walk!\nAn exception raised. The traceback is as follows:\nTraceback (most recent call last):\n  File \"/home/ml/users/ksinha4/mlp/comp424_final_project/submissions/comp424mcgill/final-project-a_new_team/world.py\", line 310, in step\n    raise ValueError(\nValueError: [INVALID:STEP] Not a valid step from [5 4] to [5 4] and put barrier at 0, with max steps = 5\n\nExecute Random Walk!\nAn exception raised. The traceback is as follows:\nTraceback (most recent call last):\n  File \"/home/ml/users/ksinha4/mlp/comp424_final_project/submissions/comp424mcgill/final-project-a_new_team/world.py\", line 310, in step\n    raise ValueError(\nValueError: [INVALID:STEP] Not a valid step from [5 5] to [5 5] and put barrier at 0, with max steps = 5\n\nExecute Random Walk!\n"}, {"student_agent_score": 120, "random_agent_score": 1, "student_agent_time": 0.003599882125854492, "random_agent_time": 0.0029754638671875, "board_size": 11, "swap_players": true, "run_out": "An exception raised. The traceback is as follows:\nTraceback (most recent call last):\n  File \"/home/ml/users/ksinha4/mlp/comp424_final_project/submissions/comp424mcgill/final-project-a_new_team/world.py\", line 310, in step\n    raise ValueError(\nValueError: [INVALID:STEP] Not a valid step from [9 3] to [9 3] and put barrier at 0, with max steps = 6\n\nExecute Random Walk!\nAn exception raised. The traceback is as follows:\nTraceback (most recent call last):\n  File \"/home/ml/users/ksinha4/mlp/comp424_final_project/submissions/comp424mcgill/final-project-a_new_team/world.py\", line 310, in step\n    raise ValueError(\nValueError: [INVALID:STEP] Not a valid step from [9 3] to [9 3] and put barrier at 0, with max steps = 6\n\nExecute Random Walk!\n"}, {"student_agent_score": 2, "random_agent_score": 98, "student_agent_time": 0.00534510612487793, "random_agent_time": 0.00758051872253418, "board_size": 10, "swap_players": false, "run_out": "An exception raised. The traceback is as follows:\nTraceback (most recent call last):\n  File \"/home/ml/users/ksinha4/mlp/comp424_final_project/submissions/comp424mcgill/final-project-a_new_team/world.py\", line 310, in step\n    raise ValueError(\nValueError: [INVALID:STEP] Not a valid step from [7 5] to [7 5] and put barrier at 0, with max steps = 5\n\nExecute Random Walk!\nAn exception raised. The traceback is as follows:\nTraceback (most recent call last):\n  File \"/home/ml/users/ksinha4/mlp/comp424_final_project/submissions/comp424mcgill/final-project-a_new_team/world.py\", line 310, in step\n    raise ValueError(\nValueError: [INVALID:STEP] Not a valid step from [6 6] to [6 6] and put barrier at 0, with max steps = 5\n\nExecute Random Walk!\nAn exception raised. The traceback is as follows:\nTraceback (most recent call last):\n  File \"/home/ml/users/ksinha4/mlp/comp424_final_project/submissions/comp424mcgill/final-project-a_new_team/world.py\", line 310, in step\n    raise ValueError(\nValueError: [INVALID:STEP] Not a valid step from [7 8] to [7 8] and put barrier at 0, with max steps = 5\n\nExecute Random Walk!\nAn exception raised. The traceback is as follows:\nTraceback (most recent call last):\n  File \"/home/ml/users/ksinha4/mlp/comp424_final_project/submissions/comp424mcgill/final-project-a_new_team/world.py\", line 310, in step\n    raise ValueError(\nValueError: [INVALID:STEP] Not a valid step from [7 8] to [7 8] and put barrier at 0, with max steps = 5\n\nExecute Random Walk!\n"}, {"student_agent_score": 1, "random_agent_score": 48, "student_agent_time": 0.004070758819580078, "random_agent_time": 0.0034439563751220703, "board_size": 7, "swap_players": false, "run_out": "An exception raised. The traceback is as follows:\nTraceback (most recent call last):\n  File \"/home/ml/users/ksinha4/mlp/comp424_final_project/submissions/comp424mcgill/final-project-a_new_team/world.py\", line 310, in step\n    raise ValueError(\nValueError: [INVALID:STEP] Not a valid step from [4 3] to [4 3] and put barrier at 0, with max steps = 4\n\nExecute Random Walk!\nAn exception raised. The traceback is as follows:\nTraceback (most recent call last):\n  File \"/home/ml/users/ksinha4/mlp/comp424_final_project/submissions/comp424mcgill/final-project-a_new_team/world.py\", line 310, in step\n    raise ValueError(\nValueError: [INVALID:STEP] Not a valid step from [4 2] to [4 2] and put barrier at 0, with max steps = 4\n\nExecute Random Walk!\nAn exception raised. The traceback is as follows:\nTraceback (most recent call last):\n  File \"/home/ml/users/ksinha4/mlp/comp424_final_project/submissions/comp424mcgill/final-project-a_new_team/world.py\", line 310, in step\n    raise ValueError(\nValueError: [INVALID:STEP] Not a valid step from [4 3] to [4 3] and put barrier at 0, with max steps = 4\n\nExecute Random Walk!\nAn exception raised. The traceback is as follows:\nTraceback (most recent call last):\n  File \"/home/ml/users/ksinha4/mlp/comp424_final_project/submissions/comp424mcgill/final-project-a_new_team/world.py\", line 310, in step\n    raise ValueError(\nValueError: [INVALID:STEP] Not a valid step from [5 4] to [5 4] and put barrier at 0, with max steps = 4\n\nExecute Random Walk!\nAn exception raised. The traceback is as follows:\nTraceback (most recent call last):\n  File \"/home/ml/users/ksinha4/mlp/comp424_final_project/submissions/comp424mcgill/final-project-a_new_team/world.py\", line 310, in step\n    raise ValueError(\nValueError: [INVALID:STEP] Not a valid step from [6 3] to [6 3] and put barrier at 0, with max steps = 4\n\nExecute Random Walk!\n"}, {"student_agent_score": 1, "random_agent_score": 48, "student_agent_time": 0.004364967346191406, "random_agent_time": 0.0039708614349365234, "board_size": 7, "swap_players": false, "run_out": "An exception raised. The traceback is as follows:\nTraceback (most recent call last):\n  File \"/home/ml/users/ksinha4/mlp/comp424_final_project/submissions/comp424mcgill/final-project-a_new_team/world.py\", line 310, in step\n    raise ValueError(\nValueError: [INVALID:STEP] Not a valid step from [4 3] to [4 3] and put barrier at 0, with max steps = 4\n\nExecute Random Walk!\nAn exception raised. The traceback is as follows:\nTraceback (most recent call last):\n  File \"/home/ml/users/ksinha4/mlp/comp424_final_project/submissions/comp424mcgill/final-project-a_new_team/world.py\", line 310, in step\n    raise ValueError(\nValueError: [INVALID:STEP] Not a valid step from [4 2] to [4 2] and put barrier at 0, with max steps = 4\n\nExecute Random Walk!\nAn exception raised. The traceback is as follows:\nTraceback (most recent call last):\n  File \"/home/ml/users/ksinha4/mlp/comp424_final_project/submissions/comp424mcgill/final-project-a_new_team/world.py\", line 310, in step\n    raise ValueError(\nValueError: [INVALID:STEP] Not a valid step from [4 3] to [4 3] and put barrier at 0, with max steps = 4\n\nExecute Random Walk!\nAn exception raised. The traceback is as follows:\nTraceback (most recent call last):\n  File \"/home/ml/users/ksinha4/mlp/comp424_final_project/submissions/comp424mcgill/final-project-a_new_team/world.py\", line 310, in step\n    raise ValueError(\nValueError: [INVALID:STEP] Not a valid step from [5 4] to [5 4] and put barrier at 0, with max steps = 4\n\nExecute Random Walk!\nAn exception raised. The traceback is as follows:\nTraceback (most recent call last):\n  File \"/home/ml/users/ksinha4/mlp/comp424_final_project/submissions/comp424mcgill/final-project-a_new_team/world.py\", line 310, in step\n    raise ValueError(\nValueError: [INVALID:STEP] Not a valid step from [6 3] to [6 3] and put barrier at 0, with max steps = 4\n\nExecute Random Walk!\n"}, {"student_agent_score": 1, "random_agent_score": 48, "student_agent_time": 0.002532482147216797, "random_agent_time": 0.0022656917572021484, "board_size": 7, "swap_players": true, "run_out": "An exception raised. The traceback is as follows:\nTraceback (most recent call last):\n  File \"/home/ml/users/ksinha4/mlp/comp424_final_project/submissions/comp424mcgill/final-project-a_new_team/world.py\", line 310, in step\n    raise ValueError(\nValueError: [INVALID:STEP] Not a valid step from [2 3] to [2 3] and put barrier at 0, with max steps = 4\n\nExecute Random Walk!\nAn exception raised. The traceback is as follows:\nTraceback (most recent call last):\n  File \"/home/ml/users/ksinha4/mlp/comp424_final_project/submissions/comp424mcgill/final-project-a_new_team/world.py\", line 310, in step\n    raise ValueError(\nValueError: [INVALID:STEP] Not a valid step from [5 4] to [5 4] and put barrier at 0, with max steps = 4\n\nExecute Random Walk!\nAn exception raised. The traceback is as follows:\nTraceback (most recent call last):\n  File \"/home/ml/users/ksinha4/mlp/comp424_final_project/submissions/comp424mcgill/final-project-a_new_team/world.py\", line 310, in step\n    raise ValueError(\nValueError: [INVALID:STEP] Not a valid step from [6 3] to [6 3] and put barrier at 0, with max steps = 4\n\nExecute Random Walk!\n"}, {"student_agent_score": 2, "random_agent_score": 79, "student_agent_time": 0.003469228744506836, "random_agent_time": 0.0018262863159179688, "board_size": 9, "swap_players": false, "run_out": "An exception raised. The traceback is as follows:\nTraceback (most recent call last):\n  File \"/home/ml/users/ksinha4/mlp/comp424_final_project/submissions/comp424mcgill/final-project-a_new_team/world.py\", line 310, in step\n    raise ValueError(\nValueError: [INVALID:STEP] Not a valid step from [5 4] to [5 4] and put barrier at 0, with max steps = 5\n\nExecute Random Walk!\nAn exception raised. The traceback is as follows:\nTraceback (most recent call last):\n  File \"/home/ml/users/ksinha4/mlp/comp424_final_project/submissions/comp424mcgill/final-project-a_new_team/world.py\", line 310, in step\n    raise ValueError(\nValueError: [INVALID:STEP] Not a valid step from [5 3] to [5 3] and put barrier at 0, with max steps = 5\n\nExecute Random Walk!\n"}, {"student_agent_score": 1, "random_agent_score": 48, "student_agent_time": 0.0037386417388916016, "random_agent_time": 0.0026988983154296875, "board_size": 7, "swap_players": true, "run_out": "An exception raised. The traceback is as follows:\nTraceback (most recent call last):\n  File \"/home/ml/users/ksinha4/mlp/comp424_final_project/submissions/comp424mcgill/final-project-a_new_team/world.py\", line 310, in step\n    raise ValueError(\nValueError: [INVALID:STEP] Not a valid step from [2 3] to [2 3] and put barrier at 0, with max steps = 4\n\nExecute Random Walk!\nAn exception raised. The traceback is as follows:\nTraceback (most recent call last):\n  File \"/home/ml/users/ksinha4/mlp/comp424_final_project/submissions/comp424mcgill/final-project-a_new_team/world.py\", line 310, in step\n    raise ValueError(\nValueError: [INVALID:STEP] Not a valid step from [5 4] to [5 4] and put barrier at 0, with max steps = 4\n\nExecute Random Walk!\nAn exception raised. The traceback is as follows:\nTraceback (most recent call last):\n  File \"/home/ml/users/ksinha4/mlp/comp424_final_project/submissions/comp424mcgill/final-project-a_new_team/world.py\", line 310, in step\n    raise ValueError(\nValueError: [INVALID:STEP] Not a valid step from [6 3] to [6 3] and put barrier at 0, with max steps = 4\n\nExecute Random Walk!\n"}, {"student_agent_score": 1, "random_agent_score": 63, "student_agent_time": 0.004743337631225586, "random_agent_time": 0.002210855484008789, "board_size": 8, "swap_players": false, "run_out": "An exception raised. The traceback is as follows:\nTraceback (most recent call last):\n  File \"/home/ml/users/ksinha4/mlp/comp424_final_project/submissions/comp424mcgill/final-project-a_new_team/world.py\", line 310, in step\n    raise ValueError(\nValueError: [INVALID:STEP] Not a valid step from [2 2] to [2 2] and put barrier at 0, with max steps = 4\n\nExecute Random Walk!\nAn exception raised. The traceback is as follows:\nTraceback (most recent call last):\n  File \"/home/ml/users/ksinha4/mlp/comp424_final_project/submissions/comp424mcgill/final-project-a_new_team/world.py\", line 310, in step\n    raise ValueError(\nValueError: [INVALID:STEP] Not a valid step from [3 1] to [3 1] and put barrier at 0, with max steps = 4\n\nExecute Random Walk!\nAn exception raised. The traceback is as follows:\nTraceback (most recent call last):\n  File \"/home/ml/users/ksinha4/mlp/comp424_final_project/submissions/comp424mcgill/final-project-a_new_team/world.py\", line 310, in step\n    raise ValueError(\nValueError: [INVALID:STEP] Not a valid step from [3 0] to [3 0] and put barrier at 0, with max steps = 4\n\nExecute Random Walk!\nAn exception raised. The traceback is as follows:\nTraceback (most recent call last):\n  File \"/home/ml/users/ksinha4/mlp/comp424_final_project/submissions/comp424mcgill/final-project-a_new_team/world.py\", line 310, in step\n    raise ValueError(\nValueError: [INVALID:STEP] Not a valid step from [6 1] to [6 1] and put barrier at 0, with max steps = 4\n\nExecute Random Walk!\n"}, {"student_agent_score": 1, "random_agent_score": 48, "student_agent_time": 0.00391697883605957, "random_agent_time": 0.0018763542175292969, "board_size": 7, "swap_players": true, "run_out": "An exception raised. The traceback is as follows:\nTraceback (most recent call last):\n  File \"/home/ml/users/ksinha4/mlp/comp424_final_project/submissions/comp424mcgill/final-project-a_new_team/world.py\", line 310, in step\n    raise ValueError(\nValueError: [INVALID:STEP] Not a valid step from [2 3] to [2 3] and put barrier at 0, with max steps = 4\n\nExecute Random Walk!\nAn exception raised. The traceback is as follows:\nTraceback (most recent call last):\n  File \"/home/ml/users/ksinha4/mlp/comp424_final_project/submissions/comp424mcgill/final-project-a_new_team/world.py\", line 310, in step\n    raise ValueError(\nValueError: [INVALID:STEP] Not a valid step from [5 4] to [5 4] and put barrier at 0, with max steps = 4\n\nExecute Random Walk!\nAn exception raised. The traceback is as follows:\nTraceback (most recent call last):\n  File \"/home/ml/users/ksinha4/mlp/comp424_final_project/submissions/comp424mcgill/final-project-a_new_team/world.py\", line 310, in step\n    raise ValueError(\nValueError: [INVALID:STEP] Not a valid step from [6 3] to [6 3] and put barrier at 0, with max steps = 4\n\nExecute Random Walk!\n"}, {"student_agent_score": 99, "random_agent_score": 1, "student_agent_time": 0.0003514289855957031, "random_agent_time": 0.0008807182312011719, "board_size": 10, "swap_players": true, "run_out": ""}, {"student_agent_score": 80, "random_agent_score": 1, "student_agent_time": 0.008025169372558594, "random_agent_time": 0.005252838134765625, "board_size": 9, "swap_players": true, "run_out": "An exception raised. The traceback is as follows:\nTraceback (most recent call last):\n  File \"/home/ml/users/ksinha4/mlp/comp424_final_project/submissions/comp424mcgill/final-project-a_new_team/world.py\", line 310, in step\n    raise ValueError(\nValueError: [INVALID:STEP] Not a valid step from [3 4] to [3 4] and put barrier at 0, with max steps = 5\n\nExecute Random Walk!\nAn exception raised. The traceback is as follows:\nTraceback (most recent call last):\n  File \"/home/ml/users/ksinha4/mlp/comp424_final_project/submissions/comp424mcgill/final-project-a_new_team/world.py\", line 310, in step\n    raise ValueError(\nValueError: [INVALID:STEP] Not a valid step from [3 5] to [3 5] and put barrier at 0, with max steps = 5\n\nExecute Random Walk!\nAn exception raised. The traceback is as follows:\nTraceback (most recent call last):\n  File \"/home/ml/users/ksinha4/mlp/comp424_final_project/submissions/comp424mcgill/final-project-a_new_team/world.py\", line 310, in step\n    raise ValueError(\nValueError: [INVALID:STEP] Not a valid step from [3 4] to [3 4] and put barrier at 0, with max steps = 5\n\nExecute Random Walk!\nAn exception raised. The traceback is as follows:\nTraceback (most recent call last):\n  File \"/home/ml/users/ksinha4/mlp/comp424_final_project/submissions/comp424mcgill/final-project-a_new_team/world.py\", line 310, in step\n    raise ValueError(\nValueError: [INVALID:STEP] Not a valid step from [5 4] to [5 4] and put barrier at 0, with max steps = 5\n\nExecute Random Walk!\nAn exception raised. The traceback is as follows:\nTraceback (most recent call last):\n  File \"/home/ml/users/ksinha4/mlp/comp424_final_project/submissions/comp424mcgill/final-project-a_new_team/world.py\", line 310, in step\n    raise ValueError(\nValueError: [INVALID:STEP] Not a valid step from [5 5] to [5 5] and put barrier at 0, with max steps = 5\n\nExecute Random Walk!\n"}, {"student_agent_score": 80, "random_agent_score": 1, "student_agent_time": 0.005517721176147461, "random_agent_time": 0.005906581878662109, "board_size": 9, "swap_players": true, "run_out": "An exception raised. The traceback is as follows:\nTraceback (most recent call last):\n  File \"/home/ml/users/ksinha4/mlp/comp424_final_project/submissions/comp424mcgill/final-project-a_new_team/world.py\", line 310, in step\n    raise ValueError(\nValueError: [INVALID:STEP] Not a valid step from [3 4] to [3 4] and put barrier at 0, with max steps = 5\n\nExecute Random Walk!\nAn exception raised. The traceback is as follows:\nTraceback (most recent call last):\n  File \"/home/ml/users/ksinha4/mlp/comp424_final_project/submissions/comp424mcgill/final-project-a_new_team/world.py\", line 310, in step\n    raise ValueError(\nValueError: [INVALID:STEP] Not a valid step from [3 5] to [3 5] and put barrier at 0, with max steps = 5\n\nExecute Random Walk!\nAn exception raised. The traceback is as follows:\nTraceback (most recent call last):\n  File \"/home/ml/users/ksinha4/mlp/comp424_final_project/submissions/comp424mcgill/final-project-a_new_team/world.py\", line 310, in step\n    raise ValueError(\nValueError: [INVALID:STEP] Not a valid step from [3 4] to [3 4] and put barrier at 0, with max steps = 5\n\nExecute Random Walk!\nAn exception raised. The traceback is as follows:\nTraceback (most recent call last):\n  File \"/home/ml/users/ksinha4/mlp/comp424_final_project/submissions/comp424mcgill/final-project-a_new_team/world.py\", line 310, in step\n    raise ValueError(\nValueError: [INVALID:STEP] Not a valid step from [5 4] to [5 4] and put barrier at 0, with max steps = 5\n\nExecute Random Walk!\nAn exception raised. The traceback is as follows:\nTraceback (most recent call last):\n  File \"/home/ml/users/ksinha4/mlp/comp424_final_project/submissions/comp424mcgill/final-project-a_new_team/world.py\", line 310, in step\n    raise ValueError(\nValueError: [INVALID:STEP] Not a valid step from [5 5] to [5 5] and put barrier at 0, with max steps = 5\n\nExecute Random Walk!\n"}, {"student_agent_score": 99, "random_agent_score": 1, "student_agent_time": 0.00034928321838378906, "random_agent_time": 0.0010178089141845703, "board_size": 10, "swap_players": true, "run_out": ""}, {"student_agent_score": 1, "random_agent_score": 48, "student_agent_time": 0.0064182281494140625, "random_agent_time": 0.0023708343505859375, "board_size": 7, "swap_players": false, "run_out": "An exception raised. The traceback is as follows:\nTraceback (most recent call last):\n  File \"/home/ml/users/ksinha4/mlp/comp424_final_project/submissions/comp424mcgill/final-project-a_new_team/world.py\", line 310, in step\n    raise ValueError(\nValueError: [INVALID:STEP] Not a valid step from [4 3] to [4 3] and put barrier at 0, with max steps = 4\n\nExecute Random Walk!\nAn exception raised. The traceback is as follows:\nTraceback (most recent call last):\n  File \"/home/ml/users/ksinha4/mlp/comp424_final_project/submissions/comp424mcgill/final-project-a_new_team/world.py\", line 310, in step\n    raise ValueError(\nValueError: [INVALID:STEP] Not a valid step from [4 2] to [4 2] and put barrier at 0, with max steps = 4\n\nExecute Random Walk!\nAn exception raised. The traceback is as follows:\nTraceback (most recent call last):\n  File \"/home/ml/users/ksinha4/mlp/comp424_final_project/submissions/comp424mcgill/final-project-a_new_team/world.py\", line 310, in step\n    raise ValueError(\nValueError: [INVALID:STEP] Not a valid step from [4 3] to [4 3] and put barrier at 0, with max steps = 4\n\nExecute Random Walk!\nAn exception raised. The traceback is as follows:\nTraceback (most recent call last):\n  File \"/home/ml/users/ksinha4/mlp/comp424_final_project/submissions/comp424mcgill/final-project-a_new_team/world.py\", line 310, in step\n    raise ValueError(\nValueError: [INVALID:STEP] Not a valid step from [5 4] to [5 4] and put barrier at 0, with max steps = 4\n\nExecute Random Walk!\nAn exception raised. The traceback is as follows:\nTraceback (most recent call last):\n  File \"/home/ml/users/ksinha4/mlp/comp424_final_project/submissions/comp424mcgill/final-project-a_new_team/world.py\", line 310, in step\n    raise ValueError(\nValueError: [INVALID:STEP] Not a valid step from [6 3] to [6 3] and put barrier at 0, with max steps = 4\n\nExecute Random Walk!\n"}, {"student_agent_score": 1, "random_agent_score": 48, "student_agent_time": 0.004660844802856445, "random_agent_time": 0.0019180774688720703, "board_size": 7, "swap_players": false, "run_out": "An exception raised. The traceback is as follows:\nTraceback (most recent call last):\n  File \"/home/ml/users/ksinha4/mlp/comp424_final_project/submissions/comp424mcgill/final-project-a_new_team/world.py\", line 310, in step\n    raise ValueError(\nValueError: [INVALID:STEP] Not a valid step from [4 3] to [4 3] and put barrier at 0, with max steps = 4\n\nExecute Random Walk!\nAn exception raised. The traceback is as follows:\nTraceback (most recent call last):\n  File \"/home/ml/users/ksinha4/mlp/comp424_final_project/submissions/comp424mcgill/final-project-a_new_team/world.py\", line 310, in step\n    raise ValueError(\nValueError: [INVALID:STEP] Not a valid step from [4 2] to [4 2] and put barrier at 0, with max steps = 4\n\nExecute Random Walk!\nAn exception raised. The traceback is as follows:\nTraceback (most recent call last):\n  File \"/home/ml/users/ksinha4/mlp/comp424_final_project/submissions/comp424mcgill/final-project-a_new_team/world.py\", line 310, in step\n    raise ValueError(\nValueError: [INVALID:STEP] Not a valid step from [4 3] to [4 3] and put barrier at 0, with max steps = 4\n\nExecute Random Walk!\nAn exception raised. The traceback is as follows:\nTraceback (most recent call last):\n  File \"/home/ml/users/ksinha4/mlp/comp424_final_project/submissions/comp424mcgill/final-project-a_new_team/world.py\", line 310, in step\n    raise ValueError(\nValueError: [INVALID:STEP] Not a valid step from [5 4] to [5 4] and put barrier at 0, with max steps = 4\n\nExecute Random Walk!\nAn exception raised. The traceback is as follows:\nTraceback (most recent call last):\n  File \"/home/ml/users/ksinha4/mlp/comp424_final_project/submissions/comp424mcgill/final-project-a_new_team/world.py\", line 310, in step\n    raise ValueError(\nValueError: [INVALID:STEP] Not a valid step from [6 3] to [6 3] and put barrier at 0, with max steps = 4\n\nExecute Random Walk!\n"}, {"student_agent_score": 1, "random_agent_score": 48, "student_agent_time": 0.0047969818115234375, "random_agent_time": 0.002842426300048828, "board_size": 7, "swap_players": false, "run_out": "An exception raised. The traceback is as follows:\nTraceback (most recent call last):\n  File \"/home/ml/users/ksinha4/mlp/comp424_final_project/submissions/comp424mcgill/final-project-a_new_team/world.py\", line 310, in step\n    raise ValueError(\nValueError: [INVALID:STEP] Not a valid step from [4 3] to [4 3] and put barrier at 0, with max steps = 4\n\nExecute Random Walk!\nAn exception raised. The traceback is as follows:\nTraceback (most recent call last):\n  File \"/home/ml/users/ksinha4/mlp/comp424_final_project/submissions/comp424mcgill/final-project-a_new_team/world.py\", line 310, in step\n    raise ValueError(\nValueError: [INVALID:STEP] Not a valid step from [4 2] to [4 2] and put barrier at 0, with max steps = 4\n\nExecute Random Walk!\nAn exception raised. The traceback is as follows:\nTraceback (most recent call last):\n  File \"/home/ml/users/ksinha4/mlp/comp424_final_project/submissions/comp424mcgill/final-project-a_new_team/world.py\", line 310, in step\n    raise ValueError(\nValueError: [INVALID:STEP] Not a valid step from [4 3] to [4 3] and put barrier at 0, with max steps = 4\n\nExecute Random Walk!\nAn exception raised. The traceback is as follows:\nTraceback (most recent call last):\n  File \"/home/ml/users/ksinha4/mlp/comp424_final_project/submissions/comp424mcgill/final-project-a_new_team/world.py\", line 310, in step\n    raise ValueError(\nValueError: [INVALID:STEP] Not a valid step from [5 4] to [5 4] and put barrier at 0, with max steps = 4\n\nExecute Random Walk!\nAn exception raised. The traceback is as follows:\nTraceback (most recent call last):\n  File \"/home/ml/users/ksinha4/mlp/comp424_final_project/submissions/comp424mcgill/final-project-a_new_team/world.py\", line 310, in step\n    raise ValueError(\nValueError: [INVALID:STEP] Not a valid step from [6 3] to [6 3] and put barrier at 0, with max steps = 4\n\nExecute Random Walk!\n"}, {"student_agent_score": 120, "random_agent_score": 1, "student_agent_time": 0.0019490718841552734, "random_agent_time": 0.002324819564819336, "board_size": 11, "swap_players": true, "run_out": "An exception raised. The traceback is as follows:\nTraceback (most recent call last):\n  File \"/home/ml/users/ksinha4/mlp/comp424_final_project/submissions/comp424mcgill/final-project-a_new_team/world.py\", line 310, in step\n    raise ValueError(\nValueError: [INVALID:STEP] Not a valid step from [9 3] to [9 3] and put barrier at 0, with max steps = 6\n\nExecute Random Walk!\nAn exception raised. The traceback is as follows:\nTraceback (most recent call last):\n  File \"/home/ml/users/ksinha4/mlp/comp424_final_project/submissions/comp424mcgill/final-project-a_new_team/world.py\", line 310, in step\n    raise ValueError(\nValueError: [INVALID:STEP] Not a valid step from [9 3] to [9 3] and put barrier at 0, with max steps = 6\n\nExecute Random Walk!\n"}, {"student_agent_score": 2, "random_agent_score": 79, "student_agent_time": 0.002363443374633789, "random_agent_time": 0.0032143592834472656, "board_size": 9, "swap_players": false, "run_out": "An exception raised. The traceback is as follows:\nTraceback (most recent call last):\n  File \"/home/ml/users/ksinha4/mlp/comp424_final_project/submissions/comp424mcgill/final-project-a_new_team/world.py\", line 310, in step\n    raise ValueError(\nValueError: [INVALID:STEP] Not a valid step from [5 4] to [5 4] and put barrier at 0, with max steps = 5\n\nExecute Random Walk!\nAn exception raised. The traceback is as follows:\nTraceback (most recent call last):\n  File \"/home/ml/users/ksinha4/mlp/comp424_final_project/submissions/comp424mcgill/final-project-a_new_team/world.py\", line 310, in step\n    raise ValueError(\nValueError: [INVALID:STEP] Not a valid step from [5 3] to [5 3] and put barrier at 0, with max steps = 5\n\nExecute Random Walk!\n"}, {"student_agent_score": 1, "random_agent_score": 48, "student_agent_time": 0.0023546218872070312, "random_agent_time": 0.002554655075073242, "board_size": 7, "swap_players": true, "run_out": "An exception raised. The traceback is as follows:\nTraceback (most recent call last):\n  File \"/home/ml/users/ksinha4/mlp/comp424_final_project/submissions/comp424mcgill/final-project-a_new_team/world.py\", line 310, in step\n    raise ValueError(\nValueError: [INVALID:STEP] Not a valid step from [2 3] to [2 3] and put barrier at 0, with max steps = 4\n\nExecute Random Walk!\nAn exception raised. The traceback is as follows:\nTraceback (most recent call last):\n  File \"/home/ml/users/ksinha4/mlp/comp424_final_project/submissions/comp424mcgill/final-project-a_new_team/world.py\", line 310, in step\n    raise ValueError(\nValueError: [INVALID:STEP] Not a valid step from [5 4] to [5 4] and put barrier at 0, with max steps = 4\n\nExecute Random Walk!\nAn exception raised. The traceback is as follows:\nTraceback (most recent call last):\n  File \"/home/ml/users/ksinha4/mlp/comp424_final_project/submissions/comp424mcgill/final-project-a_new_team/world.py\", line 310, in step\n    raise ValueError(\nValueError: [INVALID:STEP] Not a valid step from [6 3] to [6 3] and put barrier at 0, with max steps = 4\n\nExecute Random Walk!\n"}, {"student_agent_score": 117, "random_agent_score": 1, "student_agent_time": 0.007561683654785156, "random_agent_time": 0.007910966873168945, "board_size": 11, "swap_players": false, "run_out": "An exception raised. The traceback is as follows:\nTraceback (most recent call last):\n  File \"/home/ml/users/ksinha4/mlp/comp424_final_project/submissions/comp424mcgill/final-project-a_new_team/world.py\", line 310, in step\n    raise ValueError(\nValueError: [INVALID:STEP] Not a valid step from [1 7] to [1 7] and put barrier at 0, with max steps = 6\n\nExecute Random Walk!\nAn exception raised. The traceback is as follows:\nTraceback (most recent call last):\n  File \"/home/ml/users/ksinha4/mlp/comp424_final_project/submissions/comp424mcgill/final-project-a_new_team/world.py\", line 310, in step\n    raise ValueError(\nValueError: [INVALID:STEP] Not a valid step from [1 8] to [1 8] and put barrier at 0, with max steps = 6\n\nExecute Random Walk!\nAn exception raised. The traceback is as follows:\nTraceback (most recent call last):\n  File \"/home/ml/users/ksinha4/mlp/comp424_final_project/submissions/comp424mcgill/final-project-a_new_team/world.py\", line 310, in step\n    raise ValueError(\nValueError: [INVALID:STEP] Not a valid step from [1 6] to [1 6] and put barrier at 0, with max steps = 6\n\nExecute Random Walk!\nAn exception raised. The traceback is as follows:\nTraceback (most recent call last):\n  File \"/home/ml/users/ksinha4/mlp/comp424_final_project/submissions/comp424mcgill/final-project-a_new_team/world.py\", line 310, in step\n    raise ValueError(\nValueError: [INVALID:STEP] Not a valid step from [3 3] to [3 3] and put barrier at 0, with max steps = 6\n\nExecute Random Walk!\nAn exception raised. The traceback is as follows:\nTraceback (most recent call last):\n  File \"/home/ml/users/ksinha4/mlp/comp424_final_project/submissions/comp424mcgill/final-project-a_new_team/world.py\", line 310, in step\n    raise ValueError(\nValueError: [INVALID:STEP] Not a valid step from [3 4] to [3 4] and put barrier at 0, with max steps = 6\n\nExecute Random Walk!\nAn exception raised. The traceback is as follows:\nTraceback (most recent call last):\n  File \"/home/ml/users/ksinha4/mlp/comp424_final_project/submissions/comp424mcgill/final-project-a_new_team/world.py\", line 310, in step\n    raise ValueError(\nValueError: [INVALID:STEP] Not a valid step from [3 4] to [3 4] and put barrier at 0, with max steps = 6\n\nExecute Random Walk!\nAn exception raised. The traceback is as follows:\nTraceback (most recent call last):\n  File \"/home/ml/users/ksinha4/mlp/comp424_final_project/submissions/comp424mcgill/final-project-a_new_team/world.py\", line 310, in step\n    raise ValueError(\nValueError: [INVALID:STEP] Not a valid step from [4 4] to [4 4] and put barrier at 0, with max steps = 6\n\nExecute Random Walk!\nAn exception raised. The traceback is as follows:\nTraceback (most recent call last):\n  File \"/home/ml/users/ksinha4/mlp/comp424_final_project/submissions/comp424mcgill/final-project-a_new_team/world.py\", line 310, in step\n    raise ValueError(\nValueError: [INVALID:STEP] Not a valid step from [4 4] to [4 4] and put barrier at 0, with max steps = 6\n\nExecute Random Walk!\n"}, {"student_agent_score": 99, "random_agent_score": 1, "student_agent_time": 0.0002663135528564453, "random_agent_time": 0.0006673336029052734, "board_size": 10, "swap_players": true, "run_out": ""}, {"student_agent_score": 1, "random_agent_score": 48, "student_agent_time": 0.0042111873626708984, "random_agent_time": 0.002503633499145508, "board_size": 7, "swap_players": false, "run_out": "An exception raised. The traceback is as follows:\nTraceback (most recent call last):\n  File \"/home/ml/users/ksinha4/mlp/comp424_final_project/submissions/comp424mcgill/final-project-a_new_team/world.py\", line 310, in step\n    raise ValueError(\nValueError: [INVALID:STEP] Not a valid step from [4 3] to [4 3] and put barrier at 0, with max steps = 4\n\nExecute Random Walk!\nAn exception raised. The traceback is as follows:\nTraceback (most recent call last):\n  File \"/home/ml/users/ksinha4/mlp/comp424_final_project/submissions/comp424mcgill/final-project-a_new_team/world.py\", line 310, in step\n    raise ValueError(\nValueError: [INVALID:STEP] Not a valid step from [4 2] to [4 2] and put barrier at 0, with max steps = 4\n\nExecute Random Walk!\nAn exception raised. The traceback is as follows:\nTraceback (most recent call last):\n  File \"/home/ml/users/ksinha4/mlp/comp424_final_project/submissions/comp424mcgill/final-project-a_new_team/world.py\", line 310, in step\n    raise ValueError(\nValueError: [INVALID:STEP] Not a valid step from [4 3] to [4 3] and put barrier at 0, with max steps = 4\n\nExecute Random Walk!\nAn exception raised. The traceback is as follows:\nTraceback (most recent call last):\n  File \"/home/ml/users/ksinha4/mlp/comp424_final_project/submissions/comp424mcgill/final-project-a_new_team/world.py\", line 310, in step\n    raise ValueError(\nValueError: [INVALID:STEP] Not a valid step from [5 4] to [5 4] and put barrier at 0, with max steps = 4\n\nExecute Random Walk!\nAn exception raised. The traceback is as follows:\nTraceback (most recent call last):\n  File \"/home/ml/users/ksinha4/mlp/comp424_final_project/submissions/comp424mcgill/final-project-a_new_team/world.py\", line 310, in step\n    raise ValueError(\nValueError: [INVALID:STEP] Not a valid step from [6 3] to [6 3] and put barrier at 0, with max steps = 4\n\nExecute Random Walk!\n"}, {"student_agent_score": 1, "random_agent_score": 48, "student_agent_time": 0.002601146697998047, "random_agent_time": 0.0024623870849609375, "board_size": 7, "swap_players": true, "run_out": "An exception raised. The traceback is as follows:\nTraceback (most recent call last):\n  File \"/home/ml/users/ksinha4/mlp/comp424_final_project/submissions/comp424mcgill/final-project-a_new_team/world.py\", line 310, in step\n    raise ValueError(\nValueError: [INVALID:STEP] Not a valid step from [2 3] to [2 3] and put barrier at 0, with max steps = 4\n\nExecute Random Walk!\nAn exception raised. The traceback is as follows:\nTraceback (most recent call last):\n  File \"/home/ml/users/ksinha4/mlp/comp424_final_project/submissions/comp424mcgill/final-project-a_new_team/world.py\", line 310, in step\n    raise ValueError(\nValueError: [INVALID:STEP] Not a valid step from [5 4] to [5 4] and put barrier at 0, with max steps = 4\n\nExecute Random Walk!\nAn exception raised. The traceback is as follows:\nTraceback (most recent call last):\n  File \"/home/ml/users/ksinha4/mlp/comp424_final_project/submissions/comp424mcgill/final-project-a_new_team/world.py\", line 310, in step\n    raise ValueError(\nValueError: [INVALID:STEP] Not a valid step from [6 3] to [6 3] and put barrier at 0, with max steps = 4\n\nExecute Random Walk!\n"}, {"student_agent_score": 1, "random_agent_score": 35, "student_agent_time": 0.0016407966613769531, "random_agent_time": 0.0016236305236816406, "board_size": 6, "swap_players": true, "run_out": "An exception raised. The traceback is as follows:\nTraceback (most recent call last):\n  File \"/home/ml/users/ksinha4/mlp/comp424_final_project/submissions/comp424mcgill/final-project-a_new_team/world.py\", line 310, in step\n    raise ValueError(\nValueError: [INVALID:STEP] Not a valid step from [3 3] to [3 3] and put barrier at 0, with max steps = 3\n\nExecute Random Walk!\nAn exception raised. The traceback is as follows:\nTraceback (most recent call last):\n  File \"/home/ml/users/ksinha4/mlp/comp424_final_project/submissions/comp424mcgill/final-project-a_new_team/world.py\", line 310, in step\n    raise ValueError(\nValueError: [INVALID:STEP] Not a valid step from [3 3] to [3 3] and put barrier at 0, with max steps = 3\n\nExecute Random Walk!\n"}, {"student_agent_score": 1, "random_agent_score": 63, "student_agent_time": 0.005641460418701172, "random_agent_time": 0.0024261474609375, "board_size": 8, "swap_players": false, "run_out": "An exception raised. The traceback is as follows:\nTraceback (most recent call last):\n  File \"/home/ml/users/ksinha4/mlp/comp424_final_project/submissions/comp424mcgill/final-project-a_new_team/world.py\", line 310, in step\n    raise ValueError(\nValueError: [INVALID:STEP] Not a valid step from [2 2] to [2 2] and put barrier at 0, with max steps = 4\n\nExecute Random Walk!\nAn exception raised. The traceback is as follows:\nTraceback (most recent call last):\n  File \"/home/ml/users/ksinha4/mlp/comp424_final_project/submissions/comp424mcgill/final-project-a_new_team/world.py\", line 310, in step\n    raise ValueError(\nValueError: [INVALID:STEP] Not a valid step from [3 1] to [3 1] and put barrier at 0, with max steps = 4\n\nExecute Random Walk!\nAn exception raised. The traceback is as follows:\nTraceback (most recent call last):\n  File \"/home/ml/users/ksinha4/mlp/comp424_final_project/submissions/comp424mcgill/final-project-a_new_team/world.py\", line 310, in step\n    raise ValueError(\nValueError: [INVALID:STEP] Not a valid step from [3 0] to [3 0] and put barrier at 0, with max steps = 4\n\nExecute Random Walk!\nAn exception raised. The traceback is as follows:\nTraceback (most recent call last):\n  File \"/home/ml/users/ksinha4/mlp/comp424_final_project/submissions/comp424mcgill/final-project-a_new_team/world.py\", line 310, in step\n    raise ValueError(\nValueError: [INVALID:STEP] Not a valid step from [6 1] to [6 1] and put barrier at 0, with max steps = 4\n\nExecute Random Walk!\n"}, {"student_agent_score": 2, "random_agent_score": 79, "student_agent_time": 0.002548694610595703, "random_agent_time": 0.0022089481353759766, "board_size": 9, "swap_players": false, "run_out": "An exception raised. The traceback is as follows:\nTraceback (most recent call last):\n  File \"/home/ml/users/ksinha4/mlp/comp424_final_project/submissions/comp424mcgill/final-project-a_new_team/world.py\", line 310, in step\n    raise ValueError(\nValueError: [INVALID:STEP] Not a valid step from [5 4] to [5 4] and put barrier at 0, with max steps = 5\n\nExecute Random Walk!\nAn exception raised. The traceback is as follows:\nTraceback (most recent call last):\n  File \"/home/ml/users/ksinha4/mlp/comp424_final_project/submissions/comp424mcgill/final-project-a_new_team/world.py\", line 310, in step\n    raise ValueError(\nValueError: [INVALID:STEP] Not a valid step from [5 3] to [5 3] and put barrier at 0, with max steps = 5\n\nExecute Random Walk!\n"}, {"student_agent_score": 1, "random_agent_score": 48, "student_agent_time": 0.0037665367126464844, "random_agent_time": 0.0018260478973388672, "board_size": 7, "swap_players": false, "run_out": "An exception raised. The traceback is as follows:\nTraceback (most recent call last):\n  File \"/home/ml/users/ksinha4/mlp/comp424_final_project/submissions/comp424mcgill/final-project-a_new_team/world.py\", line 310, in step\n    raise ValueError(\nValueError: [INVALID:STEP] Not a valid step from [4 3] to [4 3] and put barrier at 0, with max steps = 4\n\nExecute Random Walk!\nAn exception raised. The traceback is as follows:\nTraceback (most recent call last):\n  File \"/home/ml/users/ksinha4/mlp/comp424_final_project/submissions/comp424mcgill/final-project-a_new_team/world.py\", line 310, in step\n    raise ValueError(\nValueError: [INVALID:STEP] Not a valid step from [4 2] to [4 2] and put barrier at 0, with max steps = 4\n\nExecute Random Walk!\nAn exception raised. The traceback is as follows:\nTraceback (most recent call last):\n  File \"/home/ml/users/ksinha4/mlp/comp424_final_project/submissions/comp424mcgill/final-project-a_new_team/world.py\", line 310, in step\n    raise ValueError(\nValueError: [INVALID:STEP] Not a valid step from [4 3] to [4 3] and put barrier at 0, with max steps = 4\n\nExecute Random Walk!\nAn exception raised. The traceback is as follows:\nTraceback (most recent call last):\n  File \"/home/ml/users/ksinha4/mlp/comp424_final_project/submissions/comp424mcgill/final-project-a_new_team/world.py\", line 310, in step\n    raise ValueError(\nValueError: [INVALID:STEP] Not a valid step from [5 4] to [5 4] and put barrier at 0, with max steps = 4\n\nExecute Random Walk!\nAn exception raised. The traceback is as follows:\nTraceback (most recent call last):\n  File \"/home/ml/users/ksinha4/mlp/comp424_final_project/submissions/comp424mcgill/final-project-a_new_team/world.py\", line 310, in step\n    raise ValueError(\nValueError: [INVALID:STEP] Not a valid step from [6 3] to [6 3] and put barrier at 0, with max steps = 4\n\nExecute Random Walk!\n"}, {"student_agent_score": 80, "random_agent_score": 1, "student_agent_time": 0.008207082748413086, "random_agent_time": 0.0062558650970458984, "board_size": 9, "swap_players": true, "run_out": "An exception raised. The traceback is as follows:\nTraceback (most recent call last):\n  File \"/home/ml/users/ksinha4/mlp/comp424_final_project/submissions/comp424mcgill/final-project-a_new_team/world.py\", line 310, in step\n    raise ValueError(\nValueError: [INVALID:STEP] Not a valid step from [3 4] to [3 4] and put barrier at 0, with max steps = 5\n\nExecute Random Walk!\nAn exception raised. The traceback is as follows:\nTraceback (most recent call last):\n  File \"/home/ml/users/ksinha4/mlp/comp424_final_project/submissions/comp424mcgill/final-project-a_new_team/world.py\", line 310, in step\n    raise ValueError(\nValueError: [INVALID:STEP] Not a valid step from [3 5] to [3 5] and put barrier at 0, with max steps = 5\n\nExecute Random Walk!\nAn exception raised. The traceback is as follows:\nTraceback (most recent call last):\n  File \"/home/ml/users/ksinha4/mlp/comp424_final_project/submissions/comp424mcgill/final-project-a_new_team/world.py\", line 310, in step\n    raise ValueError(\nValueError: [INVALID:STEP] Not a valid step from [3 4] to [3 4] and put barrier at 0, with max steps = 5\n\nExecute Random Walk!\nAn exception raised. The traceback is as follows:\nTraceback (most recent call last):\n  File \"/home/ml/users/ksinha4/mlp/comp424_final_project/submissions/comp424mcgill/final-project-a_new_team/world.py\", line 310, in step\n    raise ValueError(\nValueError: [INVALID:STEP] Not a valid step from [5 4] to [5 4] and put barrier at 0, with max steps = 5\n\nExecute Random Walk!\nAn exception raised. The traceback is as follows:\nTraceback (most recent call last):\n  File \"/home/ml/users/ksinha4/mlp/comp424_final_project/submissions/comp424mcgill/final-project-a_new_team/world.py\", line 310, in step\n    raise ValueError(\nValueError: [INVALID:STEP] Not a valid step from [5 5] to [5 5] and put barrier at 0, with max steps = 5\n\nExecute Random Walk!\n"}, {"student_agent_score": 1, "random_agent_score": 48, "student_agent_time": 0.003797769546508789, "random_agent_time": 0.002661466598510742, "board_size": 7, "swap_players": true, "run_out": "An exception raised. The traceback is as follows:\nTraceback (most recent call last):\n  File \"/home/ml/users/ksinha4/mlp/comp424_final_project/submissions/comp424mcgill/final-project-a_new_team/world.py\", line 310, in step\n    raise ValueError(\nValueError: [INVALID:STEP] Not a valid step from [2 3] to [2 3] and put barrier at 0, with max steps = 4\n\nExecute Random Walk!\nAn exception raised. The traceback is as follows:\nTraceback (most recent call last):\n  File \"/home/ml/users/ksinha4/mlp/comp424_final_project/submissions/comp424mcgill/final-project-a_new_team/world.py\", line 310, in step\n    raise ValueError(\nValueError: [INVALID:STEP] Not a valid step from [5 4] to [5 4] and put barrier at 0, with max steps = 4\n\nExecute Random Walk!\nAn exception raised. The traceback is as follows:\nTraceback (most recent call last):\n  File \"/home/ml/users/ksinha4/mlp/comp424_final_project/submissions/comp424mcgill/final-project-a_new_team/world.py\", line 310, in step\n    raise ValueError(\nValueError: [INVALID:STEP] Not a valid step from [6 3] to [6 3] and put barrier at 0, with max steps = 4\n\nExecute Random Walk!\n"}, {"student_agent_score": 1, "random_agent_score": 48, "student_agent_time": 0.0038080215454101562, "random_agent_time": 0.0028688907623291016, "board_size": 7, "swap_players": false, "run_out": "An exception raised. The traceback is as follows:\nTraceback (most recent call last):\n  File \"/home/ml/users/ksinha4/mlp/comp424_final_project/submissions/comp424mcgill/final-project-a_new_team/world.py\", line 310, in step\n    raise ValueError(\nValueError: [INVALID:STEP] Not a valid step from [4 3] to [4 3] and put barrier at 0, with max steps = 4\n\nExecute Random Walk!\nAn exception raised. The traceback is as follows:\nTraceback (most recent call last):\n  File \"/home/ml/users/ksinha4/mlp/comp424_final_project/submissions/comp424mcgill/final-project-a_new_team/world.py\", line 310, in step\n    raise ValueError(\nValueError: [INVALID:STEP] Not a valid step from [4 2] to [4 2] and put barrier at 0, with max steps = 4\n\nExecute Random Walk!\nAn exception raised. The traceback is as follows:\nTraceback (most recent call last):\n  File \"/home/ml/users/ksinha4/mlp/comp424_final_project/submissions/comp424mcgill/final-project-a_new_team/world.py\", line 310, in step\n    raise ValueError(\nValueError: [INVALID:STEP] Not a valid step from [4 3] to [4 3] and put barrier at 0, with max steps = 4\n\nExecute Random Walk!\nAn exception raised. The traceback is as follows:\nTraceback (most recent call last):\n  File \"/home/ml/users/ksinha4/mlp/comp424_final_project/submissions/comp424mcgill/final-project-a_new_team/world.py\", line 310, in step\n    raise ValueError(\nValueError: [INVALID:STEP] Not a valid step from [5 4] to [5 4] and put barrier at 0, with max steps = 4\n\nExecute Random Walk!\nAn exception raised. The traceback is as follows:\nTraceback (most recent call last):\n  File \"/home/ml/users/ksinha4/mlp/comp424_final_project/submissions/comp424mcgill/final-project-a_new_team/world.py\", line 310, in step\n    raise ValueError(\nValueError: [INVALID:STEP] Not a valid step from [6 3] to [6 3] and put barrier at 0, with max steps = 4\n\nExecute Random Walk!\n"}, {"student_agent_score": 99, "random_agent_score": 1, "student_agent_time": 0.00034332275390625, "random_agent_time": 0.002677440643310547, "board_size": 10, "swap_players": true, "run_out": ""}, {"student_agent_score": 1, "random_agent_score": 48, "student_agent_time": 0.0036911964416503906, "random_agent_time": 0.0021369457244873047, "board_size": 7, "swap_players": false, "run_out": "An exception raised. The traceback is as follows:\nTraceback (most recent call last):\n  File \"/home/ml/users/ksinha4/mlp/comp424_final_project/submissions/comp424mcgill/final-project-a_new_team/world.py\", line 310, in step\n    raise ValueError(\nValueError: [INVALID:STEP] Not a valid step from [4 3] to [4 3] and put barrier at 0, with max steps = 4\n\nExecute Random Walk!\nAn exception raised. The traceback is as follows:\nTraceback (most recent call last):\n  File \"/home/ml/users/ksinha4/mlp/comp424_final_project/submissions/comp424mcgill/final-project-a_new_team/world.py\", line 310, in step\n    raise ValueError(\nValueError: [INVALID:STEP] Not a valid step from [4 2] to [4 2] and put barrier at 0, with max steps = 4\n\nExecute Random Walk!\nAn exception raised. The traceback is as follows:\nTraceback (most recent call last):\n  File \"/home/ml/users/ksinha4/mlp/comp424_final_project/submissions/comp424mcgill/final-project-a_new_team/world.py\", line 310, in step\n    raise ValueError(\nValueError: [INVALID:STEP] Not a valid step from [4 3] to [4 3] and put barrier at 0, with max steps = 4\n\nExecute Random Walk!\nAn exception raised. The traceback is as follows:\nTraceback (most recent call last):\n  File \"/home/ml/users/ksinha4/mlp/comp424_final_project/submissions/comp424mcgill/final-project-a_new_team/world.py\", line 310, in step\n    raise ValueError(\nValueError: [INVALID:STEP] Not a valid step from [5 4] to [5 4] and put barrier at 0, with max steps = 4\n\nExecute Random Walk!\nAn exception raised. The traceback is as follows:\nTraceback (most recent call last):\n  File \"/home/ml/users/ksinha4/mlp/comp424_final_project/submissions/comp424mcgill/final-project-a_new_team/world.py\", line 310, in step\n    raise ValueError(\nValueError: [INVALID:STEP] Not a valid step from [6 3] to [6 3] and put barrier at 0, with max steps = 4\n\nExecute Random Walk!\n"}, {"student_agent_score": 120, "random_agent_score": 1, "student_agent_time": 0.001939535140991211, "random_agent_time": 0.0031211376190185547, "board_size": 11, "swap_players": true, "run_out": "An exception raised. The traceback is as follows:\nTraceback (most recent call last):\n  File \"/home/ml/users/ksinha4/mlp/comp424_final_project/submissions/comp424mcgill/final-project-a_new_team/world.py\", line 310, in step\n    raise ValueError(\nValueError: [INVALID:STEP] Not a valid step from [9 3] to [9 3] and put barrier at 0, with max steps = 6\n\nExecute Random Walk!\nAn exception raised. The traceback is as follows:\nTraceback (most recent call last):\n  File \"/home/ml/users/ksinha4/mlp/comp424_final_project/submissions/comp424mcgill/final-project-a_new_team/world.py\", line 310, in step\n    raise ValueError(\nValueError: [INVALID:STEP] Not a valid step from [9 3] to [9 3] and put barrier at 0, with max steps = 6\n\nExecute Random Walk!\n"}, {"student_agent_score": 117, "random_agent_score": 1, "student_agent_time": 0.007250070571899414, "random_agent_time": 0.00950765609741211, "board_size": 11, "swap_players": false, "run_out": "An exception raised. The traceback is as follows:\nTraceback (most recent call last):\n  File \"/home/ml/users/ksinha4/mlp/comp424_final_project/submissions/comp424mcgill/final-project-a_new_team/world.py\", line 310, in step\n    raise ValueError(\nValueError: [INVALID:STEP] Not a valid step from [1 7] to [1 7] and put barrier at 0, with max steps = 6\n\nExecute Random Walk!\nAn exception raised. The traceback is as follows:\nTraceback (most recent call last):\n  File \"/home/ml/users/ksinha4/mlp/comp424_final_project/submissions/comp424mcgill/final-project-a_new_team/world.py\", line 310, in step\n    raise ValueError(\nValueError: [INVALID:STEP] Not a valid step from [1 8] to [1 8] and put barrier at 0, with max steps = 6\n\nExecute Random Walk!\nAn exception raised. The traceback is as follows:\nTraceback (most recent call last):\n  File \"/home/ml/users/ksinha4/mlp/comp424_final_project/submissions/comp424mcgill/final-project-a_new_team/world.py\", line 310, in step\n    raise ValueError(\nValueError: [INVALID:STEP] Not a valid step from [1 6] to [1 6] and put barrier at 0, with max steps = 6\n\nExecute Random Walk!\nAn exception raised. The traceback is as follows:\nTraceback (most recent call last):\n  File \"/home/ml/users/ksinha4/mlp/comp424_final_project/submissions/comp424mcgill/final-project-a_new_team/world.py\", line 310, in step\n    raise ValueError(\nValueError: [INVALID:STEP] Not a valid step from [3 3] to [3 3] and put barrier at 0, with max steps = 6\n\nExecute Random Walk!\nAn exception raised. The traceback is as follows:\nTraceback (most recent call last):\n  File \"/home/ml/users/ksinha4/mlp/comp424_final_project/submissions/comp424mcgill/final-project-a_new_team/world.py\", line 310, in step\n    raise ValueError(\nValueError: [INVALID:STEP] Not a valid step from [3 4] to [3 4] and put barrier at 0, with max steps = 6\n\nExecute Random Walk!\nAn exception raised. The traceback is as follows:\nTraceback (most recent call last):\n  File \"/home/ml/users/ksinha4/mlp/comp424_final_project/submissions/comp424mcgill/final-project-a_new_team/world.py\", line 310, in step\n    raise ValueError(\nValueError: [INVALID:STEP] Not a valid step from [3 4] to [3 4] and put barrier at 0, with max steps = 6\n\nExecute Random Walk!\nAn exception raised. The traceback is as follows:\nTraceback (most recent call last):\n  File \"/home/ml/users/ksinha4/mlp/comp424_final_project/submissions/comp424mcgill/final-project-a_new_team/world.py\", line 310, in step\n    raise ValueError(\nValueError: [INVALID:STEP] Not a valid step from [4 4] to [4 4] and put barrier at 0, with max steps = 6\n\nExecute Random Walk!\nAn exception raised. The traceback is as follows:\nTraceback (most recent call last):\n  File \"/home/ml/users/ksinha4/mlp/comp424_final_project/submissions/comp424mcgill/final-project-a_new_team/world.py\", line 310, in step\n    raise ValueError(\nValueError: [INVALID:STEP] Not a valid step from [4 4] to [4 4] and put barrier at 0, with max steps = 6\n\nExecute Random Walk!\n"}, {"student_agent_score": 1, "random_agent_score": 48, "student_agent_time": 0.002841472625732422, "random_agent_time": 0.002135753631591797, "board_size": 7, "swap_players": true, "run_out": "An exception raised. The traceback is as follows:\nTraceback (most recent call last):\n  File \"/home/ml/users/ksinha4/mlp/comp424_final_project/submissions/comp424mcgill/final-project-a_new_team/world.py\", line 310, in step\n    raise ValueError(\nValueError: [INVALID:STEP] Not a valid step from [2 3] to [2 3] and put barrier at 0, with max steps = 4\n\nExecute Random Walk!\nAn exception raised. The traceback is as follows:\nTraceback (most recent call last):\n  File \"/home/ml/users/ksinha4/mlp/comp424_final_project/submissions/comp424mcgill/final-project-a_new_team/world.py\", line 310, in step\n    raise ValueError(\nValueError: [INVALID:STEP] Not a valid step from [5 4] to [5 4] and put barrier at 0, with max steps = 4\n\nExecute Random Walk!\nAn exception raised. The traceback is as follows:\nTraceback (most recent call last):\n  File \"/home/ml/users/ksinha4/mlp/comp424_final_project/submissions/comp424mcgill/final-project-a_new_team/world.py\", line 310, in step\n    raise ValueError(\nValueError: [INVALID:STEP] Not a valid step from [6 3] to [6 3] and put barrier at 0, with max steps = 4\n\nExecute Random Walk!\n"}, {"student_agent_score": 1, "random_agent_score": 48, "student_agent_time": 0.004475116729736328, "random_agent_time": 0.0023145675659179688, "board_size": 7, "swap_players": false, "run_out": "An exception raised. The traceback is as follows:\nTraceback (most recent call last):\n  File \"/home/ml/users/ksinha4/mlp/comp424_final_project/submissions/comp424mcgill/final-project-a_new_team/world.py\", line 310, in step\n    raise ValueError(\nValueError: [INVALID:STEP] Not a valid step from [4 3] to [4 3] and put barrier at 0, with max steps = 4\n\nExecute Random Walk!\nAn exception raised. The traceback is as follows:\nTraceback (most recent call last):\n  File \"/home/ml/users/ksinha4/mlp/comp424_final_project/submissions/comp424mcgill/final-project-a_new_team/world.py\", line 310, in step\n    raise ValueError(\nValueError: [INVALID:STEP] Not a valid step from [4 2] to [4 2] and put barrier at 0, with max steps = 4\n\nExecute Random Walk!\nAn exception raised. The traceback is as follows:\nTraceback (most recent call last):\n  File \"/home/ml/users/ksinha4/mlp/comp424_final_project/submissions/comp424mcgill/final-project-a_new_team/world.py\", line 310, in step\n    raise ValueError(\nValueError: [INVALID:STEP] Not a valid step from [4 3] to [4 3] and put barrier at 0, with max steps = 4\n\nExecute Random Walk!\nAn exception raised. The traceback is as follows:\nTraceback (most recent call last):\n  File \"/home/ml/users/ksinha4/mlp/comp424_final_project/submissions/comp424mcgill/final-project-a_new_team/world.py\", line 310, in step\n    raise ValueError(\nValueError: [INVALID:STEP] Not a valid step from [5 4] to [5 4] and put barrier at 0, with max steps = 4\n\nExecute Random Walk!\nAn exception raised. The traceback is as follows:\nTraceback (most recent call last):\n  File \"/home/ml/users/ksinha4/mlp/comp424_final_project/submissions/comp424mcgill/final-project-a_new_team/world.py\", line 310, in step\n    raise ValueError(\nValueError: [INVALID:STEP] Not a valid step from [6 3] to [6 3] and put barrier at 0, with max steps = 4\n\nExecute Random Walk!\n"}, {"student_agent_score": 1, "random_agent_score": 48, "student_agent_time": 0.002447843551635742, "random_agent_time": 0.0025932788848876953, "board_size": 7, "swap_players": true, "run_out": "An exception raised. The traceback is as follows:\nTraceback (most recent call last):\n  File \"/home/ml/users/ksinha4/mlp/comp424_final_project/submissions/comp424mcgill/final-project-a_new_team/world.py\", line 310, in step\n    raise ValueError(\nValueError: [INVALID:STEP] Not a valid step from [2 3] to [2 3] and put barrier at 0, with max steps = 4\n\nExecute Random Walk!\nAn exception raised. The traceback is as follows:\nTraceback (most recent call last):\n  File \"/home/ml/users/ksinha4/mlp/comp424_final_project/submissions/comp424mcgill/final-project-a_new_team/world.py\", line 310, in step\n    raise ValueError(\nValueError: [INVALID:STEP] Not a valid step from [5 4] to [5 4] and put barrier at 0, with max steps = 4\n\nExecute Random Walk!\nAn exception raised. The traceback is as follows:\nTraceback (most recent call last):\n  File \"/home/ml/users/ksinha4/mlp/comp424_final_project/submissions/comp424mcgill/final-project-a_new_team/world.py\", line 310, in step\n    raise ValueError(\nValueError: [INVALID:STEP] Not a valid step from [6 3] to [6 3] and put barrier at 0, with max steps = 4\n\nExecute Random Walk!\n"}, {"student_agent_score": 1, "random_agent_score": 35, "student_agent_time": 0.0018391609191894531, "random_agent_time": 0.002087831497192383, "board_size": 6, "swap_players": true, "run_out": "An exception raised. The traceback is as follows:\nTraceback (most recent call last):\n  File \"/home/ml/users/ksinha4/mlp/comp424_final_project/submissions/comp424mcgill/final-project-a_new_team/world.py\", line 310, in step\n    raise ValueError(\nValueError: [INVALID:STEP] Not a valid step from [3 3] to [3 3] and put barrier at 0, with max steps = 3\n\nExecute Random Walk!\nAn exception raised. The traceback is as follows:\nTraceback (most recent call last):\n  File \"/home/ml/users/ksinha4/mlp/comp424_final_project/submissions/comp424mcgill/final-project-a_new_team/world.py\", line 310, in step\n    raise ValueError(\nValueError: [INVALID:STEP] Not a valid step from [3 3] to [3 3] and put barrier at 0, with max steps = 3\n\nExecute Random Walk!\n"}, {"student_agent_score": 1, "random_agent_score": 35, "student_agent_time": 0.0027666091918945312, "random_agent_time": 0.0032503604888916016, "board_size": 6, "swap_players": true, "run_out": "An exception raised. The traceback is as follows:\nTraceback (most recent call last):\n  File \"/home/ml/users/ksinha4/mlp/comp424_final_project/submissions/comp424mcgill/final-project-a_new_team/world.py\", line 310, in step\n    raise ValueError(\nValueError: [INVALID:STEP] Not a valid step from [3 3] to [3 3] and put barrier at 0, with max steps = 3\n\nExecute Random Walk!\nAn exception raised. The traceback is as follows:\nTraceback (most recent call last):\n  File \"/home/ml/users/ksinha4/mlp/comp424_final_project/submissions/comp424mcgill/final-project-a_new_team/world.py\", line 310, in step\n    raise ValueError(\nValueError: [INVALID:STEP] Not a valid step from [3 3] to [3 3] and put barrier at 0, with max steps = 3\n\nExecute Random Walk!\n"}, {"student_agent_score": 80, "random_agent_score": 1, "student_agent_time": 0.006147861480712891, "random_agent_time": 0.006598711013793945, "board_size": 9, "swap_players": true, "run_out": "An exception raised. The traceback is as follows:\nTraceback (most recent call last):\n  File \"/home/ml/users/ksinha4/mlp/comp424_final_project/submissions/comp424mcgill/final-project-a_new_team/world.py\", line 310, in step\n    raise ValueError(\nValueError: [INVALID:STEP] Not a valid step from [3 4] to [3 4] and put barrier at 0, with max steps = 5\n\nExecute Random Walk!\nAn exception raised. The traceback is as follows:\nTraceback (most recent call last):\n  File \"/home/ml/users/ksinha4/mlp/comp424_final_project/submissions/comp424mcgill/final-project-a_new_team/world.py\", line 310, in step\n    raise ValueError(\nValueError: [INVALID:STEP] Not a valid step from [3 5] to [3 5] and put barrier at 0, with max steps = 5\n\nExecute Random Walk!\nAn exception raised. The traceback is as follows:\nTraceback (most recent call last):\n  File \"/home/ml/users/ksinha4/mlp/comp424_final_project/submissions/comp424mcgill/final-project-a_new_team/world.py\", line 310, in step\n    raise ValueError(\nValueError: [INVALID:STEP] Not a valid step from [3 4] to [3 4] and put barrier at 0, with max steps = 5\n\nExecute Random Walk!\nAn exception raised. The traceback is as follows:\nTraceback (most recent call last):\n  File \"/home/ml/users/ksinha4/mlp/comp424_final_project/submissions/comp424mcgill/final-project-a_new_team/world.py\", line 310, in step\n    raise ValueError(\nValueError: [INVALID:STEP] Not a valid step from [5 4] to [5 4] and put barrier at 0, with max steps = 5\n\nExecute Random Walk!\nAn exception raised. The traceback is as follows:\nTraceback (most recent call last):\n  File \"/home/ml/users/ksinha4/mlp/comp424_final_project/submissions/comp424mcgill/final-project-a_new_team/world.py\", line 310, in step\n    raise ValueError(\nValueError: [INVALID:STEP] Not a valid step from [5 5] to [5 5] and put barrier at 0, with max steps = 5\n\nExecute Random Walk!\n"}, {"student_agent_score": 2, "random_agent_score": 98, "student_agent_time": 0.008178472518920898, "random_agent_time": 0.007010459899902344, "board_size": 10, "swap_players": false, "run_out": "An exception raised. The traceback is as follows:\nTraceback (most recent call last):\n  File \"/home/ml/users/ksinha4/mlp/comp424_final_project/submissions/comp424mcgill/final-project-a_new_team/world.py\", line 310, in step\n    raise ValueError(\nValueError: [INVALID:STEP] Not a valid step from [7 5] to [7 5] and put barrier at 0, with max steps = 5\n\nExecute Random Walk!\nAn exception raised. The traceback is as follows:\nTraceback (most recent call last):\n  File \"/home/ml/users/ksinha4/mlp/comp424_final_project/submissions/comp424mcgill/final-project-a_new_team/world.py\", line 310, in step\n    raise ValueError(\nValueError: [INVALID:STEP] Not a valid step from [6 6] to [6 6] and put barrier at 0, with max steps = 5\n\nExecute Random Walk!\nAn exception raised. The traceback is as follows:\nTraceback (most recent call last):\n  File \"/home/ml/users/ksinha4/mlp/comp424_final_project/submissions/comp424mcgill/final-project-a_new_team/world.py\", line 310, in step\n    raise ValueError(\nValueError: [INVALID:STEP] Not a valid step from [7 8] to [7 8] and put barrier at 0, with max steps = 5\n\nExecute Random Walk!\nAn exception raised. The traceback is as follows:\nTraceback (most recent call last):\n  File \"/home/ml/users/ksinha4/mlp/comp424_final_project/submissions/comp424mcgill/final-project-a_new_team/world.py\", line 310, in step\n    raise ValueError(\nValueError: [INVALID:STEP] Not a valid step from [7 8] to [7 8] and put barrier at 0, with max steps = 5\n\nExecute Random Walk!\n"}, {"student_agent_score": 2, "random_agent_score": 79, "student_agent_time": 0.006575822830200195, "random_agent_time": 0.0018467903137207031, "board_size": 9, "swap_players": false, "run_out": "An exception raised. The traceback is as follows:\nTraceback (most recent call last):\n  File \"/home/ml/users/ksinha4/mlp/comp424_final_project/submissions/comp424mcgill/final-project-a_new_team/world.py\", line 310, in step\n    raise ValueError(\nValueError: [INVALID:STEP] Not a valid step from [5 4] to [5 4] and put barrier at 0, with max steps = 5\n\nExecute Random Walk!\nAn exception raised. The traceback is as follows:\nTraceback (most recent call last):\n  File \"/home/ml/users/ksinha4/mlp/comp424_final_project/submissions/comp424mcgill/final-project-a_new_team/world.py\", line 310, in step\n    raise ValueError(\nValueError: [INVALID:STEP] Not a valid step from [5 3] to [5 3] and put barrier at 0, with max steps = 5\n\nExecute Random Walk!\n"}, {"student_agent_score": 1, "random_agent_score": 48, "student_agent_time": 0.003980159759521484, "random_agent_time": 0.003926753997802734, "board_size": 7, "swap_players": true, "run_out": "An exception raised. The traceback is as follows:\nTraceback (most recent call last):\n  File \"/home/ml/users/ksinha4/mlp/comp424_final_project/submissions/comp424mcgill/final-project-a_new_team/world.py\", line 310, in step\n    raise ValueError(\nValueError: [INVALID:STEP] Not a valid step from [2 3] to [2 3] and put barrier at 0, with max steps = 4\n\nExecute Random Walk!\nAn exception raised. The traceback is as follows:\nTraceback (most recent call last):\n  File \"/home/ml/users/ksinha4/mlp/comp424_final_project/submissions/comp424mcgill/final-project-a_new_team/world.py\", line 310, in step\n    raise ValueError(\nValueError: [INVALID:STEP] Not a valid step from [5 4] to [5 4] and put barrier at 0, with max steps = 4\n\nExecute Random Walk!\nAn exception raised. The traceback is as follows:\nTraceback (most recent call last):\n  File \"/home/ml/users/ksinha4/mlp/comp424_final_project/submissions/comp424mcgill/final-project-a_new_team/world.py\", line 310, in step\n    raise ValueError(\nValueError: [INVALID:STEP] Not a valid step from [6 3] to [6 3] and put barrier at 0, with max steps = 4\n\nExecute Random Walk!\n"}, {"student_agent_score": 1, "random_agent_score": 48, "student_agent_time": 0.004771232604980469, "random_agent_time": 0.002168416976928711, "board_size": 7, "swap_players": false, "run_out": "An exception raised. The traceback is as follows:\nTraceback (most recent call last):\n  File \"/home/ml/users/ksinha4/mlp/comp424_final_project/submissions/comp424mcgill/final-project-a_new_team/world.py\", line 310, in step\n    raise ValueError(\nValueError: [INVALID:STEP] Not a valid step from [4 3] to [4 3] and put barrier at 0, with max steps = 4\n\nExecute Random Walk!\nAn exception raised. The traceback is as follows:\nTraceback (most recent call last):\n  File \"/home/ml/users/ksinha4/mlp/comp424_final_project/submissions/comp424mcgill/final-project-a_new_team/world.py\", line 310, in step\n    raise ValueError(\nValueError: [INVALID:STEP] Not a valid step from [4 2] to [4 2] and put barrier at 0, with max steps = 4\n\nExecute Random Walk!\nAn exception raised. The traceback is as follows:\nTraceback (most recent call last):\n  File \"/home/ml/users/ksinha4/mlp/comp424_final_project/submissions/comp424mcgill/final-project-a_new_team/world.py\", line 310, in step\n    raise ValueError(\nValueError: [INVALID:STEP] Not a valid step from [4 3] to [4 3] and put barrier at 0, with max steps = 4\n\nExecute Random Walk!\nAn exception raised. The traceback is as follows:\nTraceback (most recent call last):\n  File \"/home/ml/users/ksinha4/mlp/comp424_final_project/submissions/comp424mcgill/final-project-a_new_team/world.py\", line 310, in step\n    raise ValueError(\nValueError: [INVALID:STEP] Not a valid step from [5 4] to [5 4] and put barrier at 0, with max steps = 4\n\nExecute Random Walk!\nAn exception raised. The traceback is as follows:\nTraceback (most recent call last):\n  File \"/home/ml/users/ksinha4/mlp/comp424_final_project/submissions/comp424mcgill/final-project-a_new_team/world.py\", line 310, in step\n    raise ValueError(\nValueError: [INVALID:STEP] Not a valid step from [6 3] to [6 3] and put barrier at 0, with max steps = 4\n\nExecute Random Walk!\n"}, {"student_agent_score": 1, "random_agent_score": 48, "student_agent_time": 0.004842996597290039, "random_agent_time": 0.00486302375793457, "board_size": 7, "swap_players": false, "run_out": "An exception raised. The traceback is as follows:\nTraceback (most recent call last):\n  File \"/home/ml/users/ksinha4/mlp/comp424_final_project/submissions/comp424mcgill/final-project-a_new_team/world.py\", line 310, in step\n    raise ValueError(\nValueError: [INVALID:STEP] Not a valid step from [4 3] to [4 3] and put barrier at 0, with max steps = 4\n\nExecute Random Walk!\nAn exception raised. The traceback is as follows:\nTraceback (most recent call last):\n  File \"/home/ml/users/ksinha4/mlp/comp424_final_project/submissions/comp424mcgill/final-project-a_new_team/world.py\", line 310, in step\n    raise ValueError(\nValueError: [INVALID:STEP] Not a valid step from [4 2] to [4 2] and put barrier at 0, with max steps = 4\n\nExecute Random Walk!\nAn exception raised. The traceback is as follows:\nTraceback (most recent call last):\n  File \"/home/ml/users/ksinha4/mlp/comp424_final_project/submissions/comp424mcgill/final-project-a_new_team/world.py\", line 310, in step\n    raise ValueError(\nValueError: [INVALID:STEP] Not a valid step from [4 3] to [4 3] and put barrier at 0, with max steps = 4\n\nExecute Random Walk!\nAn exception raised. The traceback is as follows:\nTraceback (most recent call last):\n  File \"/home/ml/users/ksinha4/mlp/comp424_final_project/submissions/comp424mcgill/final-project-a_new_team/world.py\", line 310, in step\n    raise ValueError(\nValueError: [INVALID:STEP] Not a valid step from [5 4] to [5 4] and put barrier at 0, with max steps = 4\n\nExecute Random Walk!\nAn exception raised. The traceback is as follows:\nTraceback (most recent call last):\n  File \"/home/ml/users/ksinha4/mlp/comp424_final_project/submissions/comp424mcgill/final-project-a_new_team/world.py\", line 310, in step\n    raise ValueError(\nValueError: [INVALID:STEP] Not a valid step from [6 3] to [6 3] and put barrier at 0, with max steps = 4\n\nExecute Random Walk!\n"}, {"student_agent_score": 117, "random_agent_score": 1, "student_agent_time": 0.008631229400634766, "random_agent_time": 0.008161067962646484, "board_size": 11, "swap_players": false, "run_out": "An exception raised. The traceback is as follows:\nTraceback (most recent call last):\n  File \"/home/ml/users/ksinha4/mlp/comp424_final_project/submissions/comp424mcgill/final-project-a_new_team/world.py\", line 310, in step\n    raise ValueError(\nValueError: [INVALID:STEP] Not a valid step from [1 7] to [1 7] and put barrier at 0, with max steps = 6\n\nExecute Random Walk!\nAn exception raised. The traceback is as follows:\nTraceback (most recent call last):\n  File \"/home/ml/users/ksinha4/mlp/comp424_final_project/submissions/comp424mcgill/final-project-a_new_team/world.py\", line 310, in step\n    raise ValueError(\nValueError: [INVALID:STEP] Not a valid step from [1 8] to [1 8] and put barrier at 0, with max steps = 6\n\nExecute Random Walk!\nAn exception raised. The traceback is as follows:\nTraceback (most recent call last):\n  File \"/home/ml/users/ksinha4/mlp/comp424_final_project/submissions/comp424mcgill/final-project-a_new_team/world.py\", line 310, in step\n    raise ValueError(\nValueError: [INVALID:STEP] Not a valid step from [1 6] to [1 6] and put barrier at 0, with max steps = 6\n\nExecute Random Walk!\nAn exception raised. The traceback is as follows:\nTraceback (most recent call last):\n  File \"/home/ml/users/ksinha4/mlp/comp424_final_project/submissions/comp424mcgill/final-project-a_new_team/world.py\", line 310, in step\n    raise ValueError(\nValueError: [INVALID:STEP] Not a valid step from [3 3] to [3 3] and put barrier at 0, with max steps = 6\n\nExecute Random Walk!\nAn exception raised. The traceback is as follows:\nTraceback (most recent call last):\n  File \"/home/ml/users/ksinha4/mlp/comp424_final_project/submissions/comp424mcgill/final-project-a_new_team/world.py\", line 310, in step\n    raise ValueError(\nValueError: [INVALID:STEP] Not a valid step from [3 4] to [3 4] and put barrier at 0, with max steps = 6\n\nExecute Random Walk!\nAn exception raised. The traceback is as follows:\nTraceback (most recent call last):\n  File \"/home/ml/users/ksinha4/mlp/comp424_final_project/submissions/comp424mcgill/final-project-a_new_team/world.py\", line 310, in step\n    raise ValueError(\nValueError: [INVALID:STEP] Not a valid step from [3 4] to [3 4] and put barrier at 0, with max steps = 6\n\nExecute Random Walk!\nAn exception raised. The traceback is as follows:\nTraceback (most recent call last):\n  File \"/home/ml/users/ksinha4/mlp/comp424_final_project/submissions/comp424mcgill/final-project-a_new_team/world.py\", line 310, in step\n    raise ValueError(\nValueError: [INVALID:STEP] Not a valid step from [4 4] to [4 4] and put barrier at 0, with max steps = 6\n\nExecute Random Walk!\nAn exception raised. The traceback is as follows:\nTraceback (most recent call last):\n  File \"/home/ml/users/ksinha4/mlp/comp424_final_project/submissions/comp424mcgill/final-project-a_new_team/world.py\", line 310, in step\n    raise ValueError(\nValueError: [INVALID:STEP] Not a valid step from [4 4] to [4 4] and put barrier at 0, with max steps = 6\n\nExecute Random Walk!\n"}, {"student_agent_score": 99, "random_agent_score": 1, "student_agent_time": 0.0014302730560302734, "random_agent_time": 0.0010864734649658203, "board_size": 10, "swap_players": true, "run_out": ""}, {"student_agent_score": 120, "random_agent_score": 1, "student_agent_time": 0.0023097991943359375, "random_agent_time": 0.002521038055419922, "board_size": 11, "swap_players": true, "run_out": "An exception raised. The traceback is as follows:\nTraceback (most recent call last):\n  File \"/home/ml/users/ksinha4/mlp/comp424_final_project/submissions/comp424mcgill/final-project-a_new_team/world.py\", line 310, in step\n    raise ValueError(\nValueError: [INVALID:STEP] Not a valid step from [9 3] to [9 3] and put barrier at 0, with max steps = 6\n\nExecute Random Walk!\nAn exception raised. The traceback is as follows:\nTraceback (most recent call last):\n  File \"/home/ml/users/ksinha4/mlp/comp424_final_project/submissions/comp424mcgill/final-project-a_new_team/world.py\", line 310, in step\n    raise ValueError(\nValueError: [INVALID:STEP] Not a valid step from [9 3] to [9 3] and put barrier at 0, with max steps = 6\n\nExecute Random Walk!\n"}, {"student_agent_score": 1, "random_agent_score": 63, "student_agent_time": 0.003026723861694336, "random_agent_time": 0.0022363662719726562, "board_size": 8, "swap_players": false, "run_out": "An exception raised. The traceback is as follows:\nTraceback (most recent call last):\n  File \"/home/ml/users/ksinha4/mlp/comp424_final_project/submissions/comp424mcgill/final-project-a_new_team/world.py\", line 310, in step\n    raise ValueError(\nValueError: [INVALID:STEP] Not a valid step from [2 2] to [2 2] and put barrier at 0, with max steps = 4\n\nExecute Random Walk!\nAn exception raised. The traceback is as follows:\nTraceback (most recent call last):\n  File \"/home/ml/users/ksinha4/mlp/comp424_final_project/submissions/comp424mcgill/final-project-a_new_team/world.py\", line 310, in step\n    raise ValueError(\nValueError: [INVALID:STEP] Not a valid step from [3 1] to [3 1] and put barrier at 0, with max steps = 4\n\nExecute Random Walk!\nAn exception raised. The traceback is as follows:\nTraceback (most recent call last):\n  File \"/home/ml/users/ksinha4/mlp/comp424_final_project/submissions/comp424mcgill/final-project-a_new_team/world.py\", line 310, in step\n    raise ValueError(\nValueError: [INVALID:STEP] Not a valid step from [3 0] to [3 0] and put barrier at 0, with max steps = 4\n\nExecute Random Walk!\nAn exception raised. The traceback is as follows:\nTraceback (most recent call last):\n  File \"/home/ml/users/ksinha4/mlp/comp424_final_project/submissions/comp424mcgill/final-project-a_new_team/world.py\", line 310, in step\n    raise ValueError(\nValueError: [INVALID:STEP] Not a valid step from [6 1] to [6 1] and put barrier at 0, with max steps = 4\n\nExecute Random Walk!\n"}, {"student_agent_score": 1, "random_agent_score": 35, "student_agent_time": 0.0017871856689453125, "random_agent_time": 0.0016286373138427734, "board_size": 6, "swap_players": true, "run_out": "An exception raised. The traceback is as follows:\nTraceback (most recent call last):\n  File \"/home/ml/users/ksinha4/mlp/comp424_final_project/submissions/comp424mcgill/final-project-a_new_team/world.py\", line 310, in step\n    raise ValueError(\nValueError: [INVALID:STEP] Not a valid step from [3 3] to [3 3] and put barrier at 0, with max steps = 3\n\nExecute Random Walk!\nAn exception raised. The traceback is as follows:\nTraceback (most recent call last):\n  File \"/home/ml/users/ksinha4/mlp/comp424_final_project/submissions/comp424mcgill/final-project-a_new_team/world.py\", line 310, in step\n    raise ValueError(\nValueError: [INVALID:STEP] Not a valid step from [3 3] to [3 3] and put barrier at 0, with max steps = 3\n\nExecute Random Walk!\n"}, {"student_agent_score": 1, "random_agent_score": 48, "student_agent_time": 0.0028231143951416016, "random_agent_time": 0.0026273727416992188, "board_size": 7, "swap_players": true, "run_out": "An exception raised. The traceback is as follows:\nTraceback (most recent call last):\n  File \"/home/ml/users/ksinha4/mlp/comp424_final_project/submissions/comp424mcgill/final-project-a_new_team/world.py\", line 310, in step\n    raise ValueError(\nValueError: [INVALID:STEP] Not a valid step from [2 3] to [2 3] and put barrier at 0, with max steps = 4\n\nExecute Random Walk!\nAn exception raised. The traceback is as follows:\nTraceback (most recent call last):\n  File \"/home/ml/users/ksinha4/mlp/comp424_final_project/submissions/comp424mcgill/final-project-a_new_team/world.py\", line 310, in step\n    raise ValueError(\nValueError: [INVALID:STEP] Not a valid step from [5 4] to [5 4] and put barrier at 0, with max steps = 4\n\nExecute Random Walk!\nAn exception raised. The traceback is as follows:\nTraceback (most recent call last):\n  File \"/home/ml/users/ksinha4/mlp/comp424_final_project/submissions/comp424mcgill/final-project-a_new_team/world.py\", line 310, in step\n    raise ValueError(\nValueError: [INVALID:STEP] Not a valid step from [6 3] to [6 3] and put barrier at 0, with max steps = 4\n\nExecute Random Walk!\n"}, {"student_agent_score": 1, "random_agent_score": 48, "student_agent_time": 0.0038857460021972656, "random_agent_time": 0.003220796585083008, "board_size": 7, "swap_players": false, "run_out": "An exception raised. The traceback is as follows:\nTraceback (most recent call last):\n  File \"/home/ml/users/ksinha4/mlp/comp424_final_project/submissions/comp424mcgill/final-project-a_new_team/world.py\", line 310, in step\n    raise ValueError(\nValueError: [INVALID:STEP] Not a valid step from [4 3] to [4 3] and put barrier at 0, with max steps = 4\n\nExecute Random Walk!\nAn exception raised. The traceback is as follows:\nTraceback (most recent call last):\n  File \"/home/ml/users/ksinha4/mlp/comp424_final_project/submissions/comp424mcgill/final-project-a_new_team/world.py\", line 310, in step\n    raise ValueError(\nValueError: [INVALID:STEP] Not a valid step from [4 2] to [4 2] and put barrier at 0, with max steps = 4\n\nExecute Random Walk!\nAn exception raised. The traceback is as follows:\nTraceback (most recent call last):\n  File \"/home/ml/users/ksinha4/mlp/comp424_final_project/submissions/comp424mcgill/final-project-a_new_team/world.py\", line 310, in step\n    raise ValueError(\nValueError: [INVALID:STEP] Not a valid step from [4 3] to [4 3] and put barrier at 0, with max steps = 4\n\nExecute Random Walk!\nAn exception raised. The traceback is as follows:\nTraceback (most recent call last):\n  File \"/home/ml/users/ksinha4/mlp/comp424_final_project/submissions/comp424mcgill/final-project-a_new_team/world.py\", line 310, in step\n    raise ValueError(\nValueError: [INVALID:STEP] Not a valid step from [5 4] to [5 4] and put barrier at 0, with max steps = 4\n\nExecute Random Walk!\nAn exception raised. The traceback is as follows:\nTraceback (most recent call last):\n  File \"/home/ml/users/ksinha4/mlp/comp424_final_project/submissions/comp424mcgill/final-project-a_new_team/world.py\", line 310, in step\n    raise ValueError(\nValueError: [INVALID:STEP] Not a valid step from [6 3] to [6 3] and put barrier at 0, with max steps = 4\n\nExecute Random Walk!\n"}, {"student_agent_score": 1, "random_agent_score": 48, "student_agent_time": 0.004049062728881836, "random_agent_time": 0.002112150192260742, "board_size": 7, "swap_players": false, "run_out": "An exception raised. The traceback is as follows:\nTraceback (most recent call last):\n  File \"/home/ml/users/ksinha4/mlp/comp424_final_project/submissions/comp424mcgill/final-project-a_new_team/world.py\", line 310, in step\n    raise ValueError(\nValueError: [INVALID:STEP] Not a valid step from [4 3] to [4 3] and put barrier at 0, with max steps = 4\n\nExecute Random Walk!\nAn exception raised. The traceback is as follows:\nTraceback (most recent call last):\n  File \"/home/ml/users/ksinha4/mlp/comp424_final_project/submissions/comp424mcgill/final-project-a_new_team/world.py\", line 310, in step\n    raise ValueError(\nValueError: [INVALID:STEP] Not a valid step from [4 2] to [4 2] and put barrier at 0, with max steps = 4\n\nExecute Random Walk!\nAn exception raised. The traceback is as follows:\nTraceback (most recent call last):\n  File \"/home/ml/users/ksinha4/mlp/comp424_final_project/submissions/comp424mcgill/final-project-a_new_team/world.py\", line 310, in step\n    raise ValueError(\nValueError: [INVALID:STEP] Not a valid step from [4 3] to [4 3] and put barrier at 0, with max steps = 4\n\nExecute Random Walk!\nAn exception raised. The traceback is as follows:\nTraceback (most recent call last):\n  File \"/home/ml/users/ksinha4/mlp/comp424_final_project/submissions/comp424mcgill/final-project-a_new_team/world.py\", line 310, in step\n    raise ValueError(\nValueError: [INVALID:STEP] Not a valid step from [5 4] to [5 4] and put barrier at 0, with max steps = 4\n\nExecute Random Walk!\nAn exception raised. The traceback is as follows:\nTraceback (most recent call last):\n  File \"/home/ml/users/ksinha4/mlp/comp424_final_project/submissions/comp424mcgill/final-project-a_new_team/world.py\", line 310, in step\n    raise ValueError(\nValueError: [INVALID:STEP] Not a valid step from [6 3] to [6 3] and put barrier at 0, with max steps = 4\n\nExecute Random Walk!\n"}, {"student_agent_score": 80, "random_agent_score": 1, "student_agent_time": 0.0070874691009521484, "random_agent_time": 0.004884004592895508, "board_size": 9, "swap_players": true, "run_out": "An exception raised. The traceback is as follows:\nTraceback (most recent call last):\n  File \"/home/ml/users/ksinha4/mlp/comp424_final_project/submissions/comp424mcgill/final-project-a_new_team/world.py\", line 310, in step\n    raise ValueError(\nValueError: [INVALID:STEP] Not a valid step from [3 4] to [3 4] and put barrier at 0, with max steps = 5\n\nExecute Random Walk!\nAn exception raised. The traceback is as follows:\nTraceback (most recent call last):\n  File \"/home/ml/users/ksinha4/mlp/comp424_final_project/submissions/comp424mcgill/final-project-a_new_team/world.py\", line 310, in step\n    raise ValueError(\nValueError: [INVALID:STEP] Not a valid step from [3 5] to [3 5] and put barrier at 0, with max steps = 5\n\nExecute Random Walk!\nAn exception raised. The traceback is as follows:\nTraceback (most recent call last):\n  File \"/home/ml/users/ksinha4/mlp/comp424_final_project/submissions/comp424mcgill/final-project-a_new_team/world.py\", line 310, in step\n    raise ValueError(\nValueError: [INVALID:STEP] Not a valid step from [3 4] to [3 4] and put barrier at 0, with max steps = 5\n\nExecute Random Walk!\nAn exception raised. The traceback is as follows:\nTraceback (most recent call last):\n  File \"/home/ml/users/ksinha4/mlp/comp424_final_project/submissions/comp424mcgill/final-project-a_new_team/world.py\", line 310, in step\n    raise ValueError(\nValueError: [INVALID:STEP] Not a valid step from [5 4] to [5 4] and put barrier at 0, with max steps = 5\n\nExecute Random Walk!\nAn exception raised. The traceback is as follows:\nTraceback (most recent call last):\n  File \"/home/ml/users/ksinha4/mlp/comp424_final_project/submissions/comp424mcgill/final-project-a_new_team/world.py\", line 310, in step\n    raise ValueError(\nValueError: [INVALID:STEP] Not a valid step from [5 5] to [5 5] and put barrier at 0, with max steps = 5\n\nExecute Random Walk!\n"}, {"student_agent_score": 1, "random_agent_score": 48, "student_agent_time": 0.0031723976135253906, "random_agent_time": 0.002314329147338867, "board_size": 7, "swap_players": true, "run_out": "An exception raised. The traceback is as follows:\nTraceback (most recent call last):\n  File \"/home/ml/users/ksinha4/mlp/comp424_final_project/submissions/comp424mcgill/final-project-a_new_team/world.py\", line 310, in step\n    raise ValueError(\nValueError: [INVALID:STEP] Not a valid step from [2 3] to [2 3] and put barrier at 0, with max steps = 4\n\nExecute Random Walk!\nAn exception raised. The traceback is as follows:\nTraceback (most recent call last):\n  File \"/home/ml/users/ksinha4/mlp/comp424_final_project/submissions/comp424mcgill/final-project-a_new_team/world.py\", line 310, in step\n    raise ValueError(\nValueError: [INVALID:STEP] Not a valid step from [5 4] to [5 4] and put barrier at 0, with max steps = 4\n\nExecute Random Walk!\nAn exception raised. The traceback is as follows:\nTraceback (most recent call last):\n  File \"/home/ml/users/ksinha4/mlp/comp424_final_project/submissions/comp424mcgill/final-project-a_new_team/world.py\", line 310, in step\n    raise ValueError(\nValueError: [INVALID:STEP] Not a valid step from [6 3] to [6 3] and put barrier at 0, with max steps = 4\n\nExecute Random Walk!\n"}, {"student_agent_score": 1, "random_agent_score": 48, "student_agent_time": 0.003657102584838867, "random_agent_time": 0.001977682113647461, "board_size": 7, "swap_players": false, "run_out": "An exception raised. The traceback is as follows:\nTraceback (most recent call last):\n  File \"/home/ml/users/ksinha4/mlp/comp424_final_project/submissions/comp424mcgill/final-project-a_new_team/world.py\", line 310, in step\n    raise ValueError(\nValueError: [INVALID:STEP] Not a valid step from [4 3] to [4 3] and put barrier at 0, with max steps = 4\n\nExecute Random Walk!\nAn exception raised. The traceback is as follows:\nTraceback (most recent call last):\n  File \"/home/ml/users/ksinha4/mlp/comp424_final_project/submissions/comp424mcgill/final-project-a_new_team/world.py\", line 310, in step\n    raise ValueError(\nValueError: [INVALID:STEP] Not a valid step from [4 2] to [4 2] and put barrier at 0, with max steps = 4\n\nExecute Random Walk!\nAn exception raised. The traceback is as follows:\nTraceback (most recent call last):\n  File \"/home/ml/users/ksinha4/mlp/comp424_final_project/submissions/comp424mcgill/final-project-a_new_team/world.py\", line 310, in step\n    raise ValueError(\nValueError: [INVALID:STEP] Not a valid step from [4 3] to [4 3] and put barrier at 0, with max steps = 4\n\nExecute Random Walk!\nAn exception raised. The traceback is as follows:\nTraceback (most recent call last):\n  File \"/home/ml/users/ksinha4/mlp/comp424_final_project/submissions/comp424mcgill/final-project-a_new_team/world.py\", line 310, in step\n    raise ValueError(\nValueError: [INVALID:STEP] Not a valid step from [5 4] to [5 4] and put barrier at 0, with max steps = 4\n\nExecute Random Walk!\nAn exception raised. The traceback is as follows:\nTraceback (most recent call last):\n  File \"/home/ml/users/ksinha4/mlp/comp424_final_project/submissions/comp424mcgill/final-project-a_new_team/world.py\", line 310, in step\n    raise ValueError(\nValueError: [INVALID:STEP] Not a valid step from [6 3] to [6 3] and put barrier at 0, with max steps = 4\n\nExecute Random Walk!\n"}, {"student_agent_score": 117, "random_agent_score": 1, "student_agent_time": 0.008401870727539062, "random_agent_time": 0.009540796279907227, "board_size": 11, "swap_players": false, "run_out": "An exception raised. The traceback is as follows:\nTraceback (most recent call last):\n  File \"/home/ml/users/ksinha4/mlp/comp424_final_project/submissions/comp424mcgill/final-project-a_new_team/world.py\", line 310, in step\n    raise ValueError(\nValueError: [INVALID:STEP] Not a valid step from [1 7] to [1 7] and put barrier at 0, with max steps = 6\n\nExecute Random Walk!\nAn exception raised. The traceback is as follows:\nTraceback (most recent call last):\n  File \"/home/ml/users/ksinha4/mlp/comp424_final_project/submissions/comp424mcgill/final-project-a_new_team/world.py\", line 310, in step\n    raise ValueError(\nValueError: [INVALID:STEP] Not a valid step from [1 8] to [1 8] and put barrier at 0, with max steps = 6\n\nExecute Random Walk!\nAn exception raised. The traceback is as follows:\nTraceback (most recent call last):\n  File \"/home/ml/users/ksinha4/mlp/comp424_final_project/submissions/comp424mcgill/final-project-a_new_team/world.py\", line 310, in step\n    raise ValueError(\nValueError: [INVALID:STEP] Not a valid step from [1 6] to [1 6] and put barrier at 0, with max steps = 6\n\nExecute Random Walk!\nAn exception raised. The traceback is as follows:\nTraceback (most recent call last):\n  File \"/home/ml/users/ksinha4/mlp/comp424_final_project/submissions/comp424mcgill/final-project-a_new_team/world.py\", line 310, in step\n    raise ValueError(\nValueError: [INVALID:STEP] Not a valid step from [3 3] to [3 3] and put barrier at 0, with max steps = 6\n\nExecute Random Walk!\nAn exception raised. The traceback is as follows:\nTraceback (most recent call last):\n  File \"/home/ml/users/ksinha4/mlp/comp424_final_project/submissions/comp424mcgill/final-project-a_new_team/world.py\", line 310, in step\n    raise ValueError(\nValueError: [INVALID:STEP] Not a valid step from [3 4] to [3 4] and put barrier at 0, with max steps = 6\n\nExecute Random Walk!\nAn exception raised. The traceback is as follows:\nTraceback (most recent call last):\n  File \"/home/ml/users/ksinha4/mlp/comp424_final_project/submissions/comp424mcgill/final-project-a_new_team/world.py\", line 310, in step\n    raise ValueError(\nValueError: [INVALID:STEP] Not a valid step from [3 4] to [3 4] and put barrier at 0, with max steps = 6\n\nExecute Random Walk!\nAn exception raised. The traceback is as follows:\nTraceback (most recent call last):\n  File \"/home/ml/users/ksinha4/mlp/comp424_final_project/submissions/comp424mcgill/final-project-a_new_team/world.py\", line 310, in step\n    raise ValueError(\nValueError: [INVALID:STEP] Not a valid step from [4 4] to [4 4] and put barrier at 0, with max steps = 6\n\nExecute Random Walk!\nAn exception raised. The traceback is as follows:\nTraceback (most recent call last):\n  File \"/home/ml/users/ksinha4/mlp/comp424_final_project/submissions/comp424mcgill/final-project-a_new_team/world.py\", line 310, in step\n    raise ValueError(\nValueError: [INVALID:STEP] Not a valid step from [4 4] to [4 4] and put barrier at 0, with max steps = 6\n\nExecute Random Walk!\n"}, {"student_agent_score": 120, "random_agent_score": 1, "student_agent_time": 0.0030510425567626953, "random_agent_time": 0.003012418746948242, "board_size": 11, "swap_players": true, "run_out": "An exception raised. The traceback is as follows:\nTraceback (most recent call last):\n  File \"/home/ml/users/ksinha4/mlp/comp424_final_project/submissions/comp424mcgill/final-project-a_new_team/world.py\", line 310, in step\n    raise ValueError(\nValueError: [INVALID:STEP] Not a valid step from [9 3] to [9 3] and put barrier at 0, with max steps = 6\n\nExecute Random Walk!\nAn exception raised. The traceback is as follows:\nTraceback (most recent call last):\n  File \"/home/ml/users/ksinha4/mlp/comp424_final_project/submissions/comp424mcgill/final-project-a_new_team/world.py\", line 310, in step\n    raise ValueError(\nValueError: [INVALID:STEP] Not a valid step from [9 3] to [9 3] and put barrier at 0, with max steps = 6\n\nExecute Random Walk!\n"}, {"student_agent_score": 1, "random_agent_score": 48, "student_agent_time": 0.005984783172607422, "random_agent_time": 0.0021004676818847656, "board_size": 7, "swap_players": false, "run_out": "An exception raised. The traceback is as follows:\nTraceback (most recent call last):\n  File \"/home/ml/users/ksinha4/mlp/comp424_final_project/submissions/comp424mcgill/final-project-a_new_team/world.py\", line 310, in step\n    raise ValueError(\nValueError: [INVALID:STEP] Not a valid step from [4 3] to [4 3] and put barrier at 0, with max steps = 4\n\nExecute Random Walk!\nAn exception raised. The traceback is as follows:\nTraceback (most recent call last):\n  File \"/home/ml/users/ksinha4/mlp/comp424_final_project/submissions/comp424mcgill/final-project-a_new_team/world.py\", line 310, in step\n    raise ValueError(\nValueError: [INVALID:STEP] Not a valid step from [4 2] to [4 2] and put barrier at 0, with max steps = 4\n\nExecute Random Walk!\nAn exception raised. The traceback is as follows:\nTraceback (most recent call last):\n  File \"/home/ml/users/ksinha4/mlp/comp424_final_project/submissions/comp424mcgill/final-project-a_new_team/world.py\", line 310, in step\n    raise ValueError(\nValueError: [INVALID:STEP] Not a valid step from [4 3] to [4 3] and put barrier at 0, with max steps = 4\n\nExecute Random Walk!\nAn exception raised. The traceback is as follows:\nTraceback (most recent call last):\n  File \"/home/ml/users/ksinha4/mlp/comp424_final_project/submissions/comp424mcgill/final-project-a_new_team/world.py\", line 310, in step\n    raise ValueError(\nValueError: [INVALID:STEP] Not a valid step from [5 4] to [5 4] and put barrier at 0, with max steps = 4\n\nExecute Random Walk!\nAn exception raised. The traceback is as follows:\nTraceback (most recent call last):\n  File \"/home/ml/users/ksinha4/mlp/comp424_final_project/submissions/comp424mcgill/final-project-a_new_team/world.py\", line 310, in step\n    raise ValueError(\nValueError: [INVALID:STEP] Not a valid step from [6 3] to [6 3] and put barrier at 0, with max steps = 4\n\nExecute Random Walk!\n"}, {"student_agent_score": 2, "random_agent_score": 98, "student_agent_time": 0.0038366317749023438, "random_agent_time": 0.004547595977783203, "board_size": 10, "swap_players": false, "run_out": "An exception raised. The traceback is as follows:\nTraceback (most recent call last):\n  File \"/home/ml/users/ksinha4/mlp/comp424_final_project/submissions/comp424mcgill/final-project-a_new_team/world.py\", line 310, in step\n    raise ValueError(\nValueError: [INVALID:STEP] Not a valid step from [7 5] to [7 5] and put barrier at 0, with max steps = 5\n\nExecute Random Walk!\nAn exception raised. The traceback is as follows:\nTraceback (most recent call last):\n  File \"/home/ml/users/ksinha4/mlp/comp424_final_project/submissions/comp424mcgill/final-project-a_new_team/world.py\", line 310, in step\n    raise ValueError(\nValueError: [INVALID:STEP] Not a valid step from [6 6] to [6 6] and put barrier at 0, with max steps = 5\n\nExecute Random Walk!\nAn exception raised. The traceback is as follows:\nTraceback (most recent call last):\n  File \"/home/ml/users/ksinha4/mlp/comp424_final_project/submissions/comp424mcgill/final-project-a_new_team/world.py\", line 310, in step\n    raise ValueError(\nValueError: [INVALID:STEP] Not a valid step from [7 8] to [7 8] and put barrier at 0, with max steps = 5\n\nExecute Random Walk!\nAn exception raised. The traceback is as follows:\nTraceback (most recent call last):\n  File \"/home/ml/users/ksinha4/mlp/comp424_final_project/submissions/comp424mcgill/final-project-a_new_team/world.py\", line 310, in step\n    raise ValueError(\nValueError: [INVALID:STEP] Not a valid step from [7 8] to [7 8] and put barrier at 0, with max steps = 5\n\nExecute Random Walk!\n"}, {"student_agent_score": 1, "random_agent_score": 35, "student_agent_time": 0.001665353775024414, "random_agent_time": 0.0007240772247314453, "board_size": 6, "swap_players": false, "run_out": "An exception raised. The traceback is as follows:\nTraceback (most recent call last):\n  File \"/home/ml/users/ksinha4/mlp/comp424_final_project/submissions/comp424mcgill/final-project-a_new_team/world.py\", line 310, in step\n    raise ValueError(\nValueError: [INVALID:STEP] Not a valid step from [2 2] to [2 2] and put barrier at 0, with max steps = 3\n\nExecute Random Walk!\nAn exception raised. The traceback is as follows:\nTraceback (most recent call last):\n  File \"/home/ml/users/ksinha4/mlp/comp424_final_project/submissions/comp424mcgill/final-project-a_new_team/world.py\", line 310, in step\n    raise ValueError(\nValueError: [INVALID:STEP] Not a valid step from [3 0] to [3 0] and put barrier at 0, with max steps = 3\n\nExecute Random Walk!\n"}, {"student_agent_score": 80, "random_agent_score": 1, "student_agent_time": 0.00480198860168457, "random_agent_time": 0.00532984733581543, "board_size": 9, "swap_players": true, "run_out": "An exception raised. The traceback is as follows:\nTraceback (most recent call last):\n  File \"/home/ml/users/ksinha4/mlp/comp424_final_project/submissions/comp424mcgill/final-project-a_new_team/world.py\", line 310, in step\n    raise ValueError(\nValueError: [INVALID:STEP] Not a valid step from [3 4] to [3 4] and put barrier at 0, with max steps = 5\n\nExecute Random Walk!\nAn exception raised. The traceback is as follows:\nTraceback (most recent call last):\n  File \"/home/ml/users/ksinha4/mlp/comp424_final_project/submissions/comp424mcgill/final-project-a_new_team/world.py\", line 310, in step\n    raise ValueError(\nValueError: [INVALID:STEP] Not a valid step from [3 5] to [3 5] and put barrier at 0, with max steps = 5\n\nExecute Random Walk!\nAn exception raised. The traceback is as follows:\nTraceback (most recent call last):\n  File \"/home/ml/users/ksinha4/mlp/comp424_final_project/submissions/comp424mcgill/final-project-a_new_team/world.py\", line 310, in step\n    raise ValueError(\nValueError: [INVALID:STEP] Not a valid step from [3 4] to [3 4] and put barrier at 0, with max steps = 5\n\nExecute Random Walk!\nAn exception raised. The traceback is as follows:\nTraceback (most recent call last):\n  File \"/home/ml/users/ksinha4/mlp/comp424_final_project/submissions/comp424mcgill/final-project-a_new_team/world.py\", line 310, in step\n    raise ValueError(\nValueError: [INVALID:STEP] Not a valid step from [5 4] to [5 4] and put barrier at 0, with max steps = 5\n\nExecute Random Walk!\nAn exception raised. The traceback is as follows:\nTraceback (most recent call last):\n  File \"/home/ml/users/ksinha4/mlp/comp424_final_project/submissions/comp424mcgill/final-project-a_new_team/world.py\", line 310, in step\n    raise ValueError(\nValueError: [INVALID:STEP] Not a valid step from [5 5] to [5 5] and put barrier at 0, with max steps = 5\n\nExecute Random Walk!\n"}, {"student_agent_score": 1, "random_agent_score": 48, "student_agent_time": 0.003000974655151367, "random_agent_time": 0.0024683475494384766, "board_size": 7, "swap_players": true, "run_out": "An exception raised. The traceback is as follows:\nTraceback (most recent call last):\n  File \"/home/ml/users/ksinha4/mlp/comp424_final_project/submissions/comp424mcgill/final-project-a_new_team/world.py\", line 310, in step\n    raise ValueError(\nValueError: [INVALID:STEP] Not a valid step from [2 3] to [2 3] and put barrier at 0, with max steps = 4\n\nExecute Random Walk!\nAn exception raised. The traceback is as follows:\nTraceback (most recent call last):\n  File \"/home/ml/users/ksinha4/mlp/comp424_final_project/submissions/comp424mcgill/final-project-a_new_team/world.py\", line 310, in step\n    raise ValueError(\nValueError: [INVALID:STEP] Not a valid step from [5 4] to [5 4] and put barrier at 0, with max steps = 4\n\nExecute Random Walk!\nAn exception raised. The traceback is as follows:\nTraceback (most recent call last):\n  File \"/home/ml/users/ksinha4/mlp/comp424_final_project/submissions/comp424mcgill/final-project-a_new_team/world.py\", line 310, in step\n    raise ValueError(\nValueError: [INVALID:STEP] Not a valid step from [6 3] to [6 3] and put barrier at 0, with max steps = 4\n\nExecute Random Walk!\n"}, {"student_agent_score": 117, "random_agent_score": 1, "student_agent_time": 0.008295059204101562, "random_agent_time": 0.007918357849121094, "board_size": 11, "swap_players": false, "run_out": "An exception raised. The traceback is as follows:\nTraceback (most recent call last):\n  File \"/home/ml/users/ksinha4/mlp/comp424_final_project/submissions/comp424mcgill/final-project-a_new_team/world.py\", line 310, in step\n    raise ValueError(\nValueError: [INVALID:STEP] Not a valid step from [1 7] to [1 7] and put barrier at 0, with max steps = 6\n\nExecute Random Walk!\nAn exception raised. The traceback is as follows:\nTraceback (most recent call last):\n  File \"/home/ml/users/ksinha4/mlp/comp424_final_project/submissions/comp424mcgill/final-project-a_new_team/world.py\", line 310, in step\n    raise ValueError(\nValueError: [INVALID:STEP] Not a valid step from [1 8] to [1 8] and put barrier at 0, with max steps = 6\n\nExecute Random Walk!\nAn exception raised. The traceback is as follows:\nTraceback (most recent call last):\n  File \"/home/ml/users/ksinha4/mlp/comp424_final_project/submissions/comp424mcgill/final-project-a_new_team/world.py\", line 310, in step\n    raise ValueError(\nValueError: [INVALID:STEP] Not a valid step from [1 6] to [1 6] and put barrier at 0, with max steps = 6\n\nExecute Random Walk!\nAn exception raised. The traceback is as follows:\nTraceback (most recent call last):\n  File \"/home/ml/users/ksinha4/mlp/comp424_final_project/submissions/comp424mcgill/final-project-a_new_team/world.py\", line 310, in step\n    raise ValueError(\nValueError: [INVALID:STEP] Not a valid step from [3 3] to [3 3] and put barrier at 0, with max steps = 6\n\nExecute Random Walk!\nAn exception raised. The traceback is as follows:\nTraceback (most recent call last):\n  File \"/home/ml/users/ksinha4/mlp/comp424_final_project/submissions/comp424mcgill/final-project-a_new_team/world.py\", line 310, in step\n    raise ValueError(\nValueError: [INVALID:STEP] Not a valid step from [3 4] to [3 4] and put barrier at 0, with max steps = 6\n\nExecute Random Walk!\nAn exception raised. The traceback is as follows:\nTraceback (most recent call last):\n  File \"/home/ml/users/ksinha4/mlp/comp424_final_project/submissions/comp424mcgill/final-project-a_new_team/world.py\", line 310, in step\n    raise ValueError(\nValueError: [INVALID:STEP] Not a valid step from [3 4] to [3 4] and put barrier at 0, with max steps = 6\n\nExecute Random Walk!\nAn exception raised. The traceback is as follows:\nTraceback (most recent call last):\n  File \"/home/ml/users/ksinha4/mlp/comp424_final_project/submissions/comp424mcgill/final-project-a_new_team/world.py\", line 310, in step\n    raise ValueError(\nValueError: [INVALID:STEP] Not a valid step from [4 4] to [4 4] and put barrier at 0, with max steps = 6\n\nExecute Random Walk!\nAn exception raised. The traceback is as follows:\nTraceback (most recent call last):\n  File \"/home/ml/users/ksinha4/mlp/comp424_final_project/submissions/comp424mcgill/final-project-a_new_team/world.py\", line 310, in step\n    raise ValueError(\nValueError: [INVALID:STEP] Not a valid step from [4 4] to [4 4] and put barrier at 0, with max steps = 6\n\nExecute Random Walk!\n"}, {"student_agent_score": 1, "random_agent_score": 48, "student_agent_time": 0.003635406494140625, "random_agent_time": 0.0049054622650146484, "board_size": 7, "swap_players": false, "run_out": "An exception raised. The traceback is as follows:\nTraceback (most recent call last):\n  File \"/home/ml/users/ksinha4/mlp/comp424_final_project/submissions/comp424mcgill/final-project-a_new_team/world.py\", line 310, in step\n    raise ValueError(\nValueError: [INVALID:STEP] Not a valid step from [4 3] to [4 3] and put barrier at 0, with max steps = 4\n\nExecute Random Walk!\nAn exception raised. The traceback is as follows:\nTraceback (most recent call last):\n  File \"/home/ml/users/ksinha4/mlp/comp424_final_project/submissions/comp424mcgill/final-project-a_new_team/world.py\", line 310, in step\n    raise ValueError(\nValueError: [INVALID:STEP] Not a valid step from [4 2] to [4 2] and put barrier at 0, with max steps = 4\n\nExecute Random Walk!\nAn exception raised. The traceback is as follows:\nTraceback (most recent call last):\n  File \"/home/ml/users/ksinha4/mlp/comp424_final_project/submissions/comp424mcgill/final-project-a_new_team/world.py\", line 310, in step\n    raise ValueError(\nValueError: [INVALID:STEP] Not a valid step from [4 3] to [4 3] and put barrier at 0, with max steps = 4\n\nExecute Random Walk!\nAn exception raised. The traceback is as follows:\nTraceback (most recent call last):\n  File \"/home/ml/users/ksinha4/mlp/comp424_final_project/submissions/comp424mcgill/final-project-a_new_team/world.py\", line 310, in step\n    raise ValueError(\nValueError: [INVALID:STEP] Not a valid step from [5 4] to [5 4] and put barrier at 0, with max steps = 4\n\nExecute Random Walk!\nAn exception raised. The traceback is as follows:\nTraceback (most recent call last):\n  File \"/home/ml/users/ksinha4/mlp/comp424_final_project/submissions/comp424mcgill/final-project-a_new_team/world.py\", line 310, in step\n    raise ValueError(\nValueError: [INVALID:STEP] Not a valid step from [6 3] to [6 3] and put barrier at 0, with max steps = 4\n\nExecute Random Walk!\n"}, {"student_agent_score": 1, "random_agent_score": 63, "student_agent_time": 0.0036172866821289062, "random_agent_time": 0.001934051513671875, "board_size": 8, "swap_players": false, "run_out": "An exception raised. The traceback is as follows:\nTraceback (most recent call last):\n  File \"/home/ml/users/ksinha4/mlp/comp424_final_project/submissions/comp424mcgill/final-project-a_new_team/world.py\", line 310, in step\n    raise ValueError(\nValueError: [INVALID:STEP] Not a valid step from [2 2] to [2 2] and put barrier at 0, with max steps = 4\n\nExecute Random Walk!\nAn exception raised. The traceback is as follows:\nTraceback (most recent call last):\n  File \"/home/ml/users/ksinha4/mlp/comp424_final_project/submissions/comp424mcgill/final-project-a_new_team/world.py\", line 310, in step\n    raise ValueError(\nValueError: [INVALID:STEP] Not a valid step from [3 1] to [3 1] and put barrier at 0, with max steps = 4\n\nExecute Random Walk!\nAn exception raised. The traceback is as follows:\nTraceback (most recent call last):\n  File \"/home/ml/users/ksinha4/mlp/comp424_final_project/submissions/comp424mcgill/final-project-a_new_team/world.py\", line 310, in step\n    raise ValueError(\nValueError: [INVALID:STEP] Not a valid step from [3 0] to [3 0] and put barrier at 0, with max steps = 4\n\nExecute Random Walk!\nAn exception raised. The traceback is as follows:\nTraceback (most recent call last):\n  File \"/home/ml/users/ksinha4/mlp/comp424_final_project/submissions/comp424mcgill/final-project-a_new_team/world.py\", line 310, in step\n    raise ValueError(\nValueError: [INVALID:STEP] Not a valid step from [6 1] to [6 1] and put barrier at 0, with max steps = 4\n\nExecute Random Walk!\n"}, {"student_agent_score": 63, "random_agent_score": 1, "student_agent_time": 0.0028951168060302734, "random_agent_time": 0.002471923828125, "board_size": 8, "swap_players": true, "run_out": "An exception raised. The traceback is as follows:\nTraceback (most recent call last):\n  File \"/home/ml/users/ksinha4/mlp/comp424_final_project/submissions/comp424mcgill/final-project-a_new_team/world.py\", line 310, in step\n    raise ValueError(\nValueError: [INVALID:STEP] Not a valid step from [5 5] to [5 5] and put barrier at 0, with max steps = 4\n\nExecute Random Walk!\nAn exception raised. The traceback is as follows:\nTraceback (most recent call last):\n  File \"/home/ml/users/ksinha4/mlp/comp424_final_project/submissions/comp424mcgill/final-project-a_new_team/world.py\", line 310, in step\n    raise ValueError(\nValueError: [INVALID:STEP] Not a valid step from [5 4] to [5 4] and put barrier at 0, with max steps = 4\n\nExecute Random Walk!\nAn exception raised. The traceback is as follows:\nTraceback (most recent call last):\n  File \"/home/ml/users/ksinha4/mlp/comp424_final_project/submissions/comp424mcgill/final-project-a_new_team/world.py\", line 310, in step\n    raise ValueError(\nValueError: [INVALID:STEP] Not a valid step from [5 4] to [5 4] and put barrier at 0, with max steps = 4\n\nExecute Random Walk!\n"}, {"student_agent_score": 80, "random_agent_score": 1, "student_agent_time": 0.0049707889556884766, "random_agent_time": 0.006988048553466797, "board_size": 9, "swap_players": true, "run_out": "An exception raised. The traceback is as follows:\nTraceback (most recent call last):\n  File \"/home/ml/users/ksinha4/mlp/comp424_final_project/submissions/comp424mcgill/final-project-a_new_team/world.py\", line 310, in step\n    raise ValueError(\nValueError: [INVALID:STEP] Not a valid step from [3 4] to [3 4] and put barrier at 0, with max steps = 5\n\nExecute Random Walk!\nAn exception raised. The traceback is as follows:\nTraceback (most recent call last):\n  File \"/home/ml/users/ksinha4/mlp/comp424_final_project/submissions/comp424mcgill/final-project-a_new_team/world.py\", line 310, in step\n    raise ValueError(\nValueError: [INVALID:STEP] Not a valid step from [3 5] to [3 5] and put barrier at 0, with max steps = 5\n\nExecute Random Walk!\nAn exception raised. The traceback is as follows:\nTraceback (most recent call last):\n  File \"/home/ml/users/ksinha4/mlp/comp424_final_project/submissions/comp424mcgill/final-project-a_new_team/world.py\", line 310, in step\n    raise ValueError(\nValueError: [INVALID:STEP] Not a valid step from [3 4] to [3 4] and put barrier at 0, with max steps = 5\n\nExecute Random Walk!\nAn exception raised. The traceback is as follows:\nTraceback (most recent call last):\n  File \"/home/ml/users/ksinha4/mlp/comp424_final_project/submissions/comp424mcgill/final-project-a_new_team/world.py\", line 310, in step\n    raise ValueError(\nValueError: [INVALID:STEP] Not a valid step from [5 4] to [5 4] and put barrier at 0, with max steps = 5\n\nExecute Random Walk!\nAn exception raised. The traceback is as follows:\nTraceback (most recent call last):\n  File \"/home/ml/users/ksinha4/mlp/comp424_final_project/submissions/comp424mcgill/final-project-a_new_team/world.py\", line 310, in step\n    raise ValueError(\nValueError: [INVALID:STEP] Not a valid step from [5 5] to [5 5] and put barrier at 0, with max steps = 5\n\nExecute Random Walk!\n"}, {"student_agent_score": 1, "random_agent_score": 35, "student_agent_time": 0.0027992725372314453, "random_agent_time": 0.0019426345825195312, "board_size": 6, "swap_players": true, "run_out": "An exception raised. The traceback is as follows:\nTraceback (most recent call last):\n  File \"/home/ml/users/ksinha4/mlp/comp424_final_project/submissions/comp424mcgill/final-project-a_new_team/world.py\", line 310, in step\n    raise ValueError(\nValueError: [INVALID:STEP] Not a valid step from [3 3] to [3 3] and put barrier at 0, with max steps = 3\n\nExecute Random Walk!\nAn exception raised. The traceback is as follows:\nTraceback (most recent call last):\n  File \"/home/ml/users/ksinha4/mlp/comp424_final_project/submissions/comp424mcgill/final-project-a_new_team/world.py\", line 310, in step\n    raise ValueError(\nValueError: [INVALID:STEP] Not a valid step from [3 3] to [3 3] and put barrier at 0, with max steps = 3\n\nExecute Random Walk!\n"}, {"student_agent_score": 1, "random_agent_score": 48, "student_agent_time": 0.005285501480102539, "random_agent_time": 0.002333402633666992, "board_size": 7, "swap_players": false, "run_out": "An exception raised. The traceback is as follows:\nTraceback (most recent call last):\n  File \"/home/ml/users/ksinha4/mlp/comp424_final_project/submissions/comp424mcgill/final-project-a_new_team/world.py\", line 310, in step\n    raise ValueError(\nValueError: [INVALID:STEP] Not a valid step from [4 3] to [4 3] and put barrier at 0, with max steps = 4\n\nExecute Random Walk!\nAn exception raised. The traceback is as follows:\nTraceback (most recent call last):\n  File \"/home/ml/users/ksinha4/mlp/comp424_final_project/submissions/comp424mcgill/final-project-a_new_team/world.py\", line 310, in step\n    raise ValueError(\nValueError: [INVALID:STEP] Not a valid step from [4 2] to [4 2] and put barrier at 0, with max steps = 4\n\nExecute Random Walk!\nAn exception raised. The traceback is as follows:\nTraceback (most recent call last):\n  File \"/home/ml/users/ksinha4/mlp/comp424_final_project/submissions/comp424mcgill/final-project-a_new_team/world.py\", line 310, in step\n    raise ValueError(\nValueError: [INVALID:STEP] Not a valid step from [4 3] to [4 3] and put barrier at 0, with max steps = 4\n\nExecute Random Walk!\nAn exception raised. The traceback is as follows:\nTraceback (most recent call last):\n  File \"/home/ml/users/ksinha4/mlp/comp424_final_project/submissions/comp424mcgill/final-project-a_new_team/world.py\", line 310, in step\n    raise ValueError(\nValueError: [INVALID:STEP] Not a valid step from [5 4] to [5 4] and put barrier at 0, with max steps = 4\n\nExecute Random Walk!\nAn exception raised. The traceback is as follows:\nTraceback (most recent call last):\n  File \"/home/ml/users/ksinha4/mlp/comp424_final_project/submissions/comp424mcgill/final-project-a_new_team/world.py\", line 310, in step\n    raise ValueError(\nValueError: [INVALID:STEP] Not a valid step from [6 3] to [6 3] and put barrier at 0, with max steps = 4\n\nExecute Random Walk!\n"}, {"student_agent_score": 1, "random_agent_score": 48, "student_agent_time": 0.004683971405029297, "random_agent_time": 0.0021572113037109375, "board_size": 7, "swap_players": false, "run_out": "An exception raised. The traceback is as follows:\nTraceback (most recent call last):\n  File \"/home/ml/users/ksinha4/mlp/comp424_final_project/submissions/comp424mcgill/final-project-a_new_team/world.py\", line 310, in step\n    raise ValueError(\nValueError: [INVALID:STEP] Not a valid step from [4 3] to [4 3] and put barrier at 0, with max steps = 4\n\nExecute Random Walk!\nAn exception raised. The traceback is as follows:\nTraceback (most recent call last):\n  File \"/home/ml/users/ksinha4/mlp/comp424_final_project/submissions/comp424mcgill/final-project-a_new_team/world.py\", line 310, in step\n    raise ValueError(\nValueError: [INVALID:STEP] Not a valid step from [4 2] to [4 2] and put barrier at 0, with max steps = 4\n\nExecute Random Walk!\nAn exception raised. The traceback is as follows:\nTraceback (most recent call last):\n  File \"/home/ml/users/ksinha4/mlp/comp424_final_project/submissions/comp424mcgill/final-project-a_new_team/world.py\", line 310, in step\n    raise ValueError(\nValueError: [INVALID:STEP] Not a valid step from [4 3] to [4 3] and put barrier at 0, with max steps = 4\n\nExecute Random Walk!\nAn exception raised. The traceback is as follows:\nTraceback (most recent call last):\n  File \"/home/ml/users/ksinha4/mlp/comp424_final_project/submissions/comp424mcgill/final-project-a_new_team/world.py\", line 310, in step\n    raise ValueError(\nValueError: [INVALID:STEP] Not a valid step from [5 4] to [5 4] and put barrier at 0, with max steps = 4\n\nExecute Random Walk!\nAn exception raised. The traceback is as follows:\nTraceback (most recent call last):\n  File \"/home/ml/users/ksinha4/mlp/comp424_final_project/submissions/comp424mcgill/final-project-a_new_team/world.py\", line 310, in step\n    raise ValueError(\nValueError: [INVALID:STEP] Not a valid step from [6 3] to [6 3] and put barrier at 0, with max steps = 4\n\nExecute Random Walk!\n"}, {"student_agent_score": 80, "random_agent_score": 1, "student_agent_time": 0.00409245491027832, "random_agent_time": 0.005323648452758789, "board_size": 9, "swap_players": true, "run_out": "An exception raised. The traceback is as follows:\nTraceback (most recent call last):\n  File \"/home/ml/users/ksinha4/mlp/comp424_final_project/submissions/comp424mcgill/final-project-a_new_team/world.py\", line 310, in step\n    raise ValueError(\nValueError: [INVALID:STEP] Not a valid step from [3 4] to [3 4] and put barrier at 0, with max steps = 5\n\nExecute Random Walk!\nAn exception raised. The traceback is as follows:\nTraceback (most recent call last):\n  File \"/home/ml/users/ksinha4/mlp/comp424_final_project/submissions/comp424mcgill/final-project-a_new_team/world.py\", line 310, in step\n    raise ValueError(\nValueError: [INVALID:STEP] Not a valid step from [3 5] to [3 5] and put barrier at 0, with max steps = 5\n\nExecute Random Walk!\nAn exception raised. The traceback is as follows:\nTraceback (most recent call last):\n  File \"/home/ml/users/ksinha4/mlp/comp424_final_project/submissions/comp424mcgill/final-project-a_new_team/world.py\", line 310, in step\n    raise ValueError(\nValueError: [INVALID:STEP] Not a valid step from [3 4] to [3 4] and put barrier at 0, with max steps = 5\n\nExecute Random Walk!\nAn exception raised. The traceback is as follows:\nTraceback (most recent call last):\n  File \"/home/ml/users/ksinha4/mlp/comp424_final_project/submissions/comp424mcgill/final-project-a_new_team/world.py\", line 310, in step\n    raise ValueError(\nValueError: [INVALID:STEP] Not a valid step from [5 4] to [5 4] and put barrier at 0, with max steps = 5\n\nExecute Random Walk!\nAn exception raised. The traceback is as follows:\nTraceback (most recent call last):\n  File \"/home/ml/users/ksinha4/mlp/comp424_final_project/submissions/comp424mcgill/final-project-a_new_team/world.py\", line 310, in step\n    raise ValueError(\nValueError: [INVALID:STEP] Not a valid step from [5 5] to [5 5] and put barrier at 0, with max steps = 5\n\nExecute Random Walk!\n"}, {"student_agent_score": 99, "random_agent_score": 1, "student_agent_time": 0.0003695487976074219, "random_agent_time": 0.0010044574737548828, "board_size": 10, "swap_players": true, "run_out": ""}, {"student_agent_score": 1, "random_agent_score": 48, "student_agent_time": 0.003876924514770508, "random_agent_time": 0.0023794174194335938, "board_size": 7, "swap_players": false, "run_out": "An exception raised. The traceback is as follows:\nTraceback (most recent call last):\n  File \"/home/ml/users/ksinha4/mlp/comp424_final_project/submissions/comp424mcgill/final-project-a_new_team/world.py\", line 310, in step\n    raise ValueError(\nValueError: [INVALID:STEP] Not a valid step from [4 3] to [4 3] and put barrier at 0, with max steps = 4\n\nExecute Random Walk!\nAn exception raised. The traceback is as follows:\nTraceback (most recent call last):\n  File \"/home/ml/users/ksinha4/mlp/comp424_final_project/submissions/comp424mcgill/final-project-a_new_team/world.py\", line 310, in step\n    raise ValueError(\nValueError: [INVALID:STEP] Not a valid step from [4 2] to [4 2] and put barrier at 0, with max steps = 4\n\nExecute Random Walk!\nAn exception raised. The traceback is as follows:\nTraceback (most recent call last):\n  File \"/home/ml/users/ksinha4/mlp/comp424_final_project/submissions/comp424mcgill/final-project-a_new_team/world.py\", line 310, in step\n    raise ValueError(\nValueError: [INVALID:STEP] Not a valid step from [4 3] to [4 3] and put barrier at 0, with max steps = 4\n\nExecute Random Walk!\nAn exception raised. The traceback is as follows:\nTraceback (most recent call last):\n  File \"/home/ml/users/ksinha4/mlp/comp424_final_project/submissions/comp424mcgill/final-project-a_new_team/world.py\", line 310, in step\n    raise ValueError(\nValueError: [INVALID:STEP] Not a valid step from [5 4] to [5 4] and put barrier at 0, with max steps = 4\n\nExecute Random Walk!\nAn exception raised. The traceback is as follows:\nTraceback (most recent call last):\n  File \"/home/ml/users/ksinha4/mlp/comp424_final_project/submissions/comp424mcgill/final-project-a_new_team/world.py\", line 310, in step\n    raise ValueError(\nValueError: [INVALID:STEP] Not a valid step from [6 3] to [6 3] and put barrier at 0, with max steps = 4\n\nExecute Random Walk!\n"}, {"student_agent_score": 117, "random_agent_score": 1, "student_agent_time": 0.009655237197875977, "random_agent_time": 0.007688283920288086, "board_size": 11, "swap_players": false, "run_out": "An exception raised. The traceback is as follows:\nTraceback (most recent call last):\n  File \"/home/ml/users/ksinha4/mlp/comp424_final_project/submissions/comp424mcgill/final-project-a_new_team/world.py\", line 310, in step\n    raise ValueError(\nValueError: [INVALID:STEP] Not a valid step from [1 7] to [1 7] and put barrier at 0, with max steps = 6\n\nExecute Random Walk!\nAn exception raised. The traceback is as follows:\nTraceback (most recent call last):\n  File \"/home/ml/users/ksinha4/mlp/comp424_final_project/submissions/comp424mcgill/final-project-a_new_team/world.py\", line 310, in step\n    raise ValueError(\nValueError: [INVALID:STEP] Not a valid step from [1 8] to [1 8] and put barrier at 0, with max steps = 6\n\nExecute Random Walk!\nAn exception raised. The traceback is as follows:\nTraceback (most recent call last):\n  File \"/home/ml/users/ksinha4/mlp/comp424_final_project/submissions/comp424mcgill/final-project-a_new_team/world.py\", line 310, in step\n    raise ValueError(\nValueError: [INVALID:STEP] Not a valid step from [1 6] to [1 6] and put barrier at 0, with max steps = 6\n\nExecute Random Walk!\nAn exception raised. The traceback is as follows:\nTraceback (most recent call last):\n  File \"/home/ml/users/ksinha4/mlp/comp424_final_project/submissions/comp424mcgill/final-project-a_new_team/world.py\", line 310, in step\n    raise ValueError(\nValueError: [INVALID:STEP] Not a valid step from [3 3] to [3 3] and put barrier at 0, with max steps = 6\n\nExecute Random Walk!\nAn exception raised. The traceback is as follows:\nTraceback (most recent call last):\n  File \"/home/ml/users/ksinha4/mlp/comp424_final_project/submissions/comp424mcgill/final-project-a_new_team/world.py\", line 310, in step\n    raise ValueError(\nValueError: [INVALID:STEP] Not a valid step from [3 4] to [3 4] and put barrier at 0, with max steps = 6\n\nExecute Random Walk!\nAn exception raised. The traceback is as follows:\nTraceback (most recent call last):\n  File \"/home/ml/users/ksinha4/mlp/comp424_final_project/submissions/comp424mcgill/final-project-a_new_team/world.py\", line 310, in step\n    raise ValueError(\nValueError: [INVALID:STEP] Not a valid step from [3 4] to [3 4] and put barrier at 0, with max steps = 6\n\nExecute Random Walk!\nAn exception raised. The traceback is as follows:\nTraceback (most recent call last):\n  File \"/home/ml/users/ksinha4/mlp/comp424_final_project/submissions/comp424mcgill/final-project-a_new_team/world.py\", line 310, in step\n    raise ValueError(\nValueError: [INVALID:STEP] Not a valid step from [4 4] to [4 4] and put barrier at 0, with max steps = 6\n\nExecute Random Walk!\nAn exception raised. The traceback is as follows:\nTraceback (most recent call last):\n  File \"/home/ml/users/ksinha4/mlp/comp424_final_project/submissions/comp424mcgill/final-project-a_new_team/world.py\", line 310, in step\n    raise ValueError(\nValueError: [INVALID:STEP] Not a valid step from [4 4] to [4 4] and put barrier at 0, with max steps = 6\n\nExecute Random Walk!\n"}, {"student_agent_score": 1, "random_agent_score": 48, "student_agent_time": 0.0026941299438476562, "random_agent_time": 0.0024652481079101562, "board_size": 7, "swap_players": true, "run_out": "An exception raised. The traceback is as follows:\nTraceback (most recent call last):\n  File \"/home/ml/users/ksinha4/mlp/comp424_final_project/submissions/comp424mcgill/final-project-a_new_team/world.py\", line 310, in step\n    raise ValueError(\nValueError: [INVALID:STEP] Not a valid step from [2 3] to [2 3] and put barrier at 0, with max steps = 4\n\nExecute Random Walk!\nAn exception raised. The traceback is as follows:\nTraceback (most recent call last):\n  File \"/home/ml/users/ksinha4/mlp/comp424_final_project/submissions/comp424mcgill/final-project-a_new_team/world.py\", line 310, in step\n    raise ValueError(\nValueError: [INVALID:STEP] Not a valid step from [5 4] to [5 4] and put barrier at 0, with max steps = 4\n\nExecute Random Walk!\nAn exception raised. The traceback is as follows:\nTraceback (most recent call last):\n  File \"/home/ml/users/ksinha4/mlp/comp424_final_project/submissions/comp424mcgill/final-project-a_new_team/world.py\", line 310, in step\n    raise ValueError(\nValueError: [INVALID:STEP] Not a valid step from [6 3] to [6 3] and put barrier at 0, with max steps = 4\n\nExecute Random Walk!\n"}, {"student_agent_score": 80, "random_agent_score": 1, "student_agent_time": 0.00532078742980957, "random_agent_time": 0.006535768508911133, "board_size": 9, "swap_players": true, "run_out": "An exception raised. The traceback is as follows:\nTraceback (most recent call last):\n  File \"/home/ml/users/ksinha4/mlp/comp424_final_project/submissions/comp424mcgill/final-project-a_new_team/world.py\", line 310, in step\n    raise ValueError(\nValueError: [INVALID:STEP] Not a valid step from [3 4] to [3 4] and put barrier at 0, with max steps = 5\n\nExecute Random Walk!\nAn exception raised. The traceback is as follows:\nTraceback (most recent call last):\n  File \"/home/ml/users/ksinha4/mlp/comp424_final_project/submissions/comp424mcgill/final-project-a_new_team/world.py\", line 310, in step\n    raise ValueError(\nValueError: [INVALID:STEP] Not a valid step from [3 5] to [3 5] and put barrier at 0, with max steps = 5\n\nExecute Random Walk!\nAn exception raised. The traceback is as follows:\nTraceback (most recent call last):\n  File \"/home/ml/users/ksinha4/mlp/comp424_final_project/submissions/comp424mcgill/final-project-a_new_team/world.py\", line 310, in step\n    raise ValueError(\nValueError: [INVALID:STEP] Not a valid step from [3 4] to [3 4] and put barrier at 0, with max steps = 5\n\nExecute Random Walk!\nAn exception raised. The traceback is as follows:\nTraceback (most recent call last):\n  File \"/home/ml/users/ksinha4/mlp/comp424_final_project/submissions/comp424mcgill/final-project-a_new_team/world.py\", line 310, in step\n    raise ValueError(\nValueError: [INVALID:STEP] Not a valid step from [5 4] to [5 4] and put barrier at 0, with max steps = 5\n\nExecute Random Walk!\nAn exception raised. The traceback is as follows:\nTraceback (most recent call last):\n  File \"/home/ml/users/ksinha4/mlp/comp424_final_project/submissions/comp424mcgill/final-project-a_new_team/world.py\", line 310, in step\n    raise ValueError(\nValueError: [INVALID:STEP] Not a valid step from [5 5] to [5 5] and put barrier at 0, with max steps = 5\n\nExecute Random Walk!\n"}, {"student_agent_score": 1, "random_agent_score": 48, "student_agent_time": 0.004914522171020508, "random_agent_time": 0.0020351409912109375, "board_size": 7, "swap_players": false, "run_out": "An exception raised. The traceback is as follows:\nTraceback (most recent call last):\n  File \"/home/ml/users/ksinha4/mlp/comp424_final_project/submissions/comp424mcgill/final-project-a_new_team/world.py\", line 310, in step\n    raise ValueError(\nValueError: [INVALID:STEP] Not a valid step from [4 3] to [4 3] and put barrier at 0, with max steps = 4\n\nExecute Random Walk!\nAn exception raised. The traceback is as follows:\nTraceback (most recent call last):\n  File \"/home/ml/users/ksinha4/mlp/comp424_final_project/submissions/comp424mcgill/final-project-a_new_team/world.py\", line 310, in step\n    raise ValueError(\nValueError: [INVALID:STEP] Not a valid step from [4 2] to [4 2] and put barrier at 0, with max steps = 4\n\nExecute Random Walk!\nAn exception raised. The traceback is as follows:\nTraceback (most recent call last):\n  File \"/home/ml/users/ksinha4/mlp/comp424_final_project/submissions/comp424mcgill/final-project-a_new_team/world.py\", line 310, in step\n    raise ValueError(\nValueError: [INVALID:STEP] Not a valid step from [4 3] to [4 3] and put barrier at 0, with max steps = 4\n\nExecute Random Walk!\nAn exception raised. The traceback is as follows:\nTraceback (most recent call last):\n  File \"/home/ml/users/ksinha4/mlp/comp424_final_project/submissions/comp424mcgill/final-project-a_new_team/world.py\", line 310, in step\n    raise ValueError(\nValueError: [INVALID:STEP] Not a valid step from [5 4] to [5 4] and put barrier at 0, with max steps = 4\n\nExecute Random Walk!\nAn exception raised. The traceback is as follows:\nTraceback (most recent call last):\n  File \"/home/ml/users/ksinha4/mlp/comp424_final_project/submissions/comp424mcgill/final-project-a_new_team/world.py\", line 310, in step\n    raise ValueError(\nValueError: [INVALID:STEP] Not a valid step from [6 3] to [6 3] and put barrier at 0, with max steps = 4\n\nExecute Random Walk!\n"}, {"student_agent_score": 1, "random_agent_score": 48, "student_agent_time": 0.003787517547607422, "random_agent_time": 0.0019495487213134766, "board_size": 7, "swap_players": false, "run_out": "An exception raised. The traceback is as follows:\nTraceback (most recent call last):\n  File \"/home/ml/users/ksinha4/mlp/comp424_final_project/submissions/comp424mcgill/final-project-a_new_team/world.py\", line 310, in step\n    raise ValueError(\nValueError: [INVALID:STEP] Not a valid step from [4 3] to [4 3] and put barrier at 0, with max steps = 4\n\nExecute Random Walk!\nAn exception raised. The traceback is as follows:\nTraceback (most recent call last):\n  File \"/home/ml/users/ksinha4/mlp/comp424_final_project/submissions/comp424mcgill/final-project-a_new_team/world.py\", line 310, in step\n    raise ValueError(\nValueError: [INVALID:STEP] Not a valid step from [4 2] to [4 2] and put barrier at 0, with max steps = 4\n\nExecute Random Walk!\nAn exception raised. The traceback is as follows:\nTraceback (most recent call last):\n  File \"/home/ml/users/ksinha4/mlp/comp424_final_project/submissions/comp424mcgill/final-project-a_new_team/world.py\", line 310, in step\n    raise ValueError(\nValueError: [INVALID:STEP] Not a valid step from [4 3] to [4 3] and put barrier at 0, with max steps = 4\n\nExecute Random Walk!\nAn exception raised. The traceback is as follows:\nTraceback (most recent call last):\n  File \"/home/ml/users/ksinha4/mlp/comp424_final_project/submissions/comp424mcgill/final-project-a_new_team/world.py\", line 310, in step\n    raise ValueError(\nValueError: [INVALID:STEP] Not a valid step from [5 4] to [5 4] and put barrier at 0, with max steps = 4\n\nExecute Random Walk!\nAn exception raised. The traceback is as follows:\nTraceback (most recent call last):\n  File \"/home/ml/users/ksinha4/mlp/comp424_final_project/submissions/comp424mcgill/final-project-a_new_team/world.py\", line 310, in step\n    raise ValueError(\nValueError: [INVALID:STEP] Not a valid step from [6 3] to [6 3] and put barrier at 0, with max steps = 4\n\nExecute Random Walk!\n"}, {"student_agent_score": 80, "random_agent_score": 1, "student_agent_time": 0.004249095916748047, "random_agent_time": 0.005015134811401367, "board_size": 9, "swap_players": true, "run_out": "An exception raised. The traceback is as follows:\nTraceback (most recent call last):\n  File \"/home/ml/users/ksinha4/mlp/comp424_final_project/submissions/comp424mcgill/final-project-a_new_team/world.py\", line 310, in step\n    raise ValueError(\nValueError: [INVALID:STEP] Not a valid step from [3 4] to [3 4] and put barrier at 0, with max steps = 5\n\nExecute Random Walk!\nAn exception raised. The traceback is as follows:\nTraceback (most recent call last):\n  File \"/home/ml/users/ksinha4/mlp/comp424_final_project/submissions/comp424mcgill/final-project-a_new_team/world.py\", line 310, in step\n    raise ValueError(\nValueError: [INVALID:STEP] Not a valid step from [3 5] to [3 5] and put barrier at 0, with max steps = 5\n\nExecute Random Walk!\nAn exception raised. The traceback is as follows:\nTraceback (most recent call last):\n  File \"/home/ml/users/ksinha4/mlp/comp424_final_project/submissions/comp424mcgill/final-project-a_new_team/world.py\", line 310, in step\n    raise ValueError(\nValueError: [INVALID:STEP] Not a valid step from [3 4] to [3 4] and put barrier at 0, with max steps = 5\n\nExecute Random Walk!\nAn exception raised. The traceback is as follows:\nTraceback (most recent call last):\n  File \"/home/ml/users/ksinha4/mlp/comp424_final_project/submissions/comp424mcgill/final-project-a_new_team/world.py\", line 310, in step\n    raise ValueError(\nValueError: [INVALID:STEP] Not a valid step from [5 4] to [5 4] and put barrier at 0, with max steps = 5\n\nExecute Random Walk!\nAn exception raised. The traceback is as follows:\nTraceback (most recent call last):\n  File \"/home/ml/users/ksinha4/mlp/comp424_final_project/submissions/comp424mcgill/final-project-a_new_team/world.py\", line 310, in step\n    raise ValueError(\nValueError: [INVALID:STEP] Not a valid step from [5 5] to [5 5] and put barrier at 0, with max steps = 5\n\nExecute Random Walk!\n"}, {"student_agent_score": 80, "random_agent_score": 1, "student_agent_time": 0.0038199424743652344, "random_agent_time": 0.0045146942138671875, "board_size": 9, "swap_players": true, "run_out": "An exception raised. The traceback is as follows:\nTraceback (most recent call last):\n  File \"/home/ml/users/ksinha4/mlp/comp424_final_project/submissions/comp424mcgill/final-project-a_new_team/world.py\", line 310, in step\n    raise ValueError(\nValueError: [INVALID:STEP] Not a valid step from [3 4] to [3 4] and put barrier at 0, with max steps = 5\n\nExecute Random Walk!\nAn exception raised. The traceback is as follows:\nTraceback (most recent call last):\n  File \"/home/ml/users/ksinha4/mlp/comp424_final_project/submissions/comp424mcgill/final-project-a_new_team/world.py\", line 310, in step\n    raise ValueError(\nValueError: [INVALID:STEP] Not a valid step from [3 5] to [3 5] and put barrier at 0, with max steps = 5\n\nExecute Random Walk!\nAn exception raised. The traceback is as follows:\nTraceback (most recent call last):\n  File \"/home/ml/users/ksinha4/mlp/comp424_final_project/submissions/comp424mcgill/final-project-a_new_team/world.py\", line 310, in step\n    raise ValueError(\nValueError: [INVALID:STEP] Not a valid step from [3 4] to [3 4] and put barrier at 0, with max steps = 5\n\nExecute Random Walk!\nAn exception raised. The traceback is as follows:\nTraceback (most recent call last):\n  File \"/home/ml/users/ksinha4/mlp/comp424_final_project/submissions/comp424mcgill/final-project-a_new_team/world.py\", line 310, in step\n    raise ValueError(\nValueError: [INVALID:STEP] Not a valid step from [5 4] to [5 4] and put barrier at 0, with max steps = 5\n\nExecute Random Walk!\nAn exception raised. The traceback is as follows:\nTraceback (most recent call last):\n  File \"/home/ml/users/ksinha4/mlp/comp424_final_project/submissions/comp424mcgill/final-project-a_new_team/world.py\", line 310, in step\n    raise ValueError(\nValueError: [INVALID:STEP] Not a valid step from [5 5] to [5 5] and put barrier at 0, with max steps = 5\n\nExecute Random Walk!\n"}, {"student_agent_score": 117, "random_agent_score": 1, "student_agent_time": 0.007820844650268555, "random_agent_time": 0.006270647048950195, "board_size": 11, "swap_players": false, "run_out": "An exception raised. The traceback is as follows:\nTraceback (most recent call last):\n  File \"/home/ml/users/ksinha4/mlp/comp424_final_project/submissions/comp424mcgill/final-project-a_new_team/world.py\", line 310, in step\n    raise ValueError(\nValueError: [INVALID:STEP] Not a valid step from [1 7] to [1 7] and put barrier at 0, with max steps = 6\n\nExecute Random Walk!\nAn exception raised. The traceback is as follows:\nTraceback (most recent call last):\n  File \"/home/ml/users/ksinha4/mlp/comp424_final_project/submissions/comp424mcgill/final-project-a_new_team/world.py\", line 310, in step\n    raise ValueError(\nValueError: [INVALID:STEP] Not a valid step from [1 8] to [1 8] and put barrier at 0, with max steps = 6\n\nExecute Random Walk!\nAn exception raised. The traceback is as follows:\nTraceback (most recent call last):\n  File \"/home/ml/users/ksinha4/mlp/comp424_final_project/submissions/comp424mcgill/final-project-a_new_team/world.py\", line 310, in step\n    raise ValueError(\nValueError: [INVALID:STEP] Not a valid step from [1 6] to [1 6] and put barrier at 0, with max steps = 6\n\nExecute Random Walk!\nAn exception raised. The traceback is as follows:\nTraceback (most recent call last):\n  File \"/home/ml/users/ksinha4/mlp/comp424_final_project/submissions/comp424mcgill/final-project-a_new_team/world.py\", line 310, in step\n    raise ValueError(\nValueError: [INVALID:STEP] Not a valid step from [3 3] to [3 3] and put barrier at 0, with max steps = 6\n\nExecute Random Walk!\nAn exception raised. The traceback is as follows:\nTraceback (most recent call last):\n  File \"/home/ml/users/ksinha4/mlp/comp424_final_project/submissions/comp424mcgill/final-project-a_new_team/world.py\", line 310, in step\n    raise ValueError(\nValueError: [INVALID:STEP] Not a valid step from [3 4] to [3 4] and put barrier at 0, with max steps = 6\n\nExecute Random Walk!\nAn exception raised. The traceback is as follows:\nTraceback (most recent call last):\n  File \"/home/ml/users/ksinha4/mlp/comp424_final_project/submissions/comp424mcgill/final-project-a_new_team/world.py\", line 310, in step\n    raise ValueError(\nValueError: [INVALID:STEP] Not a valid step from [3 4] to [3 4] and put barrier at 0, with max steps = 6\n\nExecute Random Walk!\nAn exception raised. The traceback is as follows:\nTraceback (most recent call last):\n  File \"/home/ml/users/ksinha4/mlp/comp424_final_project/submissions/comp424mcgill/final-project-a_new_team/world.py\", line 310, in step\n    raise ValueError(\nValueError: [INVALID:STEP] Not a valid step from [4 4] to [4 4] and put barrier at 0, with max steps = 6\n\nExecute Random Walk!\nAn exception raised. The traceback is as follows:\nTraceback (most recent call last):\n  File \"/home/ml/users/ksinha4/mlp/comp424_final_project/submissions/comp424mcgill/final-project-a_new_team/world.py\", line 310, in step\n    raise ValueError(\nValueError: [INVALID:STEP] Not a valid step from [4 4] to [4 4] and put barrier at 0, with max steps = 6\n\nExecute Random Walk!\n"}, {"student_agent_score": 117, "random_agent_score": 1, "student_agent_time": 0.006805419921875, "random_agent_time": 0.0064601898193359375, "board_size": 11, "swap_players": false, "run_out": "An exception raised. The traceback is as follows:\nTraceback (most recent call last):\n  File \"/home/ml/users/ksinha4/mlp/comp424_final_project/submissions/comp424mcgill/final-project-a_new_team/world.py\", line 310, in step\n    raise ValueError(\nValueError: [INVALID:STEP] Not a valid step from [1 7] to [1 7] and put barrier at 0, with max steps = 6\n\nExecute Random Walk!\nAn exception raised. The traceback is as follows:\nTraceback (most recent call last):\n  File \"/home/ml/users/ksinha4/mlp/comp424_final_project/submissions/comp424mcgill/final-project-a_new_team/world.py\", line 310, in step\n    raise ValueError(\nValueError: [INVALID:STEP] Not a valid step from [1 8] to [1 8] and put barrier at 0, with max steps = 6\n\nExecute Random Walk!\nAn exception raised. The traceback is as follows:\nTraceback (most recent call last):\n  File \"/home/ml/users/ksinha4/mlp/comp424_final_project/submissions/comp424mcgill/final-project-a_new_team/world.py\", line 310, in step\n    raise ValueError(\nValueError: [INVALID:STEP] Not a valid step from [1 6] to [1 6] and put barrier at 0, with max steps = 6\n\nExecute Random Walk!\nAn exception raised. The traceback is as follows:\nTraceback (most recent call last):\n  File \"/home/ml/users/ksinha4/mlp/comp424_final_project/submissions/comp424mcgill/final-project-a_new_team/world.py\", line 310, in step\n    raise ValueError(\nValueError: [INVALID:STEP] Not a valid step from [3 3] to [3 3] and put barrier at 0, with max steps = 6\n\nExecute Random Walk!\nAn exception raised. The traceback is as follows:\nTraceback (most recent call last):\n  File \"/home/ml/users/ksinha4/mlp/comp424_final_project/submissions/comp424mcgill/final-project-a_new_team/world.py\", line 310, in step\n    raise ValueError(\nValueError: [INVALID:STEP] Not a valid step from [3 4] to [3 4] and put barrier at 0, with max steps = 6\n\nExecute Random Walk!\nAn exception raised. The traceback is as follows:\nTraceback (most recent call last):\n  File \"/home/ml/users/ksinha4/mlp/comp424_final_project/submissions/comp424mcgill/final-project-a_new_team/world.py\", line 310, in step\n    raise ValueError(\nValueError: [INVALID:STEP] Not a valid step from [3 4] to [3 4] and put barrier at 0, with max steps = 6\n\nExecute Random Walk!\nAn exception raised. The traceback is as follows:\nTraceback (most recent call last):\n  File \"/home/ml/users/ksinha4/mlp/comp424_final_project/submissions/comp424mcgill/final-project-a_new_team/world.py\", line 310, in step\n    raise ValueError(\nValueError: [INVALID:STEP] Not a valid step from [4 4] to [4 4] and put barrier at 0, with max steps = 6\n\nExecute Random Walk!\nAn exception raised. The traceback is as follows:\nTraceback (most recent call last):\n  File \"/home/ml/users/ksinha4/mlp/comp424_final_project/submissions/comp424mcgill/final-project-a_new_team/world.py\", line 310, in step\n    raise ValueError(\nValueError: [INVALID:STEP] Not a valid step from [4 4] to [4 4] and put barrier at 0, with max steps = 6\n\nExecute Random Walk!\n"}]}